Workbook

Sheet Cover
N2: Original Case Author
N3: Andrew Grigolyunovich
N5: Case Design Team
N6: David Brown
N7: Chris McNeil
N8: Eric Kelley
B9: Feeding Excelopolis - Junior Varsity Edition | N9: Fritz Burkhardt
B11: Case Information | N11: MECC Jobs
B12: This case originally appeared as a part of the MECC Weekend Battle series in January 2026. The objective is to calculate the population growth of Excelopolis over time. The case uses the same scoring as the original competition version, but answers are included so you can check your work. | N12: MECC sponsors such as Siemens, New York Life, Alvarez & Marsal, and BDO have all hired MECC participants. Will you be next?
N14: Earn MECC Badges
N15: Live participation in Weekend Battles counts towards earning the Excel Athlete Badge. Complete more challenges to earn the badge to post on LinkedIn!
XX1000: 125713

Sheet Case
B2: Microsoft Excel Collegiate Challenge 2026
B4: Feeding Excelopolis - MECC Junior Varsity Edition | N4: Original Case Author
N5: Andrew Grigolyunovich
N7: Case Design Team
N8: David Brown
N9: Chris McNeil
N10: Eric Kelley
N11: Fritz Burkhardt
B13: Instructions
B14: You are a chief of a tribe of nomads. Your tribe has recently discovered some advanced agricultural technologies and decided to settle down and found a city. You name the city Excelopolis.
B15: You want to forecast how fast will the population of your city grow based on 140 different scenarios listed below. Each scenario provides different land fertility assumptions.
B17: Key rules for the case:
B18: - Excelopolis is founded at the beginning of Year 1. The new era starts for your people!
B19: - The initial size of your city's population is 1 unit.
B20: - The land around Excelopolis is represented by Excel cells (see table below). The city itself is located in cell D4. The table shows an example of land fertility distribution.
B21: - Note that land fertility values in each game usually differ from the table example.
B23: Land cultivation:
B24: - Every unit of population can cultivate 1 cell of land around the city (so, initially, your people will be cultivating only 1 cell).
B25: - Different cells have different fertility - each of them can give you from 2 to 5 units of food. You will be using the most fertile cells first.
B26: - For example, if there are three people, they will each cultivate one cell, starting with the most fertile cell. Thus, in this case, the three people will cultivate the three most fertile cells
... B34: - The 10x units of food stored in the warehouse are used for growth and the warehouse now is empty or almost empty.
B37: Case Details by Difficulty Level | I37: Land Fertility Example: Excelopolis (Cell D4) & Surroundings
B38: Original Case (Pro Level) | E38: 49 cells can be used - 3 rings around the city | J38: 1 | K38: 2 | L38: 3 | M38: 4 | N38: 5 | O38: 6 | P38: 7
B39: Varsity Case | E39: 25 cells can be used - 2 rings around the city | I39: A | J39: 3 | K39: 1 | L39: 2 | M39: 2 | N39: 2 | O39: 1 | P39: 2
B40: Junior Varsity Case | E40: 9 blue cells can be used - 1 ring around the city | I40: B | J40: 2 | K40: 3 | L40: 5 | M40: 5 | N40: 5 | O40: 3 | P40: 1
I41: C | J41: 3 | K41: 3 | L41: 3 | M41: 5 | N41: 3 | O41: 2 | P41: 2
B42: The Cells Around Excelopolis: | I42: D | J42: 3 | K42: 2 | L42: 4 | M42: 3 | N42: 3 | O42: 2 | P42: 1
C43: Used in Junior Varsity, Varsity, and Original Case | I43: E | J43: 2 | K43: 3 | L43: 2 | M43: 3 | N43: 3 | O43: 3 | P43: 2
C44: Used only in Varsity and Original Case | I44: F | J44: 1 | K44: 2 | L44: 2 | M44: 3 | N44: 3 | O44: 2 | P44: 3
C45: Used only in Original Case | I45: G | J45: 2 | K45: 1 | L45: 1 | M45: 2 | N45: 3 | O45: 2 | P45: 2
B47: Bonus Questions
B49: To make the game more exciting, we have created 5 bonus questions for you. Bonus questions 1, 2, and 3 can be solved independently of the Levels. Bonus questions 4 and 5 depend on
B50: having the correct answers to the Levels 1 - 7.
B52: Game # | C52: Relates to Level # | D52: Points | E52: Answer | G52: Question
B53: Bonus 1 | C53: 1-7 | D53: 50 | F53: =IF(ISBLANK(E53),0,IF(E53=Answers!E53,1,-1)) -> 0 | G53: How many times does the most common land fertility value for a single cell occur across levels, excluding the examples? Land fertility cell values range from 2 to 5.
B54: Bonus 2 | C54: 1-7 | D54: 50 | F54: =IF(ISBLANK(E54),0,IF(E54=Answers!E54,1,-1)) -> 0 | G54: Which game number has the most fertile land, i.e., the highest sum of fertility values, excluding the examples?
B55: Bonus 3 | C55: 1-7 | D55: 50 | F55: =IF(ISBLANK(E55),0,IF(E55=Answers!E55,1,-1)) -> 0 | G55: What is the maximum number of plots of lowest fertile land (most values of 2) within a game, excluding the examples?
B56: Bonus 4 | C56: 1-7 | D56: 50 | F56: =IF(ISBLANK(E56),0,IF(E56=Answers!E56,1,-1)) -> 0 | G56: What is the most common answer across all games, excluding the examples?
B57: Bonus 5 | C57: 1-7 | D57: 50 | F57: =IF(ISBLANK(E57),0,IF(E57=Answers!E57,1,-1)) -> 0 | G57: What is the sum of the answers across all levels for odd game numbers, i.e., 1, 3, 5, …., 139? Exclude the examples.
B59: Levels
...

Sheet Graded Answers
B1: Your Answers
B2: Game # | C2: Answer | D2: Points
B3: Bonus 1 | C3: =IF(ISBLANK(Case!E53),"",Case!E53) | D3: 50
B4: Bonus 2 | C4: =IF(ISBLANK(Case!E54),"",Case!E54) | D4: 50
B5: Bonus 3 | C5: =IF(ISBLANK(Case!E55),"",Case!E55) | D5: 50
B6: Bonus 4 | C6: =IF(ISBLANK(Case!E56),"",Case!E56) | D6: 50
B7: Bonus 5 | C7: =IF(ISBLANK(Case!E57),"",Case!E57) | D7: 50
B8: 1 | C8: =IF(ISBLANK(Case!E76),"",Case!E76) -> 29 | D8: 4
B9: =B8+1 -> 2 | C9: =IF(ISBLANK(Case!E77),"",Case!E77) -> 31 | D9: 4
B10: =B9+1 -> 3 | C10: =IF(ISBLANK(Case!E78),"",Case!E78) -> 35 | D10: 4
B11: =B10+1 -> 4 | C11: =IF(ISBLANK(Case!E79),"",Case!E79) -> 35 | D11: 4
B12: =B11+1 -> 5 | C12: =IF(ISBLANK(Case!E80),"",Case!E80) -> 28 | D12: 4
B13: =B12+1 -> 6 | C13: =IF(ISBLANK(Case!E81),"",Case!E81) -> 31 | D13: 4
B14: =B13+1 -> 7 | C14: =IF(ISBLANK(Case!E82),"",Case!E82) -> 30 | D14: 4
B15: =B14+1 -> 8 | C15: =IF(ISBLANK(Case!E83),"",Case!E83) -> 32 | D15: 4
B16: =B15+1 -> 9 | C16: =IF(ISBLANK(Case!E84),"",Case!E84) -> 37 | D16: 4
B17: =B16+1 -> 10 | C17: =IF(ISBLANK(Case!E85),"",Case!E85) -> 33 | D17: 4
B18: =B17+1 -> 11 | C18: =IF(ISBLANK(Case!E86),"",Case!E86) -> 28 | D18: 4
B19: =B18+1 -> 12 | C19: =IF(ISBLANK(Case!E87),"",Case!E87) -> 34 | D19: 4
B20: =B19+1 -> 13 | C20: =IF(ISBLANK(Case!E88),"",Case!E88) -> 31 | D20: 4
... B27: =B26+1 -> 20 | C27: =IF(ISBLANK(Case!E95),"",Case!E95) -> 34 | D27: 4
B28: =B27+1 -> 21 | C28: =IF(ISBLANK(Case!E112),"",Case!E112) -> 5 | D28: 5
B29: =B28+1 -> 22 | C29: =IF(ISBLANK(Case!E113),"",Case!E113) -> 4 | D29: 5
B30: =B29+1 -> 23 | C30: =IF(ISBLANK(Case!E114),"",Case!E114) -> 5 | D30: 5
B31: =B30+1 -> 24 | C31: =IF(ISBLANK(Case!E115),"",Case!E115) -> 5 | D31: 5
B32: =B31+1 -> 25 | C32: =IF(ISBLANK(Case!E116),"",Case!E116) -> 5 | D32: 5
B33: =B32+1 -> 26 | C33: =IF(ISBLANK(Case!E117),"",Case!E117) -> 5 | D33: 5
B34: =B33+1 -> 27 | C34: =IF(ISBLANK(Case!E118),"",Case!E118) -> 3 | D34: 5
B35: =B34+1 -> 28 | C35: =IF(ISBLANK(Case!E119),"",Case!E119) -> 5 | D35: 5
B36: =B35+1 -> 29 | C36: =IF(ISBLANK(Case!E120),"",Case!E120) -> 5 | D36: 5
B37: =B36+1 -> 30 | C37: =IF(ISBLANK(Case!E121),"",Case!E121) -> 5 | D37: 5
B38: =B37+1 -> 31 | C38: =IF(ISBLANK(Case!E122),"",Case!E122) -> 5 | D38: 5
B39: =B38+1 -> 32 | C39: =IF(ISBLANK(Case!E123),"",Case!E123) -> 5 | D39: 5
... B47: =B46+1 -> 40 | C47: =IF(ISBLANK(Case!E131),"",Case!E131) -> 5 | D47: 5
B48: =B47+1 -> 41 | C48: =IF(ISBLANK(Case!E148),"",Case!E148) -> 8 | D48: 6
B49: =B48+1 -> 42 | C49: =IF(ISBLANK(Case!E149),"",Case!E149) -> 10 | D49: 6
B50: =B49+1 -> 43 | C50: =IF(ISBLANK(Case!E150),"",Case!E150) -> 9 | D50: 6
B51: =B50+1 -> 44 | C51: =IF(ISBLANK(Case!E151),"",Case!E151) -> 10 | D51: 6
B52: =B51+1 -> 45 | C52: =IF(ISBLANK(Case!E152),"",Case!E152) -> 10 | D52: 6
B53: =B52+1 -> 46 | C53: =IF(ISBLANK(Case!E153),"",Case!E153) -> 10 | D53: 6
...

Sheet Answers
B2: Microsoft Excel Collegiate Challenge 2026
B4: Feeding Excelopolis - MECC Junior Varsity Edition | N4: Original Case Author
N5: Andrew Grigolyunovich
N7: Case Design Team
N8: David Brown
N9: Chris McNeil
N10: Eric Kelley
N11: Fritz Burkhardt
B13: Instructions
B14: You are a chief of a tribe of nomads. Your tribe has recently discovered some advanced agricultural technologies and decided to settle down and found a city. You name the city Excelopolis.
B15: You want to forecast how fast will the population of your city grow based on 140 different scenarios listed below. Each scenario provides different land fertility assumptions.
B17: Key rules for the case:
B18: - Excelopolis is founded at the beginning of Year 1. The new era starts for your people!
B19: - The initial size of your city's population is 1 unit.
B20: - The land around Excelopolis is represented by Excel cells (see table below). The city itself is located in cell D4. The table shows an example of land fertility distribution.
B21: - Note that land fertility values in each game usually differ from the table example.
B23: Land cultivation:
B24: - Every unit of population can cultivate 1 cell of land around the city (so, initially, your people will be cultivating only 1 cell).
B25: - Different cells have different fertility - each of them can give you from 2 to 5 units of food. You will be using the most fertile cells first.
B26: - For example, if there are three people, they will each cultivate one cell, starting with the most fertile cell. Thus, in this case, the three people will cultivate the three most fertile cells
... B34: - The 10x units of food stored in the warehouse are used for growth and the warehouse now is empty or almost empty.
B37: Case Details by Difficulty Level | I37: Land Fertility Example: Excelopolis (Cell D4) & Surroundings
B38: Original Case (Pro Level) | E38: 49 cells can be used - 3 rings around the city | J38: 1 | K38: 2 | L38: 3 | M38: 4 | N38: 5 | O38: 6 | P38: 7
B39: Varsity Case | E39: 25 cells can be used - 2 rings around the city | I39: A | J39: 3 | K39: 1 | L39: 2 | M39: 2 | N39: 2 | O39: 1 | P39: 2
B40: Junior Varsity Case | E40: 9 blue cells can be used - 1 ring around the city | I40: B | J40: 2 | K40: 3 | L40: 5 | M40: 5 | N40: 5 | O40: 3 | P40: 1
I41: C | J41: 3 | K41: 3 | L41: 3 | M41: 5 | N41: 3 | O41: 2 | P41: 2
B42: The Cells Around Excelopolis: | I42: D | J42: 3 | K42: 2 | L42: 4 | M42: 3 | N42: 3 | O42: 2 | P42: 1
C43: Used in Junior Varsity, Varsity, and Original Case | I43: E | J43: 2 | K43: 3 | L43: 2 | M43: 3 | N43: 3 | O43: 3 | P43: 2
C44: Used only in Varsity and Original Case | I44: F | J44: 1 | K44: 2 | L44: 2 | M44: 3 | N44: 3 | O44: 2 | P44: 3
C45: Used only in Original Case | I45: G | J45: 2 | K45: 1 | L45: 1 | M45: 2 | N45: 3 | O45: 2 | P45: 2
B47: Bonus Questions
B49: To make the game more exciting, we have created 5 bonus questions for you. Bonus questions 1, 2, and 3 can be solved independently of the Levels. Bonus questions 4 and 5 depend on
B50: having the correct answers to the Levels 1 - 7.
B52: Game # | C52: Relates to Level # | D52: Points | E52: Answer | G52: Question
B53: Bonus 1 | C53: 1-7 | D53: 50 | E53: 355 | G53: How many times does the most common land fertility value for a single cell occur across levels, excluding the examples? Land fertility cell values range from 2 to 5.
B54: Bonus 2 | C54: 1-7 | D54: 50 | E54: 53 | G54: Which game number has the most fertile land, i.e., the highest sum of fertility values, excluding the examples?
B55: Bonus 3 | C55: 1-7 | D55: 50 | E55: 6 | G55: What is the maximum number of plots of lowest fertile land (most values of 2) within a game, excluding the examples?
B56: Bonus 4 | C56: 1-7 | D56: 50 | E56: 10 | G56: What is the most common answer across all games, excluding the examples?
B57: Bonus 5 | C57: 1-7 | D57: 50 | E57: 1746 | G57: What is the sum of the answers across all levels for odd game numbers, i.e., 1, 3, 5, …., 139? Exclude the examples.
B59: Levels
...
