Workbook

Sheet Case
B2: Microsoft Excel Collegiate Challenge 2025
B4: PipeMare - Varsity Edition | L4: Original Case Author
L5: Juan José Cifuentes
L7: Case Design Team
L8: Leo Fernandez
L9: Carolyn Hamilton
L10: Chris McNeil
L11: Eric Kelley
B14: Instructions
B16: You can hardly believe it; your hands are shaking so hard that you almost dropped your acceptance letter. You got into EPU!
B17: You're on your way to becoming an Excel Plumber and walking the halls where the best of the best have been trained: Bobby Filter, and even Lemmy Spillmister!
B18: But for now, it’s time to work — before your opportunity becomes nothing more than just a Pipe Dream!
B19: In this case, you will be working with pipe symbols, as presented in the PIPES table below.
B21: Special Pipe Connecting Rules & Terminology
B22: Pipes can only be connected by moving side to side or up and down
B23: Pipes cannot rotate. E.g., a “vertical” pipe cannot rotate to connect to a “horizontal” pipe.
B24: Connect To refers to a Pipe’s own up, down, left, right connections. E.g., ┗ has an up connection and a right connection.
B25: Connect From refers to other pipes that will fit to a Pipe. E.g., ┗ will fit to other pipes that have a down connection or a left connection.
B27: Mapping Binary Codes (see PIPES table).
B28: 1xxx denotes an up (top) connection; 0xxx means no up connection.
... B33: Note: Some pipe symbols may appear as an empty square ◻ in the formula bar, but Excel will still recognize and process them correctly.
G36: PIPES
G37: Pipe / Element | H37: Name | I37: Connects To | J37: Connects From
G38: ┃ | H38: Vertical | I38: 1100 | J38: 1100
G39: ━ | H39: Horizontal | I39: 0011 | J39: 0011
G40: ┏ | H40: Top-Right Bend | I40: 0101 | J40: 1010
G41: ┓ | H41: Top-Left Bend | I41: 0110 | J41: 1001
G42: ┗ | H42: Bottom-Right Bend | I42: 1001 | J42: 0110
G43: ┛ | H43: Bottom-Left Bend | I43: 1010 | J43: 0101
G44: ◉ | H44: Source | I44: 1111 | J44: 1111
G45: ○ | H45: Outlet | I45: 1111 | J45: 1111
G46: 🧱 | H46: Wall | I46: N/A | J46: N/A
B48: Bonus Questions
B50: To make the game more exciting, we have created 5 bonus questions for you. The questions can all be solved independently of the Levels.
B52: Game # | C52: Relates to Level # | D52: Points | E52: Answer | G52: Question
B53: Bonus 1 | C53: N/A | D53: 30 | G53: How many pipes are in the PipeMaze, excluding sources and outlets?
B54: Bonus 2 | C54: N/A | D54: 40 | G54: For all the pipes in Level 1, excluding the example, how many times can a pipe Connect To the LEFT direction? Each Level 1 game has 31 pipes.
B55: Bonus 3 | C55: 5 | D55: 60 | G55: In Level 5, excluding the example, how many pipes do not connect to the previous pipe in the sequence.
B56: Bonus 4 | C56: 6 | D56: 50 | G56: In Level 6, excluding the example, what is the total number of wall sections 🧱 within the areas that contain the pipe sequences?
B57: Bonus 5 | C57: 7 | D57: 70 | G57: In Level 7, excluding the example, what is the 4-letter code answer that appears the most? Report number of times followed by the 4-letter code (e.g. 8BRBL).
...

Sheet PipeMaze
C1: C | D1: D | E1: E | F1: F | G1: G | H1: H | I1: I | J1: J | K1: K | L1: L | M1: M | N1: N | O1: O | P1: P | Q1: Q | R1: R | S1: S | T1: T | U1: U | V1: V | W1: W | X1: X | Y1: Y | Z1: Z | AA1: AA | AB1: AB | AC1: AC | AD1: AD | AE1: AE | AF1: AF | AG1: AG | AH1: AH | AI1: AI | AJ1: AJ | AK1: AK | AL1: AL | AM1: AM | AN1: AN | AO1: AO | AP1: AP | AQ1: AQ | AR1: AR | AS1: AS | AT1: AT | AU1: AU | AV1: AV | AW1: AW | AX1: AX
A3: 3 | C3: 🧱 | D3: 🧱 | E3: 🧱 | F3: 🧱 | G3: 🧱 | H3: 🧱 | I3: 🧱 | J3: 🧱 | K3: 🧱 | L3: 🧱 | M3: 🧱 | N3: 🧱 | O3: 🧱 | P3: 🧱 | Q3: 🧱 | R3: 🧱 | S3: 🧱 | T3: 🧱 | U3: 🧱 | V3: 🧱 | W3: 🧱 | X3: 🧱 | Y3: 🧱 | Z3: 🧱 | AA3: 🧱 | AB3: 🧱 | AC3: 🧱 | AD3: 🧱 | AE3: 🧱 | AF3: 🧱 | AG3: 🧱 | AH3: 🧱 | AI3: ○ | AJ3: 🧱 | AK3: ◉ | AL3: 🧱 | AM3: 🧱 | AN3: 🧱 | AO3: ○ | AP3: 🧱 | AQ3: 🧱 | AR3: 🧱 | AS3: 🧱 | AT3: 🧱 | AU3: 🧱 | AV3: 🧱 | AW3: 🧱 | AX3: 🧱
A4: 4 | C4: 🧱 | D4: 🧱 | E4: 🧱 | F4: 🧱 | G4: 🧱 | H4: 🧱 | I4: 🧱 | J4: 🧱 | K4: 🧱 | L4: 🧱 | M4: 🧱 | N4: 🧱 | O4: ◉ | P4: 🧱 | Q4: ◉ | R4: 🧱 | S4: 🧱 | T4: 🧱 | U4: 🧱 | V4: 🧱 | W4: ┏ | X4: ┓ | Y4: 🧱 | Z4: 🧱 | AA4: 🧱 | AB4: ┏ | AC4: ┓ | AD4: ┏ | AE4: ┓ | AF4: 🧱 | AG4: 🧱 | AH4: ┏ | AI4: ┛ | AJ4: 🧱 | AK4: ┃ | AL4: ┏ | AM4: ┓ | AN4: 🧱 | AO4: ┃ | AP4: ○ | AQ4: 🧱 | AR4: 🧱 | AS4: 🧱 | AT4: 🧱 | AU4: 🧱 | AV4: 🧱 | AW4: ◉ | AX4: 🧱
A5: 5 | C5: 🧱 | D5: 🧱 | E5: 🧱 | F5: 🧱 | G5: 🧱 | H5: 🧱 | I5: 🧱 | J5: 🧱 | K5: ┏ | L5: ━ | M5: ━ | N5: ━ | O5: ┛ | P5: 🧱 | Q5: ┃ | R5: 🧱 | S5: 🧱 | T5: 🧱 | U5: 🧱 | V5: 🧱 | W5: ┃ | X5: ┗ | Y5: ┓ | Z5: 🧱 | AA5: 🧱 | AB5: ┃ | AC5: ┃ | AD5: ┃ | AE5: ┗ | AF5: ┓ | AG5: 🧱 | AH5: ┗ | AI5: ┓ | AJ5: 🧱 | AK5: ┗ | AL5: ┛ | AM5: ┃ | AN5: 🧱 | AO5: ┃ | AP5: ┃ | AQ5: 🧱 | AR5: 🧱 | AS5: 🧱 | AT5: ┏ | AU5: ━ | AV5: ┓ | AW5: ┃ | AX5: 🧱
A6: 6 | C6: 🧱 | D6: 🧱 | E6: 🧱 | F6: 🧱 | G6: 🧱 | H6: 🧱 | I6: 🧱 | J6: 🧱 | K6: ┃ | L6: 🧱 | M6: 🧱 | N6: 🧱 | O6: 🧱 | P6: 🧱 | Q6: ┃ | R6: 🧱 | S6: 🧱 | T6: 🧱 | U6: 🧱 | V6: 🧱 | W6: ┃ | X6: 🧱 | Y6: ┃ | Z6: 🧱 | AA6: 🧱 | AB6: ┃ | AC6: ┃ | AD6: ┃ | AE6: 🧱 | AF6: ┃ | AG6: 🧱 | AH6: 🧱 | AI6: ┃ | AJ6: 🧱 | AK6: 🧱 | AL6: 🧱 | AM6: ┃ | AN6: 🧱 | AO6: ┃ | AP6: ┃ | AQ6: 🧱 | AR6: 🧱 | AS6: 🧱 | AT6: ┃ | AU6: 🧱 | AV6: ┗ | AW6: ┛ | AX6: 🧱
A7: 7 | C7: 🧱 | D7: 🧱 | E7: 🧱 | F7: 🧱 | G7: 🧱 | H7: 🧱 | I7: 🧱 | J7: 🧱 | K7: ┗ | L7: ━ | M7: ┓ | N7: 🧱 | O7: 🧱 | P7: 🧱 | Q7: ┃ | R7: 🧱 | S7: 🧱 | T7: 🧱 | U7: 🧱 | V7: 🧱 | W7: ┃ | X7: 🧱 | Y7: ┃ | Z7: 🧱 | AA7: 🧱 | AB7: ┃ | AC7: ┃ | AD7: ┃ | AE7: 🧱 | AF7: ┗ | AG7: ┓ | AH7: 🧱 | AI7: ┃ | AJ7: 🧱 | AK7: ┏ | AL7: ━ | AM7: ┛ | AN7: ┏ | AO7: ┛ | AP7: ┃ | AQ7: ┏ | AR7: ━ | AS7: ┓ | AT7: ┃ | AU7: 🧱 | AV7: 🧱 | AW7: 🧱 | AX7: 🧱
A8: 8 | C8: 🧱 | D8: 🧱 | E8: 🧱 | F8: 🧱 | G8: ┏ | H8: ┓ | I8: 🧱 | J8: 🧱 | K8: 🧱 | L8: 🧱 | M8: ┗ | N8: ━ | O8: ┓ | P8: 🧱 | Q8: ┃ | R8: 🧱 | S8: 🧱 | T8: 🧱 | U8: 🧱 | V8: 🧱 | W8: ┃ | X8: 🧱 | Y8: ┃ | Z8: 🧱 | AA8: ┏ | AB8: ┛ | AC8: ┃ | AD8: ┃ | AE8: 🧱 | AF8: ┏ | AG8: ┛ | AH8: 🧱 | AI8: ┃ | AJ8: 🧱 | AK8: ┃ | AL8: ┏ | AM8: ━ | AN8: ┛ | AO8: 🧱 | AP8: ┃ | AQ8: ┃ | AR8: 🧱 | AS8: ┃ | AT8: ┗ | AU8: ━ | AV8: ┓ | AW8: 🧱 | AX8: 🧱
A9: 9 | C9: 🧱 | D9: 🧱 | E9: ┏ | F9: ━ | G9: ┛ | H9: ┃ | I9: 🧱 | J9: 🧱 | K9: 🧱 | L9: 🧱 | M9: 🧱 | N9: 🧱 | O9: ┃ | P9: 🧱 | Q9: ┃ | R9: 🧱 | S9: 🧱 | T9: 🧱 | U9: 🧱 | V9: 🧱 | W9: ┃ | X9: 🧱 | Y9: ┃ | Z9: ┏ | AA9: ┛ | AB9: 🧱 | AC9: ┃ | AD9: ┃ | AE9: 🧱 | AF9: ┃ | AG9: 🧱 | AH9: 🧱 | AI9: ┃ | AJ9: 🧱 | AK9: ┃ | AL9: ┃ | AM9: 🧱 | AN9: 🧱 | AO9: 🧱 | AP9: ┃ | AQ9: ┗ | AR9: ┓ | AS9: ┃ | AT9: 🧱 | AU9: 🧱 | AV9: ┃ | AW9: 🧱 | AX9: 🧱
A10: 10 | C10: 🧱 | D10: 🧱 | E10: ┃ | F10: 🧱 | G10: 🧱 | H10: ┗ | I10: ┓ | J10: 🧱 | K10: 🧱 | L10: 🧱 | M10: 🧱 | N10: ┏ | O10: ┛ | P10: 🧱 | Q10: ┗ | R10: ┓ | S10: 🧱 | T10: ┏ | U10: ┓ | V10: 🧱 | W10: ┃ | X10: 🧱 | Y10: ┗ | Z10: ┛ | AA10: 🧱 | AB10: 🧱 | AC10: ┃ | AD10: ┃ | AE10: 🧱 | AF10: ┗ | AG10: ━ | AH10: ━ | AI10: ┛ | AJ10: 🧱 | AK10: ┃ | AL10: ┃ | AM10: 🧱 | AN10: 🧱 | AO10: 🧱 | AP10: ┗ | AQ10: ┓ | AR10: ┃ | AS10: ┃ | AT10: 🧱 | AU10: ┏ | AV10: ┛ | AW10: 🧱 | AX10: 🧱
A11: 11 | C11: 🧱 | D11: 🧱 | E11: ┃ | F11: 🧱 | G11: 🧱 | H11: 🧱 | I11: ┗ | J11: ━ | K11: ━ | L11: ━ | M11: ━ | N11: ┛ | O11: 🧱 | P11: 🧱 | Q11: 🧱 | R11: ┗ | S11: ━ | T11: ┛ | U11: ○ | V11: 🧱 | W11: ◉ | X11: 🧱 | Y11: 🧱 | Z11: 🧱 | AA11: 🧱 | AB11: 🧱 | AC11: ┗ | AD11: ┛ | AE11: 🧱 | AF11: 🧱 | AG11: 🧱 | AH11: 🧱 | AI11: 🧱 | AJ11: 🧱 | AK11: ┗ | AL11: ┛ | AM11: 🧱 | AN11: 🧱 | AO11: 🧱 | AP11: 🧱 | AQ11: ┃ | AR11: ┃ | AS11: ┃ | AT11: 🧱 | AU11: ┃ | AV11: 🧱 | AW11: 🧱 | AX11: 🧱
A12: 12 | C12: 🧱 | D12: 🧱 | E12: ┃ | F12: 🧱 | G12: 🧱 | H12: 🧱 | I12: 🧱 | J12: 🧱 | K12: 🧱 | L12: 🧱 | M12: 🧱 | N12: 🧱 | O12: 🧱 | P12: 🧱 | Q12: 🧱 | R12: 🧱 | S12: 🧱 | T12: 🧱 | U12: 🧱 | V12: 🧱 | W12: 🧱 | X12: 🧱 | Y12: 🧱 | Z12: 🧱 | AA12: 🧱 | AB12: 🧱 | AC12: 🧱 | AD12: 🧱 | AE12: 🧱 | AF12: 🧱 | AG12: 🧱 | AH12: 🧱 | AI12: 🧱 | AJ12: 🧱 | AK12: 🧱 | AL12: 🧱 | AM12: 🧱 | AN12: 🧱 | AO12: 🧱 | AP12: 🧱 | AQ12: ┃ | AR12: ┃ | AS12: ┃ | AT12: 🧱 | AU12: ┗ | AV12: ━ | AW12: ┓ | AX12: 🧱
A13: 13 | C13: 🧱 | D13: 🧱 | E13: ○ | F13: 🧱 | G13: 🧱 | H13: 🧱 | I13: 🧱 | J13: 🧱 | K13: 🧱 | L13: 🧱 | M13: 🧱 | N13: 🧱 | O13: 🧱 | P13: 🧱 | Q13: 🧱 | R13: 🧱 | S13: 🧱 | T13: 🧱 | U13: 🧱 | V13: 🧱 | W13: 🧱 | X13: ◉ | Y13: 🧱 | Z13: 🧱 | AA13: 🧱 | AB13: 🧱 | AC13: 🧱 | AD13: 🧱 | AE13: 🧱 | AF13: 🧱 | AG13: 🧱 | AH13: 🧱 | AI13: 🧱 | AJ13: 🧱 | AK13: 🧱 | AL13: 🧱 | AM13: 🧱 | AN13: 🧱 | AO13: 🧱 | AP13: 🧱 | AQ13: ┃ | AR13: ┃ | AS13: ┗ | AT13: ━ | AU13: ━ | AV13: ━ | AW13: ┛ | AX13: 🧱
A14: 14 | C14: 🧱 | D14: 🧱 | E14: 🧱 | F14: 🧱 | G14: 🧱 | H14: 🧱 | I14: 🧱 | J14: 🧱 | K14: 🧱 | L14: 🧱 | M14: 🧱 | N14: 🧱 | O14: 🧱 | P14: 🧱 | Q14: 🧱 | R14: 🧱 | S14: ┏ | T14: ━ | U14: ━ | V14: ┓ | W14: 🧱 | X14: ┗ | Y14: ┓ | Z14: 🧱 | AA14: 🧱 | AB14: 🧱 | AC14: 🧱 | AD14: ◉ | AE14: ┓ | AF14: 🧱 | AG14: 🧱 | AH14: ┏ | AI14: ┓ | AJ14: 🧱 | AK14: 🧱 | AL14: 🧱 | AM14: 🧱 | AN14: 🧱 | AO14: 🧱 | AP14: 🧱 | AQ14: ┃ | AR14: ┗ | AS14: ━ | AT14: ━ | AU14: ┓ | AV14: 🧱 | AW14: 🧱 | AX14: 🧱
... A42: 42 | C42: 🧱 | D42: 🧱 | E42: 🧱 | F42: 🧱 | G42: 🧱 | H42: 🧱 | I42: ○ | J42: 🧱 | K42: 🧱 | L42: 🧱 | M42: 🧱 | N42: 🧱 | O42: 🧱 | P42: 🧱 | Q42: 🧱 | R42: 🧱 | S42: 🧱 | T42: 🧱 | U42: 🧱 | V42: ◉ | W42: 🧱 | X42: 🧱 | Y42: 🧱 | Z42: 🧱 | AA42: 🧱 | AB42: 🧱 | AC42: 🧱 | AD42: 🧱 | AE42: 🧱 | AF42: 🧱 | AG42: 🧱 | AH42: 🧱 | AI42: 🧱 | AJ42: 🧱 | AK42: 🧱 | AL42: 🧱 | AM42: 🧱 | AN42: 🧱 | AO42: 🧱 | AP42: 🧱 | AQ42: 🧱 | AR42: ┗ | AS42: ━ | AT42: ━ | AU42: ━ | AV42: ┛ | AW42: 🧱 | AX42: 🧱
XX1000: 125713

Sheet Graded Answers
B1: Your Answers
B2: Game # | C2: Answer | D2: Points
B3: Bonus 1 | C3: =IF(ISBLANK(Case!E53),"",Case!E53) | D3: 30
B4: Bonus 2 | C4: =IF(ISBLANK(Case!E54),"",Case!E54) | D4: 40
B5: Bonus 3 | C5: =IF(ISBLANK(Case!E55),"",Case!E55) | D5: 60
B6: Bonus 4 | C6: =IF(ISBLANK(Case!E56),"",Case!E56) | D6: 50
B7: Bonus 5 | C7: =IF(ISBLANK(Case!E57),"",Case!E57) | D7: 70
B8: 1 | C8: =IF(ISBLANK(Case!E79),"",Case!E79) -> 10 | D8: 5
B9: =B8+1 -> 2 | C9: =IF(ISBLANK(Case!E80),"",Case!E80) -> 7 | D9: 5
B10: =B9+1 -> 3 | C10: =IF(ISBLANK(Case!E81),"",Case!E81) -> 16 | D10: 5
B11: =B10+1 -> 4 | C11: =IF(ISBLANK(Case!E82),"",Case!E82) -> 11 | D11: 5
B12: =B11+1 -> 5 | C12: =IF(ISBLANK(Case!E83),"",Case!E83) -> 6 | D12: 5
B13: =B12+1 -> 6 | C13: =IF(ISBLANK(Case!E84),"",Case!E84) -> 10 | D13: 5
B14: =B13+1 -> 7 | C14: =IF(ISBLANK(Case!E85),"",Case!E85) -> 9 | D14: 5
B15: =B14+1 -> 8 | C15: =IF(ISBLANK(Case!E86),"",Case!E86) -> 26 | D15: 5
B16: =B15+1 -> 9 | C16: =IF(ISBLANK(Case!E87),"",Case!E87) -> 5 | D16: 5
B17: =B16+1 -> 10 | C17: =IF(ISBLANK(Case!E88),"",Case!E88) -> 7 | D17: 5
B18: =B17+1 -> 11 | C18: =IF(ISBLANK(Case!E89),"",Case!E89) -> 14 | D18: 5
B19: =B18+1 -> 12 | C19: =IF(ISBLANK(Case!E90),"",Case!E90) -> 3 | D19: 5
B20: =B19+1 -> 13 | C20: =IF(ISBLANK(Case!E91),"",Case!E91) -> 8 | D20: 5
... B27: =B26+1 -> 20 | C27: =IF(ISBLANK(Case!E98),"",Case!E98) -> 4 | D27: 5
B28: =B27+1 -> 21 | C28: =IF(ISBLANK(Case!E119),"",Case!E119) -> 10100011011001010110 | D28: 5
B29: =B28+1 -> 22 | C29: =IF(ISBLANK(Case!E120),"",Case!E120) -> 01011100010111001010 | D29: 5
B30: =B29+1 -> 23 | C30: =IF(ISBLANK(Case!E121),"",Case!E121) -> 10010110001100111001 | D30: 5
B31: =B30+1 -> 24 | C31: =IF(ISBLANK(Case!E122),"",Case!E122) -> 10011100100110011010 | D31: 5
B32: =B31+1 -> 25 | C32: =IF(ISBLANK(Case!E123),"",Case!E123) -> 01010110001101101001 | D32: 5
B33: =B32+1 -> 26 | C33: =IF(ISBLANK(Case!E124),"",Case!E124) -> 01100011010101100101 | D33: 5
B34: =B33+1 -> 27 | C34: =IF(ISBLANK(Case!E125),"",Case!E125) -> 11001001001110010011 | D34: 5
B35: =B34+1 -> 28 | C35: =IF(ISBLANK(Case!E126),"",Case!E126) -> 00111010100110100011 | D35: 5
B36: =B35+1 -> 29 | C36: =IF(ISBLANK(Case!E127),"",Case!E127) -> 01101001110001010011 | D36: 5
B37: =B36+1 -> 30 | C37: =IF(ISBLANK(Case!E128),"",Case!E128) -> 01100011100100111010 | D37: 5
B38: =B37+1 -> 31 | C38: =IF(ISBLANK(Case!E129),"",Case!E129) -> 00110110110010100101 | D38: 5
B39: =B38+1 -> 32 | C39: =IF(ISBLANK(Case!E130),"",Case!E130) -> 01011100110001010110 | D39: 5
... B47: =B46+1 -> 40 | C47: =IF(ISBLANK(Case!E138),"",Case!E138) -> 10010011011000111001 | D47: 5
B48: =B47+1 -> 41 | C48: =IF(ISBLANK(Case!E165),"",Case!E165) -> 21 | D48: 6
B49: =B48+1 -> 42 | C49: =IF(ISBLANK(Case!E166),"",Case!E166) -> 16 | D49: 6
B50: =B49+1 -> 43 | C50: =IF(ISBLANK(Case!E167),"",Case!E167) -> 22 | D50: 6
B51: =B50+1 -> 44 | C51: =IF(ISBLANK(Case!E168),"",Case!E168) -> 12 | D51: 6
B52: =B51+1 -> 45 | C52: =IF(ISBLANK(Case!E169),"",Case!E169) -> 17 | D52: 6
B53: =B52+1 -> 46 | C53: =IF(ISBLANK(Case!E170),"",Case!E170) -> 14 | D53: 6
...
