Workbook
Name maze: PipeMaze!$C$3:$AX$42

Sheet Case
B2: Microsoft Excel Collegiate Challenge 2025
B4: PipeMare - Junior Varsity Edition | L4: Original Case Author
L5: Juan José Cifuentes
L7: Case Design Team
L8: Leo Fernandez
L9: Carolyn Hamilton
L10: Chris McNeil
L11: Eric Kelley
B14: Instructions
B16: You can hardly believe it; your hands are shaking so hard that you almost dropped your acceptance letter. You got into EPU!
B17: You're on your way to becoming an Excel Plumber and walking the halls where the best of the best have been trained: Bobby Filter, and even Lemmy Spillmister!
B18: But for now, it’s time to work — before your opportunity becomes nothing more than just a Pipe Dream!
B19: In this case, you will be working with pipe symbols, as presented in the PIPES table below.
B21: Special Pipe Connecting Rules & Terminology
B22: Pipes can only be connected by moving side to side or up and down
B23: Pipes cannot rotate. E.g., a “vertical” pipe cannot rotate to connect to a “horizontal” pipe.
B24: Connects To refers to a Pipe’s own up, down, left, right connections. E.g., ┗ has an up connection and a right connection.
B25: Connects From refers to other pipes that will fit to a Pipe. E.g., ┗ will fit to other pipes that have a down connection or a left connection.
B27: Mapping Binary Codes (see PIPES table).
B28: 1xxx denotes an up (top) connection; 0xxx means no up connection.
... B33: Note: Some pipe symbols may appear as an empty square ◻ in the formula bar, but Excel will still recognize and process them correctly.
G36: PIPES
G37: Pipe / Element | H37: Name | I37: Connects To | J37: Connects From
G38: ┃ | H38: Vertical | I38: 1100 | J38: 1100
G39: ━ | H39: Horizontal | I39: 0011 | J39: 0011 | L39: ???1
G40: ┏ | H40: Top-Right Bend | I40: 0101 | J40: 1010
G41: ┓ | H41: Top-Left Bend | I41: 0110 | J41: 1001
G42: ┗ | H42: Bottom-Right Bend | I42: 1001 | J42: 0110
G43: ┛ | H43: Bottom-Left Bend | I43: 1010 | J43: 0101
G44: ◉ | H44: Source | I44: 1111 | J44: 1111
G45: ○ | H45: Outlet | I45: 1111 | J45: 1111
G46: 🧱 | H46: Wall | I46: N/A | J46: N/A
B48: Bonus Questions
B50: To make the game more exciting, we have created 5 bonus questions for you. The questions can all be solved independently of the Levels.
B52: Game # | C52: Relates to Level # | D52: Points | E52: Answer | G52: Question
B53: Bonus 1 | C53: 2 | D53: 30 | E53: {=SUM(IF(ISERROR(_xlfn.ANCHORARRAY(H120)),_xlfn.ANCHORARRAY(E120),0))} -> 1167 | G53: In Level 2 answers (excluding the example), what is the total number of elements that are not pipes, sources or outlets?
B54: Bonus 2 | C54: 3 | D54: 40 | E54: 3 | G54: In Level 3 answers, excluding the example, there is one element that is present more than any other. How many times is that element present?
B55: Bonus 3 | C55: 4-5 | D55: 60 | E55: 10 | G55: Excluding the examples, how many of the pipe sections in levels 4 and 5 are┗ ?
B56: Bonus 4 | C56: N/A | D56: 50 | E56: 282 | G56: In the PipeMaze, what is the total number of pipes that Connets To the Right? Exclude Sources and Outlets as they are not pipes.
B57: Bonus 5 | C57: 7 | D57: 70 | E57: 46 | G57: Excluding the example in Level 7, what is the total number of pipes that do not connect to the previous pipe in the sequence?
...

Sheet PipeMaze
C1: C | D1: D | E1: E | F1: F | G1: G | H1: H | I1: I | J1: J | K1: K | L1: L | M1: M | N1: N | O1: O | P1: P | Q1: Q | R1: R | S1: S | T1: T | U1: U | V1: V | W1: W | X1: X | Y1: Y | Z1: Z | AA1: AA | AB1: AB | AC1: AC | AD1: AD | AE1: AE | AF1: AF | AG1: AG | AH1: AH | AI1: AI | AJ1: AJ | AK1: AK | AL1: AL | AM1: AM | AN1: AN | AO1: AO | AP1: AP | AQ1: AQ | AR1: AR | AS1: AS | AT1: AT | AU1: AU | AV1: AV | AW1: AW | AX1: AX | BC1: PipeMaze Contents by Cell Address
BC2: Cell Address | BD2: Contents
A3: 3 | C3: 🧱 | D3: 🧱 | E3: 🧱 | F3: 🧱 | G3: 🧱 | H3: 🧱 | I3: 🧱 | J3: 🧱 | K3: 🧱 | L3: 🧱 | M3: 🧱 | N3: 🧱 | O3: 🧱 | P3: 🧱 | Q3: 🧱 | R3: 🧱 | S3: 🧱 | T3: 🧱 | U3: 🧱 | V3: 🧱 | W3: 🧱 | X3: 🧱 | Y3: 🧱 | Z3: 🧱 | AA3: 🧱 | AB3: 🧱 | AC3: 🧱 | AD3: 🧱 | AE3: 🧱 | AF3: 🧱 | AG3: 🧱 | AH3: 🧱 | AI3: ○ | AJ3: 🧱 | AK3: ◉ | AL3: 🧱 | AM3: 🧱 | AN3: 🧱 | AO3: ○ | AP3: 🧱 | AQ3: 🧱 | AR3: 🧱 | AS3: 🧱 | AT3: 🧱 | AU3: 🧱 | AV3: 🧱 | AW3: 🧱 | AX3: 🧱 | BC3: C3 | BD3: 🧱
A4: 4 | C4: 🧱 | D4: 🏵 | E4: 🏵 | F4: 🏵 | G4: 🏵 | H4: 🏵 | I4: 🏵 | J4: 🧱 | K4: 🧱 | L4: 🧱 | M4: 🧱 | N4: 🧱 | O4: ◉ | P4: 🧱 | Q4: ◉ | R4: 🧱 | S4: 🌱 | T4: 🌱 | U4: 🌱 | V4: 🧱 | W4: ┏ | X4: ┓ | Y4: 🧱 | Z4: 🧱 | AA4: 🧱 | AB4: ┏ | AC4: ┓ | AD4: ┏ | AE4: ┓ | AF4: 🧱 | AG4: 🧱 | AH4: ┏ | AI4: ┛ | AJ4: 🧱 | AK4: ┃ | AL4: ┏ | AM4: ┓ | AN4: 🧱 | AO4: ┃ | AP4: ○ | AQ4: 🧱 | AR4: 🌾 | AS4: 🧱 | AT4: 🧱 | AU4: 🧱 | AV4: 🧱 | AW4: ◉ | AX4: 🧱 | BC4: D3 | BD4: 🧱 | BG4: =COUNTIF(_xlfn.ANCHORARRAY(BI4),"???1") -> 282 | BI4: {=_xlfn.XLOOKUP(maze,Case!$G$38:$G$43,Case!I38:I43,"",0,1)}
A5: 5 | C5: 🧱 | D5: 🏵 | E5: 🏵 | F5: 🏵 | G5: 🏵 | H5: 🏵 | I5: 🏵 | J5: 🧱 | K5: ┏ | L5: ━ | M5: ━ | N5: ━ | O5: ┛ | P5: 🧱 | Q5: ┃ | R5: 🧱 | S5: 🌱 | T5: 🌱 | U5: 🌱 | V5: 🧱 | W5: ┃ | X5: ┗ | Y5: ┓ | Z5: 🧱 | AA5: 🧱 | AB5: ┃ | AC5: ┃ | AD5: ┃ | AE5: ┗ | AF5: ┓ | AG5: 🧱 | AH5: ┗ | AI5: ┓ | AJ5: 🧱 | AK5: ┗ | AL5: ┛ | AM5: ┃ | AN5: 🧱 | AO5: ┃ | AP5: ┃ | AQ5: 🧱 | AR5: 🌾 | AS5: 🧱 | AT5: ┏ | AU5: ━ | AV5: ┓ | AW5: ┃ | AX5: 🧱 | BC5: E3 | BD5: 🧱 | CC5: 0101 | CD5: 0110 | CH5: 0101 | CI5: 0110 | CJ5: 0101 | CK5: 0110 | CN5: 0101 | CO5: 1010 | CQ5: 1100 | CR5: 0101 | CS5: 0110 | CU5: 1100
A6: 6 | C6: 🧱 | D6: 🏵 | E6: 🏵 | F6: 🏵 | G6: 🏵 | H6: 🏵 | I6: 🏵 | J6: 🧱 | K6: ┃ | L6: 🧱 | M6: 🧱 | N6: 🧱 | O6: 🧱 | P6: 🧱 | Q6: ┃ | R6: 🧱 | S6: 🌱 | T6: 🌱 | U6: 🌱 | V6: 🧱 | W6: ┃ | X6: 🧱 | Y6: ┃ | Z6: 🧱 | AA6: 🧱 | AB6: ┃ | AC6: ┃ | AD6: ┃ | AE6: 🧱 | AF6: ┃ | AG6: 🧱 | AH6: 🧱 | AI6: ┃ | AJ6: 🧱 | AK6: 🧱 | AL6: 🧱 | AM6: ┃ | AN6: 🧱 | AO6: ┃ | AP6: ┃ | AQ6: 🧱 | AR6: 🧱 | AS6: 🧱 | AT6: ┃ | AU6: 🧱 | AV6: ┗ | AW6: ┛ | AX6: 🧱 | BC6: F3 | BD6: 🧱 | BQ6: 0101 | BR6: 0011 | BS6: 0011 | BT6: 0011 | BU6: 1010 | BW6: 1100 | CC6: 1100 | CD6: 1001 | CE6: 0110 | CH6: 1100 | CI6: 1100 | CJ6: 1100 | CK6: 1001 | CL6: 0110 | CN6: 1001 | CO6: 0110 | CQ6: 1001 | CR6: 1010 | CS6: 1100 | CU6: 1100 | CV6: 1100 | CZ6: 0101 | DA6: 0011 | DB6: 0110 | DC6: 1100
A7: 7 | C7: 🧱 | D7: 🏵 | E7: 🏵 | F7: 🧱 | G7: 🧱 | H7: 🧱 | I7: 🧱 | J7: 🧱 | K7: ┗ | L7: ━ | M7: ┓ | N7: 🧱 | O7: 🧱 | P7: 🧱 | Q7: ┃ | R7: 🧱 | S7: 🌱 | T7: 🌱 | U7: 🌱 | V7: 🧱 | W7: ┃ | X7: 🧱 | Y7: ┃ | Z7: 🧱 | AA7: 🧱 | AB7: ┃ | AC7: ┃ | AD7: ┃ | AE7: 🧱 | AF7: ┗ | AG7: ┓ | AH7: 🧱 | AI7: ┃ | AJ7: 🧱 | AK7: ┏ | AL7: ━ | AM7: ┛ | AN7: ┏ | AO7: ┛ | AP7: ┃ | AQ7: ┏ | AR7: ━ | AS7: ┓ | AT7: ┃ | AU7: 🧱 | AV7: 🧱 | AW7: 🧱 | AX7: 🧱 | BC7: G3 | BD7: 🧱 | BQ7: 1100 | BW7: 1100 | CC7: 1100 | CE7: 1100 | CH7: 1100 | CI7: 1100 | CJ7: 1100 | CL7: 1100 | CO7: 1100 | CS7: 1100 | CU7: 1100 | CV7: 1100 | CZ7: 1100 | DB7: 1001 | DC7: 1010
A8: 8 | C8: 🧱 | D8: 🧱 | E8: 🧱 | F8: 🧱 | G8: ┏ | H8: ┓ | I8: 🧱 | J8: 🌵 | K8: 🧱 | L8: 🧱 | M8: ┗ | N8: ━ | O8: ┓ | P8: 🧱 | Q8: ┃ | R8: 🧱 | S8: 🌱 | T8: 🌱 | U8: 🌱 | V8: 🧱 | W8: ┃ | X8: 🧱 | Y8: ┃ | Z8: 🧱 | AA8: ┏ | AB8: ┛ | AC8: ┃ | AD8: ┃ | AE8: 🧱 | AF8: ┏ | AG8: ┛ | AH8: 🧱 | AI8: ┃ | AJ8: 🧱 | AK8: ┃ | AL8: ┏ | AM8: ━ | AN8: ┛ | AO8: 🧱 | AP8: ┃ | AQ8: ┃ | AR8: 🧱 | AS8: ┃ | AT8: ┗ | AU8: ━ | AV8: ┓ | AW8: 🧱 | AX8: 🧱 | BC8: H3 | BD8: 🧱 | BQ8: 1001 | BR8: 0011 | BS8: 0110 | BW8: 1100 | CC8: 1100 | CE8: 1100 | CH8: 1100 | CI8: 1100 | CJ8: 1100 | CL8: 1001 | CM8: 0110 | CO8: 1100 | CQ8: 0101 | CR8: 0011 | CS8: 1010 | CT8: 0101 | CU8: 1010 | CV8: 1100 | CW8: 0101 | CX8: 0011 | CY8: 0110 | CZ8: 1100
A9: 9 | C9: 🧱 | D9: 🧱 | E9: ┏ | F9: ━ | G9: ┛ | H9: ┃ | I9: 🧱 | J9: 🌵 | K9: 🌵 | L9: 🌵 | M9: 🧱 | N9: 🧱 | O9: ┃ | P9: 🧱 | Q9: ┃ | R9: 🧱 | S9: 🧱 | T9: 🧱 | U9: 🧱 | V9: 🧱 | W9: ┃ | X9: 🧱 | Y9: ┃ | Z9: ┏ | AA9: ┛ | AB9: 🧱 | AC9: ┃ | AD9: ┃ | AE9: 🧱 | AF9: ┃ | AG9: 🧱 | AH9: 🧱 | AI9: ┃ | AJ9: 🧱 | AK9: ┃ | AL9: ┃ | AM9: 🧱 | AN9: 🧱 | AO9: 🧱 | AP9: ┃ | AQ9: ┗ | AR9: ┓ | AS9: ┃ | AT9: 🧱 | AU9: 🧱 | AV9: ┃ | AW9: 🧱 | AX9: 🧱 | BC9: I3 | BD9: 🧱 | BM9: 0101 | BN9: 0110 | BS9: 1001 | BT9: 0011 | BU9: 0110 | BW9: 1100 | CC9: 1100 | CE9: 1100 | CG9: 0101 | CH9: 1010 | CI9: 1100 | CJ9: 1100 | CL9: 0101 | CM9: 1010 | CO9: 1100 | CQ9: 1100 | CR9: 0101 | CS9: 0011 | CT9: 1010 | CV9: 1100 | CW9: 1100 | CY9: 1100 | CZ9: 1001 | DA9: 0011 | DB9: 0110
A10: 10 | C10: 🧱 | D10: 🧱 | E10: ┃ | F10: 🧱 | G10: 🧱 | H10: ┗ | I10: ┓ | J10: 🧱 | K10: 🧱 | L10: 🧱 | M10: 🧱 | N10: ┏ | O10: ┛ | P10: 🧱 | Q10: ┗ | R10: ┓ | S10: 🧱 | T10: ┏ | U10: ┓ | V10: 🧱 | W10: ┃ | X10: 🧱 | Y10: ┗ | Z10: ┛ | AA10: 🧱 | AB10: 🧱 | AC10: ┃ | AD10: ┃ | AE10: 🧱 | AF10: ┗ | AG10: ━ | AH10: ━ | AI10: ┛ | AJ10: 🧱 | AK10: ┃ | AL10: ┃ | AM10: 🧱 | AN10: 🌿 | AO10: 🧱 | AP10: ┗ | AQ10: ┓ | AR10: ┃ | AS10: ┃ | AT10: 🧱 | AU10: ┏ | AV10: ┛ | AW10: 🧱 | AX10: 🧱 | BC10: J3 | BD10: 🧱 | BK10: 0101 | BL10: 0011 | BM10: 1010 | BN10: 1100 | BU10: 1100 | BW10: 1100 | CC10: 1100 | CE10: 1100 | CF10: 0101 | CG10: 1010 | CI10: 1100 | CJ10: 1100 | CL10: 1100 | CO10: 1100 | CQ10: 1100 | CR10: 1100 | CV10: 1100 | CW10: 1001 | CX10: 0110 | CY10: 1100 | DB10: 1100
A11: 11 | C11: 🧱 | D11: 🧱 | E11: ┃ | F11: 🧱 | G11: 🌳 | H11: 🧱 | I11: ┗ | J11: ━ | K11: ━ | L11: ━ | M11: ━ | N11: ┛ | O11: 🧱 | P11: 🧱 | Q11: 🧱 | R11: ┗ | S11: ━ | T11: ┛ | U11: ○ | V11: 🧱 | W11: ◉ | X11: 🧱 | Y11: 🧱 | Z11: 🧱 | AA11: 🧱 | AB11: 🧱 | AC11: ┗ | AD11: ┛ | AE11: 🧱 | AF11: 🧱 | AG11: 🧱 | AH11: 🧱 | AI11: 🧱 | AJ11: 🧱 | AK11: ┗ | AL11: ┛ | AM11: 🧱 | AN11: 🌿 | AO11: 🧱 | AP11: 🧱 | AQ11: ┃ | AR11: ┃ | AS11: ┃ | AT11: 🧱 | AU11: ┃ | AV11: 🧱 | AW11: 🧱 | AX11: 🧱 | BC11: K3 | BD11: 🧱 | BK11: 1100 | BN11: 1001 | BO11: 0110 | BT11: 0101 | BU11: 1010 | BW11: 1001 | BX11: 0110 | BZ11: 0101 | CA11: 0110 | CC11: 1100 | CE11: 1001 | CF11: 1010 | CI11: 1100 | CJ11: 1100 | CL11: 1001 | CM11: 0011 | CN11: 0011 | CO11: 1010 | CQ11: 1100 | CR11: 1100 | CV11: 1001 | CW11: 0110 | CX11: 1100 | CY11: 1100 | DA11: 0101 | DB11: 1010
A12: 12 | C12: 🧱 | D12: 🧱 | E12: ┃ | F12: 🧱 | G12: 🌳 | H12: 🌳 | I12: 🧱 | J12: 🧱 | K12: 🧱 | L12: 🧱 | M12: 🧱 | N12: 🧱 | O12: 🧱 | P12: 🌵 | Q12: 🧱 | R12: 🧱 | S12: 🧱 | T12: 🧱 | U12: 🧱 | V12: 🧱 | W12: 🧱 | X12: 🧱 | Y12: 🧱 | Z12: 🌾 | AA12: 🌾 | AB12: 🧱 | AC12: 🧱 | AD12: 🧱 | AE12: 🧱 | AF12: 🌾 | AG12: 🌾 | AH12: 🌾 | AI12: 🧱 | AJ12: 🧱 | AK12: 🧱 | AL12: 🧱 | AM12: 🧱 | AN12: 🌿 | AO12: 🌿 | AP12: 🧱 | AQ12: ┃ | AR12: ┃ | AS12: ┃ | AT12: 🧱 | AU12: ┗ | AV12: ━ | AW12: ┓ | AX12: 🧱 | BC12: L3 | BD12: 🧱 | BK12: 1100 | BO12: 1001 | BP12: 0011 | BQ12: 0011 | BR12: 0011 | BS12: 0011 | BT12: 1010 | BX12: 1001 | BY12: 0011 | BZ12: 1010 | CI12: 1001 | CJ12: 1010 | CQ12: 1001 | CR12: 1010 | CW12: 1100 | CX12: 1100 | CY12: 1100 | DA12: 1100
A13: 13 | C13: 🧱 | D13: 🧱 | E13: ○ | F13: 🧱 | G13: 🌳 | H13: 🌳 | I13: 🌳 | J13: 🌵 | K13: 🌵 | L13: 🌵 | M13: 🌵 | N13: 🌵 | O13: 🌵 | P13: 🌵 | Q13: 🌵 | R13: 🧱 | S13: 🧱 | T13: 🧱 | U13: 🧱 | V13: 🧱 | W13: 🧱 | X13: ◉ | Y13: 🧱 | Z13: 🧱 | AA13: 🌾 | AB13: 🌾 | AC13: 🧱 | AD13: 🧱 | AE13: 🧱 | AF13: 🧱 | AG13: 🧱 | AH13: 🧱 | AI13: 🧱 | AJ13: 🧱 | AK13: 🌿 | AL13: 🌿 | AM13: 🌿 | AN13: 🌿 | AO13: 🌿 | AP13: 🧱 | AQ13: ┃ | AR13: ┃ | AS13: ┗ | AT13: ━ | AU13: ━ | AV13: ━ | AW13: ┛ | AX13: 🧱 | BC13: M3 | BD13: 🧱 | BK13: 1100 | CW13: 1100 | CX13: 1100 | CY13: 1100 | DA13: 1001 | DB13: 0011 | DC13: 0110
A14: 14 | C14: 🧱 | D14: 🧱 | E14: 🧱 | F14: 🧱 | G14: 🌳 | H14: 🌳 | I14: 🌳 | J14: 🌵 | K14: 🌵 | L14: 🌵 | M14: 🌵 | N14: 🌵 | O14: 🌵 | P14: 🌵 | Q14: 🧱 | R14: 🧱 | S14: ┏ | T14: ━ | U14: ━ | V14: ┓ | W14: 🧱 | X14: ┗ | Y14: ┓ | Z14: 🧱 | AA14: 🌾 | AB14: 🧱 | AC14: 🧱 | AD14: ◉ | AE14: ┓ | AF14: 🧱 | AG14: 🧱 | AH14: ┏ | AI14: ┓ | AJ14: 🧱 | AK14: 🌿 | AL14: 🌿 | AM14: 🌿 | AN14: 🌿 | AO14: 🌿 | AP14: 🧱 | AQ14: ┃ | AR14: ┗ | AS14: ━ | AT14: ━ | AU14: ┓ | AV14: 🧱 | AW14: 🧱 | AX14: 🧱 | BC14: N3 | BD14: 🧱 | CW14: 1100 | CX14: 1100 | CY14: 1001 | CZ14: 0011 | DA14: 0011 | DB14: 0011 | DC14: 1010
A15: 15 | C15: 🧱 | D15: 🧱 | E15: 🧱 | F15: 🧱 | G15: 🌳 | H15: 🌳 | I15: 🌳 | J15: 🧱 | K15: 🧱 | L15: 🧱 | M15: 🧱 | N15: 🧱 | O15: 🧱 | P15: 🧱 | Q15: 🧱 | R15: ┏ | S15: ┛ | T15: 🧱 | U15: 🧱 | V15: ┃ | W15: 🧱 | X15: ┏ | Y15: ┛ | Z15: 🧱 | AA15: 🧱 | AB15: 🧱 | AC15: 🧱 | AD15: 🧱 | AE15: ┗ | AF15: ┓ | AG15: ┏ | AH15: ┛ | AI15: ┃ | AJ15: 🧱 | AK15: 🌿 | AL15: 🌿 | AM15: 🌿 | AN15: 🌿 | AO15: 🌿 | AP15: 🧱 | AQ15: ┗ | AR15: ━ | AS15: ━ | AT15: ━ | AU15: ┛ | AV15: 🧱 | AW15: 🧱 | AX15: 🧱 | BC15: O3 | BD15: 🧱 | BY15: 0101 | BZ15: 0011 | CA15: 0011 | CB15: 0110 | CD15: 1001 | CE15: 0110 | CK15: 0110 | CN15: 0101 | CO15: 0110 | CW15: 1100 | CX15: 1001 | CY15: 0011 | CZ15: 0011 | DA15: 0110
A16: 16 | C16: 🧱 | D16: ┏ | E16: ┓ | F16: 🧱 | G16: 🌳 | H16: 🌳 | I16: 🌳 | J16: 🧱 | K16: 🧱 | L16: 🧱 | M16: 🧱 | N16: ┏ | O16: ━ | P16: ━ | Q16: ┓ | R16: ┃ | S16: 🧱 | T16: 🌵 | U16: 🧱 | V16: ┃ | W16: 🧱 | X16: ┃ | Y16: 🧱 | Z16: 🧱 | AA16: ┏ | AB16: ┓ | AC16: 🧱 | AD16: 🧱 | AE16: 🧱 | AF16: ┃ | AG16: ┃ | AH16: 🧱 | AI16: ┃ | AJ16: 🧱 | AK16: 🌿 | AL16: 🌿 | AM16: 🌿 | AN16: 🌿 | AO16: 🌿 | AP16: 🧱 | AQ16: 🧱 | AR16: 🧱 | AS16: ┏ | AT16: ━ | AU16: ━ | AV16: ◉ | AW16: 🧱 | AX16: 🧱 | BC16: P3 | BD16: 🧱 | BX16: 0101 | BY16: 1010 | CB16: 1100 | CD16: 0101 | CE16: 1010 | CK16: 1001 | CL16: 0110 | CM16: 0101 | CN16: 1010 | CO16: 1100 | CW16: 1001 | CX16: 0011 | CY16: 0011 | CZ16: 0011 | DA16: 1010
A17: 17 | C17: 🧱 | D17: ┃ | E17: ┃ | F17: 🧱 | G17: 🌳 | H17: 🌳 | I17: 🌳 | J17: 🧱 | K17: ┏ | L17: ┓ | M17: 🧱 | N17: ┃ | O17: 🧱 | P17: 🧱 | Q17: ┃ | R17: ┃ | S17: 🧱 | T17: 🧱 | U17: 🧱 | V17: ┃ | W17: 🧱 | X17: ┃ | Y17: 🧱 | Z17: 🧱 | AA17: ┃ | AB17: ┃ | AC17: 🧱 | AD17: 🌻 | AE17: 🧱 | AF17: ┗ | AG17: ┛ | AH17: 🧱 | AI17: ┃ | AJ17: 🧱 | AK17: 🌿 | AL17: 🌿 | AM17: 🌿 | AN17: 🧱 | AO17: 🧱 | AP17: 🧱 | AQ17: 🧱 | AR17: 🧱 | AS17: ┃ | AT17: 🧱 | AU17: 🧱 | AV17: 🧱 | AW17: 🧱 | AX17: 🧱 | BC17: Q3 | BD17: 🧱 | BJ17: 0101 | BK17: 0110 | BT17: 0101 | BU17: 0011 | BV17: 0011 | BW17: 0110 | BX17: 1100 | CB17: 1100 | CD17: 1100 | CG17: 0101 | CH17: 0110 | CL17: 1100 | CM17: 1100 | CO17: 1100 | CY17: 0101 | CZ17: 0011 | DA17: 0011
A18: 18 | C18: 🧱 | D18: ┃ | E18: ┃ | F18: 🧱 | G18: 🌳 | H18: 🌳 | I18: 🌳 | J18: 🧱 | K18: ┃ | L18: ┗ | M18: ━ | N18: ┛ | O18: 🧱 | P18: 🧱 | Q18: ┃ | R18: ┗ | S18: ┓ | T18: 🧱 | U18: 🧱 | V18: ┃ | W18: 🧱 | X18: ┃ | Y18: 🧱 | Z18: 🧱 | AA18: ┃ | AB18: ┃ | AC18: 🧱 | AD18: 🌻 | AE18: 🌻 | AF18: 🧱 | AG18: 🧱 | AH18: 🧱 | AI18: ┃ | AJ18: 🧱 | AK18: 🌿 | AL18: 🌿 | AM18: 🌿 | AN18: 🧱 | AO18: ┏ | AP18: ━ | AQ18: ┓ | AR18: 🧱 | AS18: ┃ | AT18: 🧱 | AU18: 🌾 | AV18: 🌾 | AW18: 🌾 | AX18: 🧱 | BC18: R3 | BD18: 🧱 | BJ18: 1100 | BK18: 1100 | BQ18: 0101 | BR18: 0110 | BT18: 1100 | BW18: 1100 | BX18: 1100 | CB18: 1100 | CD18: 1100 | CG18: 1100 | CH18: 1100 | CL18: 1001 | CM18: 1010 | CO18: 1100 | CY18: 1100
A19: 19 | C19: 🧱 | D19: ┃ | E19: ┗ | F19: ┓ | G19: 🧱 | H19: 🌳 | I19: 🌳 | J19: 🧱 | K19: ┃ | L19: 🧱 | M19: 🧱 | N19: 🧱 | O19: 🧱 | P19: 🧱 | Q19: ┗ | R19: ┓ | S19: ┗ | T19: ┓ | U19: 🧱 | V19: ┃ | W19: 🧱 | X19: ┃ | Y19: 🧱 | Z19: 🧱 | AA19: ┃ | AB19: ┃ | AC19: 🧱 | AD19: 🌻 | AE19: 🌻 | AF19: 🌼 | AG19: 🌼 | AH19: 🧱 | AI19: ┃ | AJ19: 🧱 | AK19: 🌿 | AL19: 🌿 | AM19: 🌿 | AN19: 🧱 | AO19: ┃ | AP19: 🧱 | AQ19: ┃ | AR19: 🧱 | AS19: ┃ | AT19: 🧱 | AU19: 🌾 | AV19: 🌾 | AW19: 🌾 | AX19: 🧱 | BC19: S3 | BD19: 🧱 | BJ19: 1100 | BK19: 1100 | BQ19: 1100 | BR19: 1001 | BS19: 0011 | BT19: 1010 | BW19: 1100 | BX19: 1001 | BY19: 0110 | CB19: 1100 | CD19: 1100 | CG19: 1100 | CH19: 1100 | CO19: 1100 | CU19: 0101 | CV19: 0011 | CW19: 0110 | CY19: 1100
A20: 20 | C20: 🧱 | D20: ┃ | E20: 🧱 | F20: ┃ | G20: 🧱 | H20: 🌳 | I20: 🧱 | J20: 🧱 | K20: ┃ | L20: 🧱 | M20: 🌴 | N20: 🌴 | O20: 🌴 | P20: 🌴 | Q20: 🧱 | R20: ┗ | S20: ┓ | T20: ┃ | U20: 🧱 | V20: ┃ | W20: 🧱 | X20: ┗ | Y20: ┓ | Z20: 🧱 | AA20: ┃ | AB20: ┃ | AC20: 🧱 | AD20: 🌻 | AE20: 🌻 | AF20: 🌼 | AG20: 🌼 | AH20: 🧱 | AI20: ┃ | AJ20: 🧱 | AK20: 🌿 | AL20: 🌿 | AM20: 🌿 | AN20: 🧱 | AO20: ┗ | AP20: ┓ | AQ20: ┃ | AR20: 🧱 | AS20: ┃ | AT20: 🧱 | AU20: 🧱 | AV20: 🧱 | AW20: 🧱 | AX20: 🧱 | BC20: T3 | BD20: 🧱 | BJ20: 1100 | BK20: 1001 | BL20: 0110 | BQ20: 1100 | BW20: 1001 | BX20: 0110 | BY20: 1001 | BZ20: 0110 | CB20: 1100 | CD20: 1100 | CG20: 1100 | CH20: 1100 | CO20: 1100 | CU20: 1100 | CW20: 1100 | CY20: 1100
A21: 21 | C21: 🧱 | D21: ┃ | E21: 🧱 | F21: ┃ | G21: 🧱 | H21: 🧱 | I21: 🧱 | J21: ┏ | K21: ┛ | L21: 🧱 | M21: 🌴 | N21: 🌴 | O21: 🌴 | P21: 🌴 | Q21: 🧱 | R21: 🧱 | S21: ┗ | T21: ┛ | U21: 🧱 | V21: ┃ | W21: 🧱 | X21: 🧱 | Y21: ┗ | Z21: ━ | AA21: ┛ | AB21: ○ | AC21: 🧱 | AD21: 🌻 | AE21: 🌻 | AF21: 🌼 | AG21: 🌼 | AH21: 🧱 | AI21: ┃ | AJ21: 🧱 | AK21: 🧱 | AL21: 🧱 | AM21: 🌿 | AN21: 🧱 | AO21: 🧱 | AP21: ┃ | AQ21: ┃ | AR21: 🧱 | AS21: ┗ | AT21: ━ | AU21: ━ | AV21: ┓ | AW21: 🧱 | AX21: 🧱 | BC21: U3 | BD21: 🧱 | BJ21: 1100 | BL21: 1100 | BQ21: 1100 | BX21: 1001 | BY21: 0110 | BZ21: 1100 | CB21: 1100 | CD21: 1001 | CE21: 0110 | CG21: 1100 | CH21: 1100 | CO21: 1100 | CU21: 1001 | CV21: 0110 | CW21: 1100 | CY21: 1100
A22: 22 | C22: 🧱 | D22: ◉ | E22: 🧱 | F22: ┗ | G22: ━ | H22: ━ | I22: ━ | J22: ┛ | K22: 🧱 | L22: 🧱 | M22: 🧱 | N22: 🌴 | O22: 🌴 | P22: 🧱 | Q22: 🧱 | R22: 🧱 | S22: 🧱 | T22: 🧱 | U22: 🧱 | V22: ○ | W22: 🧱 | X22: 🧱 | Y22: 🧱 | Z22: 🧱 | AA22: 🧱 | AB22: 🧱 | AC22: 🧱 | AD22: 🌻 | AE22: 🌻 | AF22: 🧱 | AG22: 🧱 | AH22: 🧱 | AI22: ┗ | AJ22: ━ | AK22: ○ | AL22: 🧱 | AM22: 🌿 | AN22: 🌿 | AO22: 🧱 | AP22: ┃ | AQ22: ┃ | AR22: 🧱 | AS22: 🧱 | AT22: 🧱 | AU22: 🧱 | AV22: ┃ | AW22: 🧱 | AX22: 🧱 | BC22: V3 | BD22: 🧱 | BJ22: 1100 | BL22: 1100 | BP22: 0101 | BQ22: 1010 | BY22: 1001 | BZ22: 1010 | CB22: 1100 | CE22: 1001 | CF22: 0011 | CG22: 1010 | CO22: 1100 | CV22: 1100 | CW22: 1100 | CY22: 1001 | CZ22: 0011 | DA22: 0011 | DB22: 0110
A23: 23 | C23: ○ | D23: ━ | E23: ━ | F23: ┓ | G23: 🧱 | H23: 🧱 | I23: 🧱 | J23: 🧱 | K23: 🧱 | L23: 🧱 | M23: 🧱 | N23: 🧱 | O23: 🌴 | P23: 🧱 | Q23: 🧱 | R23: 🧱 | S23: 🧱 | T23: 🧱 | U23: 🧱 | V23: 🧱 | W23: 🧱 | X23: 🧱 | Y23: 🧱 | Z23: 🌲 | AA23: 🧱 | AB23: 🧱 | AC23: 🧱 | AD23: 🧱 | AE23: 🧱 | AF23: 🧱 | AG23: ○ | AH23: 🧱 | AI23: 🧱 | AJ23: 🧱 | AK23: 🧱 | AL23: 🧱 | AM23: 🧱 | AN23: 🌿 | AO23: 🧱 | AP23: ┃ | AQ23: ┗ | AR23: ━ | AS23: ━ | AT23: ┓ | AU23: ┏ | AV23: ┛ | AW23: 🧱 | AX23: 🧱 | BC23: W3 | BD23: 🧱 | BL23: 1001 | BM23: 0011 | BN23: 0011 | BO23: 0011 | BP23: 1010 | CO23: 1001 | CP23: 0011 | CV23: 1100 | CW23: 1100 | DB23: 1100
A24: 24 | C24: 🧱 | D24: 🧱 | E24: 🧱 | F24: ┃ | G24: 🧱 | H24: 🧱 | I24: 🧱 | J24: 🧱 | K24: ○ | L24: ━ | M24: ┓ | N24: 🧱 | O24: 🌴 | P24: 🧱 | Q24: 🧱 | R24: 🧱 | S24: ┏ | T24: ━ | U24: ┓ | V24: 🧱 | W24: 🧱 | X24: ◉ | Y24: 🧱 | Z24: 🌲 | AA24: 🧱 | AB24: ○ | AC24: 🧱 | AD24: ┏ | AE24: ━ | AF24: ┓ | AG24: ┃ | AH24: 🧱 | AI24: ◉ | AJ24: ━ | AK24: ━ | AL24: ┓ | AM24: 🧱 | AN24: 🧱 | AO24: 🧱 | AP24: ┃ | AQ24: ┏ | AR24: ━ | AS24: ━ | AT24: ┛ | AU24: ┗ | AV24: ┓ | AW24: 🧱 | AX24: 🧱 | BC24: X3 | BD24: 🧱 | BJ24: 0011 | BK24: 0011 | BL24: 0110 | CV24: 1100 | CW24: 1001 | CX24: 0011 | CY24: 0011 | CZ24: 0110 | DA24: 0101 | DB24: 1010
A25: 25 | C25: 🧱 | D25: 🍄 | E25: 🧱 | F25: ┗ | G25: ┓ | H25: 🧱 | I25: 🧱 | J25: 🧱 | K25: 🧱 | L25: 🧱 | M25: ┃ | N25: 🧱 | O25: 🌴 | P25: 🧱 | Q25: 🧱 | R25: ┏ | S25: ┛ | T25: 🧱 | U25: ┗ | V25: ┓ | W25: 🧱 | X25: ┃ | Y25: 🧱 | Z25: 🌲 | AA25: 🧱 | AB25: ┃ | AC25: 🧱 | AD25: ┃ | AE25: 🧱 | AF25: ┗ | AG25: ┛ | AH25: 🧱 | AI25: 🧱 | AJ25: 🧱 | AK25: 🧱 | AL25: ┗ | AM25: ━ | AN25: ┓ | AO25: 🧱 | AP25: ┃ | AQ25: ┗ | AR25: ━ | AS25: ━ | AT25: ┓ | AU25: ┏ | AV25: ┛ | AW25: 🧱 | AX25: 🧱 | BC25: Y3 | BD25: 🧱 | BL25: 1100 | BR25: 0011 | BS25: 0110 | BY25: 0101 | BZ25: 0011 | CA25: 0110 | CJ25: 0101 | CK25: 0011 | CL25: 0110 | CM25: 1100 | CP25: 0011 | CQ25: 0011 | CR25: 0110 | CV25: 1100 | CW25: 0101 | CX25: 0011 | CY25: 0011 | CZ25: 1010 | DA25: 1001 | DB25: 0110
A26: 26 | C26: 🧱 | D26: 🍄 | E26: 🧱 | F26: 🧱 | G26: ┃ | H26: 🧱 | I26: 🍄 | J26: 🍄 | K26: 🍄 | L26: 🧱 | M26: ┃ | N26: 🧱 | O26: 🌴 | P26: 🧱 | Q26: 🧱 | R26: ┃ | S26: 🧱 | T26: 🧱 | U26: 🧱 | V26: ┃ | W26: 🧱 | X26: ┃ | Y26: 🧱 | Z26: 🌲 | AA26: 🧱 | AB26: ┃ | AC26: 🧱 | AD26: ┃ | AE26: 🧱 | AF26: 🧱 | AG26: 🧱 | AH26: 🧱 | AI26: ┏ | AJ26: ━ | AK26: ━ | AL26: ━ | AM26: ━ | AN26: ┛ | AO26: ○ | AP26: ┛ | AQ26: 🧱 | AR26: 🧱 | AS26: 🧱 | AT26: ┗ | AU26: ┛ | AV26: 🧱 | AW26: 🧱 | AX26: 🧱 | BC26: Z3 | BD26: 🧱 | BL26: 1001 | BM26: 0110 | BS26: 1100 | BX26: 0101 | BY26: 1010 | CA26: 1001 | CB26: 0110 | CD26: 1100 | CH26: 1100 | CJ26: 1100 | CL26: 1001 | CM26: 1010 | CR26: 1001 | CS26: 0011 | CT26: 0110 | CV26: 1100 | CW26: 1001 | CX26: 0011 | CY26: 0011 | CZ26: 0110 | DA26: 0101 | DB26: 1010
A27: 27 | C27: 🧱 | D27: 🍄 | E27: 🍄 | F27: 🧱 | G27: ┃ | H27: 🧱 | I27: 🍄 | J27: 🍄 | K27: 🍄 | L27: 🧱 | M27: ┃ | N27: 🧱 | O27: 🌴 | P27: 🧱 | Q27: 🧱 | R27: ┃ | S27: 🧱 | T27: 🧱 | U27: 🧱 | V27: ┃ | W27: 🧱 | X27: ┃ | Y27: 🧱 | Z27: 🌲 | AA27: 🧱 | AB27: ┃ | AC27: 🧱 | AD27: ┃ | AE27: 🧱 | AF27: 🌽 | AG27: 🌽 | AH27: 🧱 | AI27: ┗ | AJ27: ━ | AK27: ━ | AL27: ┓ | AM27: 🧱 | AN27: 🧱 | AO27: 🧱 | AP27: 🧱 | AQ27: 🧱 | AR27: ○ | AS27: ┓ | AT27: 🧱 | AU27: 🧱 | AV27: ◉ | AW27: 🧱 | AX27: 🧱 | BC27: AA3 | BD27: 🧱 | BM27: 1100 | BS27: 1100 | BX27: 1100 | CB27: 1100 | CD27: 1100 | CH27: 1100 | CJ27: 1100 | CO27: 0101 | CP27: 0011 | CQ27: 0011 | CR27: 0011 | CS27: 0011 | CT27: 1010 | CV27: 1010 | CZ27: 1001 | DA27: 1010
A28: 28 | C28: 🧱 | D28: 🍄 | E28: 🍄 | F28: 🧱 | G28: ┃ | H28: 🧱 | I28: 🍄 | J28: 🍄 | K28: 🍄 | L28: 🧱 | M28: ┃ | N28: 🧱 | O28: 🌴 | P28: 🧱 | Q28: 🧱 | R28: ┃ | S28: ┏ | T28: ━ | U28: ━ | V28: ┛ | W28: 🧱 | X28: ┃ | Y28: 🧱 | Z28: 🌲 | AA28: 🧱 | AB28: ┃ | AC28: 🧱 | AD28: ┃ | AE28: 🧱 | AF28: 🌽 | AG28: 🌽 | AH28: 🧱 | AI28: ┏ | AJ28: ━ | AK28: ━ | AL28: ┛ | AM28: 🧱 | AN28: 🌱 | AO28: 🌱 | AP28: 🌱 | AQ28: 🌱 | AR28: 🧱 | AS28: ┗ | AT28: ┓ | AU28: 🧱 | AV28: ┃ | AW28: 🧱 | AX28: 🧱 | BC28: AB3 | BD28: 🧱 | BM28: 1100 | BS28: 1100 | BX28: 1100 | CB28: 1100 | CD28: 1100 | CH28: 1100 | CJ28: 1100 | CO28: 1001 | CP28: 0011 | CQ28: 0011 | CR28: 0110 | CY28: 0110
A29: 29 | C29: 🧱 | D29: 🍄 | E29: 🍄 | F29: 🧱 | G29: ┃ | H29: 🧱 | I29: 🍄 | J29: 🍄 | K29: 🍄 | L29: 🧱 | M29: ┃ | N29: 🧱 | O29: 🌴 | P29: 🧱 | Q29: 🧱 | R29: ┃ | S29: ┗ | T29: ━ | U29: ━ | V29: ┓ | W29: 🧱 | X29: ┃ | Y29: 🧱 | Z29: 🌲 | AA29: 🧱 | AB29: ┃ | AC29: 🧱 | AD29: ┃ | AE29: 🧱 | AF29: 🧱 | AG29: 🧱 | AH29: 🧱 | AI29: ┃ | AJ29: 🧱 | AK29: 🧱 | AL29: 🧱 | AM29: 🧱 | AN29: 🌱 | AO29: 🌱 | AP29: 🌱 | AQ29: 🌱 | AR29: 🧱 | AS29: 🧱 | AT29: ┗ | AU29: ┓ | AV29: ┃ | AW29: 🧱 | AX29: 🧱 | BC29: AC3 | BD29: 🧱 | BM29: 1100 | BS29: 1100 | BX29: 1100 | BY29: 0101 | BZ29: 0011 | CA29: 0011 | CB29: 1010 | CD29: 1100 | CH29: 1100 | CJ29: 1100 | CO29: 0101 | CP29: 0011 | CQ29: 0011 | CR29: 1010 | CY29: 1001 | CZ29: 0110 | DB29: 1100
A30: 30 | C30: 🧱 | D30: 🍄 | E30: 🍄 | F30: 🧱 | G30: ┃ | H30: 🧱 | I30: 🍄 | J30: 🍄 | K30: 🍄 | L30: 🧱 | M30: ┃ | N30: 🧱 | O30: 🧱 | P30: 🧱 | Q30: ┏ | R30: ┛ | S30: 🧱 | T30: 🧱 | U30: 🧱 | V30: ┃ | W30: 🧱 | X30: ┗ | Y30: ┓ | Z30: 🧱 | AA30: ┏ | AB30: ┛ | AC30: 🧱 | AD30: ┗ | AE30: ━ | AF30: ━ | AG30: ┓ | AH30: 🧱 | AI30: ┃ | AJ30: 🧱 | AK30: 🧱 | AL30: 🧱 | AM30: 🧱 | AN30: 🧱 | AO30: 🧱 | AP30: 🌱 | AQ30: 🌱 | AR30: 🌽 | AS30: 🧱 | AT30: 🧱 | AU30: ┃ | AV30: ┃ | AW30: 🧱 | AX30: 🧱 | BC30: AD3 | BD30: 🧱 | BM30: 1100 | BS30: 1100 | BX30: 1100 | BY30: 1001 | BZ30: 0011 | CA30: 0011 | CB30: 0110 | CD30: 1100 | CH30: 1100 | CJ30: 1100 | CO30: 1100 | CZ30: 1001 | DA30: 0110 | DB30: 1100
A31: 31 | C31: 🧱 | D31: 🍄 | E31: 🍄 | F31: 🧱 | G31: ┃ | H31: 🧱 | I31: 🧱 | J31: 🧱 | K31: 🧱 | L31: 🧱 | M31: ┗ | N31: ━ | O31: ━ | P31: ━ | Q31: ┛ | R31: ┏ | S31: ━ | T31: ┓ | U31: 🧱 | V31: ┃ | W31: 🧱 | X31: 🧱 | Y31: ┗ | Z31: ━ | AA31: ┛ | AB31: 🧱 | AC31: 🧱 | AD31: 🧱 | AE31: 🧱 | AF31: ┏ | AG31: ┛ | AH31: 🧱 | AI31: ┗ | AJ31: ━ | AK31: ━ | AL31: ━ | AM31: ━ | AN31: ┓ | AO31: 🧱 | AP31: 🌽 | AQ31: 🌽 | AR31: 🌽 | AS31: 🌽 | AT31: 🧱 | AU31: ┃ | AV31: ┃ | AW31: 🧱 | AX31: 🧱 | BC31: AE3 | BD31: 🧱 | BM31: 1100 | BS31: 1100 | BW31: 0101 | BX31: 1010 | CB31: 1100 | CD31: 1001 | CE31: 0110 | CG31: 0101 | CH31: 1010 | CJ31: 1001 | CK31: 0011 | CL31: 0011 | CM31: 0110 | CO31: 1100 | DA31: 1100 | DB31: 1100
A32: 32 | C32: 🧱 | D32: 🍄 | E32: 🧱 | F32: 🧱 | G32: ┗ | H32: ━ | I32: ━ | J32: ◉ | K32: 🧱 | L32: 🧱 | M32: 🧱 | N32: ┏ | O32: ━ | P32: ━ | Q32: ━ | R32: ┛ | S32: 🧱 | T32: ┃ | U32: 🧱 | V32: ┃ | W32: 🧱 | X32: 🧱 | Y32: 🧱 | Z32: 🧱 | AA32: 🧱 | AB32: 🧱 | AC32: 🧱 | AD32: ◉ | AE32: ━ | AF32: ┛ | AG32: 🧱 | AH32: 🧱 | AI32: ○ | AJ32: ━ | AK32: ━ | AL32: ━ | AM32: ━ | AN32: ┛ | AO32: 🧱 | AP32: 🌽 | AQ32: 🧱 | AR32: 🧱 | AS32: 🧱 | AT32: 🧱 | AU32: ┃ | AV32: ┃ | AW32: 🧱 | AX32: 🧱 | BC32: AF3 | BD32: 🧱 | BM32: 1100 | BS32: 1001 | BT32: 0011 | BU32: 0011 | BV32: 0011 | BW32: 1010 | BX32: 0101 | BY32: 0011 | BZ32: 0110 | CB32: 1100 | CE32: 1001 | CF32: 0011 | CG32: 1010 | CL32: 0101 | CM32: 1010 | CO32: 1001 | CP32: 0011 | CQ32: 0011 | CR32: 0011 | CS32: 0011 | CT32: 0110 | DA32: 1100 | DB32: 1100
A33: 33 | C33: 🧱 | D33: 🧱 | E33: 🧱 | F33: 🧱 | G33: 🧱 | H33: 🧱 | I33: 🧱 | J33: 🧱 | K33: ◉ | L33: ━ | M33: ━ | N33: ┛ | O33: 🧱 | P33: 🧱 | Q33: 🧱 | R33: 🧱 | S33: 🧱 | T33: ┗ | U33: ━ | V33: ┛ | W33: 🧱 | X33: 🧱 | Y33: 🧱 | Z33: 🍄 | AA33: 🍄 | AB33: 🍄 | AC33: 🧱 | AD33: 🧱 | AE33: 🧱 | AF33: 🧱 | AG33: 🧱 | AH33: 🧱 | AI33: 🧱 | AJ33: 🧱 | AK33: 🧱 | AL33: 🧱 | AM33: 🧱 | AN33: 🧱 | AO33: 🧱 | AP33: 🧱 | AQ33: 🧱 | AR33: ┏ | AS33: ━ | AT33: ━ | AU33: ┛ | AV33: ┃ | AW33: 🧱 | AX33: 🧱 | BC33: AG3 | BD33: 🧱 | BM33: 1001 | BN33: 0011 | BO33: 0011 | BT33: 0101 | BU33: 0011 | BV33: 0011 | BW33: 0011 | BX33: 1010 | BZ33: 1100 | CB33: 1100 | CK33: 0011 | CL33: 1010 | CP33: 0011 | CQ33: 0011 | CR33: 0011 | CS33: 0011 | CT33: 1010 | DA33: 1100 | DB33: 1100
A34: 34 | C34: 🧱 | D34: ┏ | E34: ━ | F34: ━ | G34: ━ | H34: ━ | I34: ◉ | J34: ┏ | K34: ━ | L34: ━ | M34: ┓ | N34: ○ | O34: 🧱 | P34: 🧱 | Q34: ┏ | R34: ━ | S34: ┓ | T34: 🧱 | U34: ◉ | V34: ┏ | W34: ━ | X34: ┓ | Y34: 🧱 | Z34: 🧱 | AA34: 🧱 | AB34: 🧱 | AC34: 🍄 | AD34: 🧱 | AE34: ○ | AF34: 🧱 | AG34: 🧱 | AH34: ┏ | AI34: ━ | AJ34: ┓ | AK34: 🧱 | AL34: 🧱 | AM34: ┏ | AN34: ━ | AO34: ━ | AP34: ━ | AQ34: ○ | AR34: ┃ | AS34: ┏ | AT34: ━ | AU34: ━ | AV34: ┛ | AW34: 🧱 | AX34: 🧱 | BC34: AH3 | BD34: 🧱 | BR34: 0011 | BS34: 0011 | BT34: 1010 | BZ34: 1001 | CA34: 0011 | CB34: 1010 | CX34: 0101 | CY34: 0011 | CZ34: 0011 | DA34: 1010 | DB34: 1100
A35: 35 | C35: 🧱 | D35: ┃ | E35: 🧱 | F35: 🧱 | G35: 🧱 | H35: 🧱 | I35: 🧱 | J35: ┃ | K35: ┏ | L35: ━ | M35: ┛ | N35: ┃ | O35: 🧱 | P35: ┏ | Q35: ┛ | R35: 🧱 | S35: ┗ | T35: ┓ | U35: ┃ | V35: ┃ | W35: 🧱 | X35: ┗ | Y35: ━ | Z35: ━ | AA35: ┓ | AB35: 🧱 | AC35: 🍄 | AD35: 🧱 | AE35: ┃ | AF35: 🧱 | AG35: ┏ | AH35: ┛ | AI35: 🧱 | AJ35: ┗ | AK35: ┓ | AL35: 🧱 | AM35: ┗ | AN35: ━ | AO35: ┓ | AP35: 🧱 | AQ35: 🧱 | AR35: ┃ | AS35: ┗ | AT35: ┓ | AU35: 🧱 | AV35: 🧱 | AW35: 🧱 | AX35: 🧱 | BC35: AI3 | BD35: ○ | BJ35: 0101 | BK35: 0011 | BL35: 0011 | BM35: 0011 | BN35: 0011 | BP35: 0101 | BQ35: 0011 | BR35: 0011 | BS35: 0110 | BW35: 0101 | BX35: 0011 | BY35: 0110 | CB35: 0101 | CC35: 0011 | CD35: 0110 | CN35: 0101 | CO35: 0011 | CP35: 0110 | CS35: 0101 | CT35: 0011 | CU35: 0011 | CV35: 0011 | CX35: 1100 | CY35: 0101 | CZ35: 0011 | DA35: 0011 | DB35: 1010
A36: 36 | C36: 🧱 | D36: ┃ | E36: 🧱 | F36: 🧱 | G36: 🧱 | H36: 🧱 | I36: 🧱 | J36: ┃ | K36: ┗ | L36: ━ | M36: ┓ | N36: ┃ | O36: 🧱 | P36: ┃ | Q36: 🧱 | R36: 🧱 | S36: 🧱 | T36: ┃ | U36: ┃ | V36: ┃ | W36: 🧱 | X36: 🧱 | Y36: 🧱 | Z36: 🧱 | AA36: ┃ | AB36: 🧱 | AC36: 🍄 | AD36: 🧱 | AE36: ┃ | AF36: 🧱 | AG36: ┃ | AH36: 🧱 | AI36: 🧱 | AJ36: 🧱 | AK36: ┃ | AL36: 🧱 | AM36: 🧱 | AN36: 🧱 | AO36: ┃ | AP36: 🧱 | AQ36: 🧱 | AR36: ┃ | AS36: ┏ | AT36: ┛ | AU36: 🧱 | AV36: 🧱 | AW36: 🧱 | AX36: 🧱 | BC36: AJ3 | BD36: 🧱 | BJ36: 1100 | BP36: 1100 | BQ36: 0101 | BR36: 0011 | BS36: 1010 | BT36: 1100 | BV36: 0101 | BW36: 1010 | BY36: 1001 | BZ36: 0110 | CA36: 1100 | CB36: 1100 | CD36: 1001 | CE36: 0011 | CF36: 0011 | CG36: 0110 | CK36: 1100 | CM36: 0101 | CN36: 1010 | CP36: 1001 | CQ36: 0110 | CS36: 1001 | CT36: 0011 | CU36: 0110 | CX36: 1100 | CY36: 1001 | CZ36: 0110
A37: 37 | C37: 🧱 | D37: ┃ | E37: 🧱 | F37: ┏ | G37: ━ | H37: ━ | I37: ┓ | J37: ┃ | K37: ┏ | L37: ━ | M37: ┛ | N37: ┃ | O37: 🧱 | P37: ┃ | Q37: 🧱 | R37: 🧱 | S37: 🧱 | T37: ┃ | U37: ┃ | V37: ┃ | W37: 🧱 | X37: 🌼 | Y37: 🌼 | Z37: 🧱 | AA37: ┃ | AB37: 🧱 | AC37: 🍄 | AD37: 🧱 | AE37: ┃ | AF37: 🧱 | AG37: ┃ | AH37: 🧱 | AI37: 🧱 | AJ37: 🧱 | AK37: ┃ | AL37: 🧱 | AM37: 🌵 | AN37: 🧱 | AO37: ┃ | AP37: 🧱 | AQ37: 🧱 | AR37: ┃ | AS37: ┗ | AT37: ━ | AU37: ━ | AV37: ┓ | AW37: 🧱 | AX37: 🧱 | BC37: AK3 | BD37: ◉ | BJ37: 1100 | BP37: 1100 | BQ37: 1001 | BR37: 0011 | BS37: 0110 | BT37: 1100 | BV37: 1100 | BZ37: 1100 | CA37: 1100 | CB37: 1100 | CG37: 1100 | CK37: 1100 | CM37: 1100 | CQ37: 1100 | CU37: 1100 | CX37: 1100 | CY37: 0101 | CZ37: 1010
A38: 38 | C38: 🧱 | D38: ┃ | E38: 🧱 | F38: ┗ | G38: ━ | H38: ┓ | I38: ┃ | J38: ┃ | K38: ┗ | L38: ┓ | M38: 🧱 | N38: ┃ | O38: 🧱 | P38: ┃ | Q38: ┏ | R38: ━ | S38: ━ | T38: ┛ | U38: ┃ | V38: ┃ | W38: 🧱 | X38: 🌼 | Y38: 🌼 | Z38: 🧱 | AA38: ┃ | AB38: 🧱 | AC38: 🍄 | AD38: 🧱 | AE38: ┃ | AF38: 🧱 | AG38: ┃ | AH38: ┏ | AI38: ━ | AJ38: ━ | AK38: ┛ | AL38: 🧱 | AM38: 🌵 | AN38: 🧱 | AO38: ┃ | AP38: 🧱 | AQ38: 🧱 | AR38: ┃ | AS38: ┏ | AT38: ━ | AU38: ━ | AV38: ┛ | AW38: 🧱 | AX38: 🧱 | BC38: AL3 | BD38: 🧱 | BJ38: 1100 | BL38: 0101 | BM38: 0011 | BN38: 0011 | BO38: 0110 | BP38: 1100 | BQ38: 0101 | BR38: 0011 | BS38: 1010 | BT38: 1100 | BV38: 1100 | BZ38: 1100 | CA38: 1100 | CB38: 1100 | CG38: 1100 | CK38: 1100 | CM38: 1100 | CQ38: 1100 | CU38: 1100 | CX38: 1100 | CY38: 1001 | CZ38: 0011 | DA38: 0011 | DB38: 0110
A39: 39 | C39: 🧱 | D39: ┃ | E39: 🧱 | F39: 🧱 | G39: 🧱 | H39: ┃ | I39: ┃ | J39: ┃ | K39: 🧱 | L39: ┗ | M39: ┓ | N39: ┃ | O39: 🧱 | P39: ┃ | Q39: ┗ | R39: ━ | S39: ━ | T39: ┓ | U39: ┃ | V39: ┃ | W39: 🧱 | X39: 🌼 | Y39: 🌼 | Z39: 🧱 | AA39: ┃ | AB39: 🧱 | AC39: 🍄 | AD39: 🧱 | AE39: ┃ | AF39: 🧱 | AG39: ┃ | AH39: ┗ | AI39: ━ | AJ39: ━ | AK39: ┓ | AL39: 🧱 | AM39: 🌵 | AN39: 🧱 | AO39: ┃ | AP39: 🧱 | AQ39: 🧱 | AR39: ┃ | AS39: ┗ | AT39: ┓ | AU39: 🧱 | AV39: 🧱 | AW39: 🧱 | AX39: 🧱 | BC39: AM3 | BD39: 🧱 | BJ39: 1100 | BL39: 1001 | BM39: 0011 | BN39: 0110 | BO39: 1100 | BP39: 1100 | BQ39: 1001 | BR39: 0110 | BT39: 1100 | BV39: 1100 | BW39: 0101 | BX39: 0011 | BY39: 0011 | BZ39: 1010 | CA39: 1100 | CB39: 1100 | CG39: 1100 | CK39: 1100 | CM39: 1100 | CN39: 0101 | CO39: 0011 | CP39: 0011 | CQ39: 1010 | CU39: 1100 | CX39: 1100 | CY39: 0101 | CZ39: 0011 | DA39: 0011 | DB39: 1010
A40: 40 | C40: 🧱 | D40: ┃ | E40: 🧱 | F40: 🧱 | G40: 🧱 | H40: ┃ | I40: ┃ | J40: ┃ | K40: 🧱 | L40: 🧱 | M40: ┗ | N40: ┛ | O40: 🧱 | P40: ┃ | Q40: 🧱 | R40: 🧱 | S40: 🧱 | T40: ┃ | U40: ┃ | V40: ┃ | W40: 🧱 | X40: 🌼 | Y40: 🌼 | Z40: 🧱 | AA40: ┗ | AB40: ┓ | AC40: 🧱 | AD40: ┏ | AE40: ┛ | AF40: 🧱 | AG40: ┃ | AH40: 🧱 | AI40: 🧱 | AJ40: 🧱 | AK40: ┃ | AL40: 🧱 | AM40: 🌵 | AN40: 🧱 | AO40: ┃ | AP40: 🧱 | AQ40: 🧱 | AR40: ┃ | AS40: ┏ | AT40: ┛ | AU40: 🧱 | AV40: 🧱 | AW40: 🧱 | AX40: 🧱 | BC40: AN3 | BD40: 🧱 | BJ40: 1100 | BN40: 1100 | BO40: 1100 | BP40: 1100 | BR40: 1001 | BS40: 0110 | BT40: 1100 | BV40: 1100 | BW40: 1001 | BX40: 0011 | BY40: 0011 | BZ40: 0110 | CA40: 1100 | CB40: 1100 | CG40: 1100 | CK40: 1100 | CM40: 1100 | CN40: 1001 | CO40: 0011 | CP40: 0011 | CQ40: 0110 | CU40: 1100 | CX40: 1100 | CY40: 1001 | CZ40: 0110
...

Sheet Graded Answers
B1: Your Answers
B2: Game # | C2: Answer | D2: Points
B3: Bonus 1 | C3: =IF(ISBLANK(Case!E53),"",Case!E53) -> 1167 | D3: 30
B4: Bonus 2 | C4: =IF(ISBLANK(Case!E54),"",Case!E54) -> 3 | D4: 40
B5: Bonus 3 | C5: =IF(ISBLANK(Case!E55),"",Case!E55) -> 10 | D5: 60
B6: Bonus 4 | C6: =IF(ISBLANK(Case!E56),"",Case!E56) -> 282 | D6: 50
B7: Bonus 5 | C7: =IF(ISBLANK(Case!E57),"",Case!E57) -> 46 | D7: 70
B8: 1 | C8: =IF(ISBLANK(Case!E80),"",Case!E80) -> 5 | D8: 5
B9: =B8+1 -> 2 | C9: =IF(ISBLANK(Case!E81),"",Case!E81) -> 2 | D9: 5
B10: =B9+1 -> 3 | C10: =IF(ISBLANK(Case!E82),"",Case!E82) -> 6 | D10: 5
B11: =B10+1 -> 4 | C11: =IF(ISBLANK(Case!E83),"",Case!E83) -> 3 | D11: 5
B12: =B11+1 -> 5 | C12: =IF(ISBLANK(Case!E84),"",Case!E84) -> 3 | D12: 5
B13: =B12+1 -> 6 | C13: =IF(ISBLANK(Case!E85),"",Case!E85) -> 6 | D13: 5
B14: =B13+1 -> 7 | C14: =IF(ISBLANK(Case!E86),"",Case!E86) -> 2 | D14: 5
B15: =B14+1 -> 8 | C15: =IF(ISBLANK(Case!E87),"",Case!E87) -> 8 | D15: 5
B16: =B15+1 -> 9 | C16: =IF(ISBLANK(Case!E88),"",Case!E88) -> 1 | D16: 5
B17: =B16+1 -> 10 | C17: =IF(ISBLANK(Case!E89),"",Case!E89) -> 3 | D17: 5
B18: =B17+1 -> 11 | C18: =IF(ISBLANK(Case!E90),"",Case!E90) -> 4 | D18: 5
B19: =B18+1 -> 12 | C19: =IF(ISBLANK(Case!E91),"",Case!E91) -> 1 | D19: 5
B20: =B19+1 -> 13 | C20: =IF(ISBLANK(Case!E92),"",Case!E92) -> 4 | D20: 5
... B27: =B26+1 -> 20 | C27: =IF(ISBLANK(Case!E99),"",Case!E99) -> 1 | D27: 5
B28: =B27+1 -> 21 | C28: =IF(ISBLANK(Case!E120),"",Case!E120) -> 262 | D28: 7
B29: =B28+1 -> 22 | C29: =IF(ISBLANK(Case!E121),"",Case!E121) -> 139 | D29: 7
B30: =B29+1 -> 23 | C30: =IF(ISBLANK(Case!E122),"",Case!E122) -> 64 | D30: 7
B31: =B30+1 -> 24 | C31: =IF(ISBLANK(Case!E123),"",Case!E123) -> 79 | D31: 7
B32: =B31+1 -> 25 | C32: =IF(ISBLANK(Case!E124),"",Case!E124) -> 79 | D32: 7
B33: =B32+1 -> 26 | C33: =IF(ISBLANK(Case!E125),"",Case!E125) -> 68 | D33: 7
B34: =B33+1 -> 27 | C34: =IF(ISBLANK(Case!E126),"",Case!E126) -> 21 | D34: 7
B35: =B34+1 -> 28 | C35: =IF(ISBLANK(Case!E127),"",Case!E127) -> 21 | D35: 7
B36: =B35+1 -> 29 | C36: =IF(ISBLANK(Case!E128),"",Case!E128) -> 937 | D36: 7
B37: =B36+1 -> 30 | C37: =IF(ISBLANK(Case!E129),"",Case!E129) -> 25 | D37: 7
B38: =B37+1 -> 31 | C38: =IF(ISBLANK(Case!E130),"",Case!E130) -> 26 | D38: 7
B39: =B38+1 -> 32 | C39: =IF(ISBLANK(Case!E131),"",Case!E131) -> 17 | D39: 7
... B47: =B46+1 -> 40 | C47: =IF(ISBLANK(Case!E139),"",Case!E139) -> 38 | D47: 7
B48: =B47+1 -> 41 | C48: =IF(ISBLANK(Case!E161),"",Case!E161) -> ┃ | D48: 6
B49: =B48+1 -> 42 | C49: =IF(ISBLANK(Case!E162),"",Case!E162) -> 🌱 | D49: 6
B50: =B49+1 -> 43 | C50: =IF(ISBLANK(Case!E163),"",Case!E163) -> ┏ | D50: 6
B51: =B50+1 -> 44 | C51: =IF(ISBLANK(Case!E164),"",Case!E164) -> 🌿 | D51: 6
B52: =B51+1 -> 45 | C52: =IF(ISBLANK(Case!E165),"",Case!E165) -> ┓ | D52: 6
B53: =B52+1 -> 46 | C53: =IF(ISBLANK(Case!E166),"",Case!E166) -> ○ | D53: 6
...
