Workbook

Sheet Case
B2: Microsoft Excel Collegiate Challenge 2026
B4: Understanding Your FICO Credit Score - Junior Varsity Edition | M4: Case Author
M5: David Brown
M7: Case Design Team
M8: Eric Kelley
M9: Winston Smith
M10: Chris McNeil
M11: Gina Nicolosi
B14: Instructions
B15: Alex is a college senior who dreams of buying a new car after graduation.
B16: Before heading to the dealership, Alex wants to understand how a FICO credit score is calculated, and how a higher score means a lower interest rate and lower monthly payment on her car loan.
B17: Work through each level to help Alex understand her credit score and figure out how much car she can afford!
B20: Bonus Questions
B22: To make the game more exciting, we have created 5 bonus questions for you. These questions can be answered at any time during the game.
B24: Game # | C24: Relates to Level # | D24: Points | E24: Answer | G24: Question
B25: Bonus 1 | C25: 1 | D25: 30 | E25: =ROUND(SUM(G51:G70)/SUM(H51:H70)*100,0) -> 30 | G25: In Level 1,if one borrower had all of the games' balances and credit limits (excluding the example), what would be their total credit card utilization? Sum the balances and divide by the sum of the credit limits and round to the nearest integer. Percents should be expressed as whole numbers, i.e., answer 24% as 24.
B26: Bonus 2 | C26: 3 | D26: 40 | E26: =COUNTIF(N129:R148,">50") -> 24 | G26: In Level 3, how many individual credit cards across all 20 games (excluding the example) have a utilization rate greater than 50%?
B27: Bonus 3 | C27: 5 | D27: 50 | E27: 715 | G27: In Level 5, what is the median FICO score across all 21 games (include the example)?
B28: Bonus 4 | C28: 6 | D28: 60 | E28: 207 | G28: In Level 6, what is the total number of FICO points lost to the previous credit inquiries across all 20 games combined (excluding the example)?
B29: Bonus 5 | C29: 7 | D29: 70 | E29: =SUMIF(H306:H325,">=700",_xlfn.ANCHORARRAY(E306))-SUMIF(H306:H325,"<700",_xlfn.ANCHORARRAY(E306)) -> 153848 | G29: In Level 7, how much more can borrowers with FICO scores of 700 or higher afford versus those with lower FICO scores? Sum the answers for the high FICO scores (>=700) and subtract the sum of the answers for the low FICO scores (<700).
B31: Questions
B33: Level 1 | C33: Easy
B35: After graduation, Alex wants to buy a car and needs a great credit score to get a low interest rate.
B36: One key factor is Credit Utilization — the percentage of a credit limit that is currently being used.
B37: Calculate Credit Utilization (=balance/limit) for each game based on the given balances and credit limits.
B38: Express Credit Utilization as a percentage by multiplying the calculation by 100.
B40: Example1: A card with a $350 balance and a $1,000 limit has a utilization rate of 35%. 35% x 100 = 35.
B42: Answer Hints:
B43: Game 1's answer is between 20 and 24.
B44: Game 2's answer is between 30 and 34.
B45: Game 3's answer is between 6 and 10.
B47: Game # | C47: Level | D47: Points | E47: Answer | G47: Balance ($) | H47: Credit Limit ($)
B49: Example1 | C49: 1 | D49: 0 | E49: 35 | G49: 350 | H49: 1000
B51: 1 | C51: 1 | D51: 4 | E51: =(G51/H51)*100 -> 22 | G51: 220 | H51: 1000
B52: 2 | C52: 1 | D52: 4 | E52: =(G52/H52)*100 -> 32 | G52: 480 | H52: 1500
B53: 3 | C53: 1 | D53: 4 | E53: =(G53/H53)*100 -> 8 | G53: 160 | H53: 2000
B54: 4 | C54: 1 | D54: 4 | E54: =(G54/H54)*100 -> 33 | G54: 825 | H54: 2500
B55: 5 | C55: 1 | D55: 4 | E55: =(G55/H55)*100 -> 35 | G55: 630 | H55: 1800
B56: 6 | C56: 1 | D56: 4 | E56: =(G56/H56)*100 -> 19 | G56: 95 | H56: 500
B57: 7 | C57: 1 | D57: 4 | E57: =(G57/H57)*100 -> 30 | G57: 1200 | H57: 4000
...

Sheet Graded Answers
B1: Your Answers
B2: Game # | C2: Answer | D2: Points
B3: Bonus 1 | C3: =IF(ISBLANK(Case!E25), "", Case!E25) -> 30 | D3: 30
B4: Bonus 2 | C4: =IF(ISBLANK(Case!E26), "", Case!E26) -> 24 | D4: 40
B5: Bonus 3 | C5: =IF(ISBLANK(Case!E27), "", Case!E27) -> 715 | D5: 50
B6: Bonus 4 | C6: =IF(ISBLANK(Case!E28), "", Case!E28) -> 207 | D6: 60
B7: Bonus 5 | C7: =IF(ISBLANK(Case!E29), "", Case!E29) -> 153848 | D7: 70
B8: 1 | C8: =IF(ISBLANK(Case!E51), "", Case!E51) -> 22 | D8: 4
B9: =B8+1 -> 2 | C9: =IF(ISBLANK(Case!E52), "", Case!E52) -> 32 | D9: 4
B10: =B9+1 -> 3 | C10: =IF(ISBLANK(Case!E53), "", Case!E53) -> 8 | D10: 4
B11: =B10+1 -> 4 | C11: =IF(ISBLANK(Case!E54), "", Case!E54) -> 33 | D11: 4
B12: =B11+1 -> 5 | C12: =IF(ISBLANK(Case!E55), "", Case!E55) -> 35 | D12: 4
B13: =B12+1 -> 6 | C13: =IF(ISBLANK(Case!E56), "", Case!E56) -> 19 | D13: 4
B14: =B13+1 -> 7 | C14: =IF(ISBLANK(Case!E57), "", Case!E57) -> 30 | D14: 4
B15: =B14+1 -> 8 | C15: =IF(ISBLANK(Case!E58), "", Case!E58) -> 48 | D15: 4
B16: =B15+1 -> 9 | C16: =IF(ISBLANK(Case!E59), "", Case!E59) -> 18 | D16: 4
B17: =B16+1 -> 10 | C17: =IF(ISBLANK(Case!E60), "", Case!E60) -> 42 | D17: 4
B18: =B17+1 -> 11 | C18: =IF(ISBLANK(Case!E61), "", Case!E61) -> 22 | D18: 4
B19: =B18+1 -> 12 | C19: =IF(ISBLANK(Case!E62), "", Case!E62) -> 45 | D19: 4
B20: =B19+1 -> 13 | C20: =IF(ISBLANK(Case!E63), "", Case!E63) -> 39 | D20: 4
... B27: =B26+1 -> 20 | C27: =IF(ISBLANK(Case!E70), "", Case!E70) -> 30 | D27: 4
B28: =B27+1 -> 21 | C28: =IF(ISBLANK(Case!E90), "", Case!E90) -> 1050 | D28: 6
B29: =B28+1 -> 22 | C29: =IF(ISBLANK(Case!E91), "", Case!E91) -> 2580 | D29: 6
B30: =B29+1 -> 23 | C30: =IF(ISBLANK(Case!E92), "", Case!E92) -> 790 | D30: 6
B31: =B30+1 -> 24 | C31: =IF(ISBLANK(Case!E93), "", Case!E93) -> 3475 | D31: 6
B32: =B31+1 -> 25 | C32: =IF(ISBLANK(Case!E94), "", Case!E94) -> 790 | D32: 6
B33: =B32+1 -> 26 | C33: =IF(ISBLANK(Case!E95), "", Case!E95) -> 1310 | D33: 6
B34: =B33+1 -> 27 | C34: =IF(ISBLANK(Case!E96), "", Case!E96) -> 5970 | D34: 6
B35: =B34+1 -> 28 | C35: =IF(ISBLANK(Case!E97), "", Case!E97) -> 285 | D35: 6
B36: =B35+1 -> 29 | C36: =IF(ISBLANK(Case!E98), "", Case!E98) -> 1730 | D36: 6
B37: =B36+1 -> 30 | C37: =IF(ISBLANK(Case!E99), "", Case!E99) -> 1850 | D37: 6
B38: =B37+1 -> 31 | C38: =IF(ISBLANK(Case!E100), "", Case!E100) -> 4680 | D38: 6
B39: =B38+1 -> 32 | C39: =IF(ISBLANK(Case!E101), "", Case!E101) -> 225 | D39: 6
... B47: =B46+1 -> 40 | C47: =IF(ISBLANK(Case!E109), "", Case!E109) -> 1400 | D47: 6
B48: =B47+1 -> 41 | C48: =IF(ISBLANK(Case!E129), "", Case!E129) -> 78 | D48: 7
B49: =B48+1 -> 42 | C49: =IF(ISBLANK(Case!E130), "", Case!E130) -> 80 | D49: 7
B50: =B49+1 -> 43 | C50: =IF(ISBLANK(Case!E131), "", Case!E131) -> 77 | D50: 7
B51: =B50+1 -> 44 | C51: =IF(ISBLANK(Case!E132), "", Case!E132) -> 65 | D51: 7
B52: =B51+1 -> 45 | C52: =IF(ISBLANK(Case!E133), "", Case!E133) -> 69 | D52: 7
B53: =B52+1 -> 46 | C53: =IF(ISBLANK(Case!E134), "", Case!E134) -> 61 | D53: 7
...
