Workbook
Name endTime: [1]BackgroundCalcs!$G$2
Name pCountNew: [1]BackgroundCalcs!$S$2
Name SpreadsheetName: [1]BackgroundCalcs!$D$5
Name startTime: [1]BackgroundCalcs!$F$2
Name stop15: '[1]Last Tab'!$L$15
Name stop16: '[1]Last Tab'!$AE$20
Name stop17: '[1]Last Tab'!$W$31
Name stop21: '[1]Last Tab'!$AM$129
Name stop22: '[1]Last Tab'!$AS$129
Name stop24: '[1]Last Tab'!$BA$57
Name stop25: '[1]Last Tab'!$BR$22
Name stop26: '[1]Last Tab'!$BV$92
Name stop27: '[1]Last Tab'!$BY$6
Name StudentIDCell: [1]BackgroundCalcs!$D$8
Name StudentNameCell: [1]BackgroundCalcs!$D$11
Name totalTime: [1]BackgroundCalcs!$F$29

Sheet Cover
O2: Case Author
B9: Visual Challenge - Varsity Edition | O9: Jack Franken
B11: Case Information | N11: MECC Jobs
B12: This case originally appeared as a part of the MECC Regionals in April 2025. The objective of this case is to model and analyze duck movement across a scene to measure the impact of hunting activity. | N12: MECC sponsors such as Siemens, New York Life, Alvarez & Marsal, and BDO have all hired MECC participants. Will you be next?
B14: About ASUS | N14: Earn MECC Badges
B15: ASUS is a global tech leader known for pushing boundaries with innovative devices, powerful performance, and world-class engineering. The Republic of Gamers (ROG) sub-brand makes the best hardware for PC gaming, eSports, and overclocking, delivering top performance and premium experience. | N15: Completing MECC challenges can earn you a certificate to add to your résumé, showcasing your Excel knowledge. Learn more about the certificates available to earn this season.
G17: #VALUE!
XX1000: 125713

Sheet Case
B2: Microsoft Excel Collegiate Challenge
B4: Duck Hunt - Varsity Edition | M4: Case Author
M5: Jack Franken
M7: Case Design Team
M8: David Brown
M9: Eric Kelley
M10: Leo Fernandez
M11: Nora Junaid
B14: Instructions
B15: You are an ornithologist, studying the impact of duck hunting season on the duck population.
B16: You will track ducks as they fly across the 'Scene', determining how successful the duck hunters are during duck season.
B17: All ducks begin outside of the scene, and fly in either from the left or right, flying horizontally in the same row that the duck began.
B20: Bonus Questions
B22: Bonus questions 1 and 3 can be completed independent of the Levels. Bonus 2 is aided by solving Level 3 first. Bonus 4 is aided by solving Level 6 first. Bonus 5 is aided by solving all of the Levels first.
B24: Game # | C24: Relates to Level # | D24: Points | E24: Answer | G24: Bonus Questions
B25: Bonus 1 | C25: N/A | D25: 30 | E25: =COUNTIF(Scene!B2:U27,0) -> 40 | G25: How many cloud cells are in the scene? See the legend on the Scene tab.
B26: Bonus 2 | C26: 3 | D26: 40 | E26: =COUNTIF(G134:G153,"A*") -> 11 | G26: In Level 3, excluding the example, how many ducks are flying from left-to-right? | R26: {=_xlfn.VSTACK(I177:I196,H219:H238,H264:H283,H308:H327,J308:J327)} -> C23 | T26: {=_xlfn.GROUPBY(_xlfn.ANCHORARRAY(R26),_xlfn.ANCHORARRAY(R26),_xleta.COUNTA,0,0,-2)} -> K17 | U26: 4
B27: Bonus 3 | C27: N/A | D27: 50 | E27: K17 | G27: Across all levels, which cell does the hunter aim at most often? Include both targets in each game within Level 7. Exclude all examples. | R27: N19 | T27: B2 | U27: 3
B28: Bonus 4 | C28: 6 | D28: 60 | E28: 21 | G28: Across all of Level 6, excluding the example, how many ducks are hiding behind the trees when the hunter takes the shot? Include both the green tree and brown trunk cells. | R28: B2 | T28: C21 | U28: 2
B29: Bonus 5 | C29: All Levels | D29: 70 | E29: 0 | G29: How many times across all levels, excluding examples, does the hunter successfully shoot the duck? | R29: U22 | T29: K25 | U29: 2
R30: L20 | T30: L20 | U30: 2
B31: Levels | R31: U19 | T31: M13 | U31: 2
R32: P7 | T32: R21 | U32: 2
B33: Level 1 | C33: Easy | D33: Duck Hunt | R33: P22 | T33: U13 | U33: 2
R34: M9 | T34: U15 | U34: 2
B35: The duck moves 1 cell each second moving from left to right (from column A to column V). | R35: S10 | T35: B10 | U35: 1
B36: What cell will the duck be in, given the starting cell and the number of seconds the duck has flown? | R36: O24 | T36: B14 | U36: 1
L37: 70 | R37: B14 | T37: B17 | U37: 1
B38: Example1: The duck begins in cell A13. | L38: =SUM(D25:D29,D52:D71,D92:D111,D134:D153,D177:D196,D219:D238,D264:D283,D308:D327) -> 1250 | N38: =L38*0.97 -> 1212.5 | R38: K17 | T38: B5 | U38: 1
B39: The duck enters the scene, traveling to the right. | N39: =L38-N38 -> 37.5 | R39: S15 | T39: C12 | U39: 1
B40: The duck travels 6 cells (across 6 columns) in 6 seconds. | R40: J9 | T40: C23 | U40: 1
B41: The duck is at cell G13 (Column A + 6 Columns) after 6 seconds. | R41: I4 | T41: C25 | U41: 1
R42: Q11 | T42: D10 | U42: 1
B43: Answer Hints: | R43: H8 | T43: D12 | U43: 1
B44: Game 1's answer is within the range J7:L11. | R44: O23 | T44: D21 | U44: 1
B45: Game 2's answer is within the range R24:V27. | R45: S12 | T45: D24 | U45: 1
B46: Game 3's answer is within the range B3:E9. | R46: L20 | T46: D7 | U46: 1
R47: B2 | T47: E14 | U47: 1
B48: Game | C48: Level | D48: Points | E48: Answer | G48: Starting Cell | H48: Seconds | R48: B17 | T48: E2 | U48: 1
R49: R25 | T49: E7 | U49: 1
...

Sheet Scene
A2: → | B2: 1 | C2: 1 | D2: 1 | E2: 1 | F2: 1 | G2: 1 | H2: 1 | I2: 1 | J2: 1 | K2: 1 | L2: 1 | M2: 1 | N2: 1 | O2: 1 | P2: 1 | Q2: 1 | R2: 1 | S2: 1 | T2: 1 | U2: 1 | V2: ← | W2: Cloud | X2: 0
A3: → | B3: 1 | C3: 1 | D3: 0 | E3: 1 | F3: 1 | G3: 1 | H3: 1 | I3: 1 | J3: 1 | K3: 1 | L3: 1 | M3: 1 | N3: 1 | O3: 1 | P3: 1 | Q3: 1 | R3: 1 | S3: 1 | T3: 1 | U3: 1 | V3: ← | W3: Sky | X3: 1
A4: → | B4: 1 | C4: 0 | D4: 0 | E4: 1 | F4: 1 | G4: 1 | H4: 0 | I4: 1 | J4: 1 | K4: 1 | L4: 1 | M4: 1 | N4: 1 | O4: 1 | P4: 1 | Q4: 1 | R4: 1 | S4: 0 | T4: 0 | U4: 1 | V4: ← | W4: Tree | X4: 2
A5: → | B5: 1 | C5: 0 | D5: 0 | E5: 1 | F5: 1 | G5: 1 | H5: 0 | I5: 0 | J5: 1 | K5: 1 | L5: 1 | M5: 1 | N5: 1 | O5: 1 | P5: 1 | Q5: 1 | R5: 1 | S5: 0 | T5: 0 | U5: 1 | V5: ← | W5: Trunk | X5: 3
A6: → | B6: 1 | C6: 1 | D6: 1 | E6: 1 | F6: 1 | G6: 1 | H6: 0 | I6: 0 | J6: 1 | K6: 1 | L6: 1 | M6: 1 | N6: 1 | O6: 1 | P6: 1 | Q6: 1 | R6: 1 | S6: 0 | T6: 0 | U6: 1 | V6: ← | W6: Grass | X6: 4
A7: → | B7: 1 | C7: 1 | D7: 1 | E7: 1 | F7: 1 | G7: 1 | H7: 1 | I7: 1 | J7: 1 | K7: 1 | L7: 1 | M7: 1 | N7: 1 | O7: 1 | P7: 1 | Q7: 1 | R7: 1 | S7: 0 | T7: 1 | U7: 1 | V7: ←
A8: → | B8: 1 | C8: 1 | D8: 1 | E8: 1 | F8: 1 | G8: 1 | H8: 1 | I8: 1 | J8: 1 | K8: 1 | L8: 1 | M8: 1 | N8: 1 | O8: 1 | P8: 1 | Q8: 1 | R8: 1 | S8: 1 | T8: 1 | U8: 1 | V8: ←
A9: → | B9: 1 | C9: 1 | D9: 1 | E9: 1 | F9: 1 | G9: 1 | H9: 1 | I9: 1 | J9: 1 | K9: 1 | L9: 1 | M9: 1 | N9: 1 | O9: 1 | P9: 1 | Q9: 1 | R9: 1 | S9: 1 | T9: 1 | U9: 1 | V9: ←
A10: → | B10: 1 | C10: 1 | D10: 1 | E10: 1 | F10: 1 | G10: 1 | H10: 1 | I10: 1 | J10: 0 | K10: 1 | L10: 1 | M10: 1 | N10: 1 | O10: 0 | P10: 1 | Q10: 1 | R10: 1 | S10: 1 | T10: 1 | U10: 1 | V10: ←
A11: → | B11: 1 | C11: 1 | D11: 1 | E11: 1 | F11: 1 | G11: 1 | H11: 1 | I11: 1 | J11: 0 | K11: 1 | L11: 1 | M11: 1 | N11: 0 | O11: 0 | P11: 0 | Q11: 1 | R11: 1 | S11: 1 | T11: 1 | U11: 1 | V11: ←
A12: → | B12: 1 | C12: 1 | D12: 1 | E12: 1 | F12: 1 | G12: 0 | H12: 1 | I12: 1 | J12: 1 | K12: 1 | L12: 1 | M12: 1 | N12: 0 | O12: 0 | P12: 0 | Q12: 1 | R12: 1 | S12: 1 | T12: 1 | U12: 1 | V12: ←
A13: → | B13: 1 | C13: 1 | D13: 1 | E13: 1 | F13: 1 | G13: 0 | H13: 1 | I13: 1 | J13: 1 | K13: 1 | L13: 1 | M13: 1 | N13: 1 | O13: 1 | P13: 1 | Q13: 1 | R13: 1 | S13: 1 | T13: 1 | U13: 1 | V13: ←
A14: → | B14: 1 | C14: 1 | D14: 1 | E14: 1 | F14: 1 | G14: 1 | H14: 1 | I14: 1 | J14: 1 | K14: 1 | L14: 1 | M14: 1 | N14: 1 | O14: 1 | P14: 1 | Q14: 1 | R14: 1 | S14: 1 | T14: 1 | U14: 1 | V14: ←
A15: → | B15: 1 | C15: 1 | D15: 1 | E15: 1 | G15: 1 | H15: 1 | I15: 1 | J15: 1 | K15: 1 | L15: 1 | M15: 1 | N15: 1 | O15: 1 | P15: 1 | Q15: 1 | R15: 1 | S15: 1 | T15: 1 | U15: 1 | V15: ←
A16: → | B16: 1 | C16: 1 | D16: 0 | E16: 1 | G16: 1 | H16: 1 | I16: 0 | J16: 1 | K16: 1 | L16: 1 | M16: 1 | N16: 1 | O16: 1 | P16: 1 | Q16: 1 | R16: 1 | S16: 1 | T16: 1 | U16: 1 | V16: ←
A17: → | B17: 1 | C17: 1 | D17: 0 | E17: 0 | G17: 1 | H17: 1 | I17: 0 | J17: 1 | K17: 1 | L17: 1 | M17: 1 | N17: 1 | O17: 1 | P17: 1 | Q17: 1 | R17: 1 | S17: 1 | T17: 0 | U17: 1 | V17: ←
A18: → | B18: 1 | C18: 1 | D18: 0 | E18: 0 | F18: 1 | G18: 1 | H18: 1 | I18: 1 | J18: 1 | K18: 1 | L18: 1 | M18: 1 | N18: 1 | O18: 1 | P18: 1 | Q18: 1 | R18: 1 | S18: 0 | T18: 0 | U18: 1 | V18: ←
A19: → | B19: 1 | C19: 1 | D19: 1 | E19: 1 | F19: 1 | G19: 1 | H19: 1 | I19: 1 | J19: 1 | K19: 1 | L19: 1 | M19: 1 | N19: 1 | O19: 1 | P19: 1 | Q19: 1 | R19: 1 | S19: 0 | T19: 0 | U19: 1 | V19: ←
A20: → | B20: 1 | C20: 1 | D20: 1 | E20: 2 | F20: 1 | G20: 1 | H20: 1 | I20: 1 | J20: 1 | K20: 1 | L20: 1 | M20: 1 | N20: 1 | O20: 1 | P20: 2 | Q20: 1 | R20: 1 | S20: 1 | T20: 1 | U20: 1 | V20: ←
A21: → | B21: 1 | C21: 1 | D21: 2 | E21: 2 | F21: 2 | G21: 1 | H21: 1 | I21: 1 | J21: 1 | K21: 1 | L21: 1 | M21: 1 | N21: 1 | O21: 2 | P21: 2 | Q21: 2 | R21: 1 | S21: 1 | T21: 1 | U21: 1 | V21: ←
A22: → | B22: 1 | C22: 1 | D22: 2 | E22: 2 | F22: 2 | G22: 1 | H22: 1 | I22: 1 | J22: 1 | K22: 1 | L22: 1 | M22: 1 | N22: 1 | O22: 2 | P22: 2 | Q22: 2 | R22: 1 | S22: 1 | T22: 1 | U22: 1 | V22: ←
A23: → | B23: 1 | C23: 2 | D23: 2 | E23: 2 | F23: 2 | G23: 2 | H23: 1 | I23: 1 | J23: 1 | K23: 1 | L23: 1 | M23: 1 | N23: 2 | O23: 2 | P23: 2 | Q23: 2 | R23: 2 | S23: 1 | T23: 1 | U23: 1 | V23: ←
A24: → | B24: 1 | C24: 2 | D24: 2 | E24: 2 | F24: 2 | G24: 2 | H24: 1 | I24: 1 | J24: 1 | K24: 1 | L24: 1 | M24: 1 | N24: 2 | O24: 2 | P24: 2 | Q24: 2 | R24: 2 | S24: 1 | T24: 1 | U24: 1 | V24: ←
A25: → | B25: 1 | C25: 1 | D25: 1 | E25: 3 | F25: 1 | G25: 1 | H25: 1 | I25: 1 | J25: 1 | K25: 1 | L25: 1 | M25: 1 | N25: 1 | O25: 1 | P25: 3 | Q25: 1 | R25: 1 | S25: 1 | T25: 1 | U25: 1 | V25: ←
A26: → | B26: 1 | C26: 1 | D26: 1 | E26: 3 | F26: 1 | G26: 1 | H26: 1 | I26: 1 | J26: 1 | K26: 1 | L26: 1 | M26: 1 | N26: 1 | O26: 1 | P26: 3 | Q26: 1 | R26: 1 | S26: 1 | T26: 1 | U26: 1 | V26: ←
B27: 4 | C27: 4 | D27: 4 | E27: 4 | F27: 4 | G27: 4 | H27: 4 | I27: 4 | J27: 4 | K27: 4 | L27: 4 | M27: 4 | N27: 4 | O27: 4 | P27: 4 | Q27: 4 | R27: 4 | S27: 4 | T27: 4 | U27: 4
E29: {=CELL("adres",E20)} -> $E$20 | P29: {=CELL("adres",P20)} -> $P$20
D30: {=CELL("adres",D21)} -> $D$21 | E30: {=CELL("adres",E21)} -> $E$21 | F30: {=CELL("adres",F21)} -> $F$21 | O30: {=CELL("adres",O21)} -> $O$21 | P30: {=CELL("adres",P21)} -> $P$21 | Q30: {=CELL("adres",Q21)} -> $Q$21
D31: {=CELL("adres",D22)} -> $D$22 | E31: {=CELL("adres",E22)} -> $E$22 | F31: {=CELL("adres",F22)} -> $F$22 | O31: {=CELL("adres",O22)} -> $O$22 | P31: {=CELL("adres",P22)} -> $P$22 | Q31: {=CELL("adres",Q22)} -> $Q$22
C32: {=CELL("adres",C22)} -> $C$22 | D32: {=CELL("adres",D23)} -> $D$23 | E32: {=CELL("adres",E23)} -> $E$23 | F32: {=CELL("adres",F23)} -> $F$23 | G32: {=CELL("adres",G23)} -> $G$23 | N32: {=CELL("adres",N22)} -> $N$22 | O32: {=CELL("adres",O23)} -> $O$23 | P32: {=CELL("adres",P23)} -> $P$23 | Q32: {=CELL("adres",Q23)} -> $Q$23 | R32: {=CELL("adres",R23)} -> $R$23
C33: {=CELL("adres",C23)} -> $C$23 | D33: {=CELL("adres",D24)} -> $D$24 | E33: {=CELL("adres",E24)} -> $E$24 | F33: {=CELL("adres",F24)} -> $F$24 | G33: {=CELL("adres",G24)} -> $G$24 | N33: {=CELL("adres",N23)} -> $N$23 | O33: {=CELL("adres",O24)} -> $O$24 | P33: {=CELL("adres",P24)} -> $P$24 | Q33: {=CELL("adres",Q24)} -> $Q$24 | R33: {=CELL("adres",R24)} -> $R$24
E34: {=CELL("adres",E25)} -> $E$25 | P34: {=CELL("adres",P25)} -> $P$25
E35: {=CELL("adres",E26)} -> $E$26 | P35: {=CELL("adres",P26)} -> $P$26
C40: {=SUBSTITUTE(_xlfn.TOCOL(C29:R36,1), "$", "")} -> E20
C41: P20
C42: D21
C43: E21
C44: F21
C45: O21
C46: P21
...

Sheet Graded Answers
B1: Your Answers
B2: Game # | C2: Answer | D2: Points
B3: Bonus 1 | C3: =IF(ISBLANK(Case!E25),"",Case!E25) -> 40 | D3: 30
B4: Bonus 2 | C4: =IF(ISBLANK(Case!E26),"",Case!E26) -> 11 | D4: 40
B5: Bonus 3 | C5: =IF(ISBLANK(Case!E27),"",Case!E27) -> K17 | D5: 50
B6: Bonus 4 | C6: =IF(ISBLANK(Case!E28),"",Case!E28) -> 21 | D6: 60
B7: Bonus 5 | C7: =IF(ISBLANK(Case!E29),"",Case!E29) -> 0 | D7: 70
B8: 1 | C8: =IF(ISBLANK(Case!E52),"",Case!E52) -> K10 | D8: 4
B9: =B8+1 -> 2 | C9: =IF(ISBLANK(Case!E53),"",Case!E53) -> S25 | D9: 4
B10: =B9+1 -> 3 | C10: =IF(ISBLANK(Case!E54),"",Case!E54) -> E4 | D10: 4
B11: =B10+1 -> 4 | C11: =IF(ISBLANK(Case!E55),"",Case!E55) -> C19 | D11: 4
B12: =B11+1 -> 5 | C12: =IF(ISBLANK(Case!E56),"",Case!E56) -> P26 | D12: 4
B13: =B12+1 -> 6 | C13: =IF(ISBLANK(Case!E57),"",Case!E57) -> C3 | D13: 4
B14: =B13+1 -> 7 | C14: =IF(ISBLANK(Case!E58),"",Case!E58) -> Q17 | D14: 4
B15: =B14+1 -> 8 | C15: =IF(ISBLANK(Case!E59),"",Case!E59) -> C4 | D15: 4
B16: =B15+1 -> 9 | C16: =IF(ISBLANK(Case!E60),"",Case!E60) -> L3 | D16: 4
B17: =B16+1 -> 10 | C17: =IF(ISBLANK(Case!E61),"",Case!E61) -> O16 | D17: 4
B18: =B17+1 -> 11 | C18: =IF(ISBLANK(Case!E62),"",Case!E62) -> D7 | D18: 4
B19: =B18+1 -> 12 | C19: =IF(ISBLANK(Case!E63),"",Case!E63) -> I21 | D19: 4
B20: =B19+1 -> 13 | C20: =IF(ISBLANK(Case!E64),"",Case!E64) -> D8 | D20: 4
... B27: =B26+1 -> 20 | C27: =IF(ISBLANK(Case!E71),"",Case!E71) -> N13 | D27: 4
B28: =B27+1 -> 21 | C28: =IF(ISBLANK(Case!E92),"",Case!E92) -> D12 | D28: 4
B29: =B28+1 -> 22 | C29: =IF(ISBLANK(Case!E93),"",Case!E93) -> G16 | D29: 4
B30: =B29+1 -> 23 | C30: =IF(ISBLANK(Case!E94),"",Case!E94) -> O21 | D30: 4
B31: =B30+1 -> 24 | C31: =IF(ISBLANK(Case!E95),"",Case!E95) -> L6 | D31: 4
B32: =B31+1 -> 25 | C32: =IF(ISBLANK(Case!E96),"",Case!E96) -> Q26 | D32: 4
B33: =B32+1 -> 26 | C33: =IF(ISBLANK(Case!E97),"",Case!E97) -> F25 | D33: 4
B34: =B33+1 -> 27 | C34: =IF(ISBLANK(Case!E98),"",Case!E98) -> M26 | D34: 4
B35: =B34+1 -> 28 | C35: =IF(ISBLANK(Case!E99),"",Case!E99) -> F25 | D35: 4
B36: =B35+1 -> 29 | C36: =IF(ISBLANK(Case!E100),"",Case!E100) -> B17 | D36: 4
B37: =B36+1 -> 30 | C37: =IF(ISBLANK(Case!E101),"",Case!E101) -> D8 | D37: 4
B38: =B37+1 -> 31 | C38: =IF(ISBLANK(Case!E102),"",Case!E102) -> N9 | D38: 4
B39: =B38+1 -> 32 | C39: =IF(ISBLANK(Case!E103),"",Case!E103) -> R8 | D39: 4
... B47: =B46+1 -> 40 | C47: =IF(ISBLANK(Case!E111),"",Case!E111) -> S17 | D47: 4
B48: =B47+1 -> 41 | C48: =IF(ISBLANK(Case!E134),"",Case!E134) -> G17 | D48: 5
B49: =B48+1 -> 42 | C49: =IF(ISBLANK(Case!E135),"",Case!E135) -> S6 | D49: 5
B50: =B49+1 -> 43 | C50: =IF(ISBLANK(Case!E136),"",Case!E136) -> J5 | D50: 5
B51: =B50+1 -> 44 | C51: =IF(ISBLANK(Case!E137),"",Case!E137) -> E11 | D51: 5
B52: =B51+1 -> 45 | C52: =IF(ISBLANK(Case!E138),"",Case!E138) -> F26 | D52: 5
B53: =B52+1 -> 46 | C53: =IF(ISBLANK(Case!E139),"",Case!E139) -> H26 | D53: 5
...
