Workbook

Sheet Cover
O2: Case Author
B9: Excelgram - Junior Varsity Edition | O9: Tsiory Razafitseheno
B11: Case Information | N11: MECC Jobs
B12: This case originally appeared as a part of the MECC Regionals in April 2025. The case unfolds on Excelgram, a social network inspired by real-world platforms, where users follow one another and influence opinions. Starting with 850 subscribers, each user has a unique ID, personal details, and a list of followings—revealing who connects with whom and who emerges as an influencer. The case uses the same scoring as the original competition version, but answers are included so you can check your work. | N12: MECC sponsors such as Siemens, New York Life, Alvarez & Marsal, and BDO have all hired MECC participants. Will you be next?
B14: About ASUS | N14: Earn MECC Badges
B15: ASUS is a global tech leader known for pushing boundaries with innovative devices, powerful performance, and world-class engineering. The Republic of Gamers (ROG) sub-brand makes the best hardware for PC gaming, eSports, and overclocking, delivering top performance and premium experience. | N15: Completing MECC challenges can earn you a certificate to add to your résumé, showcasing your Excel knowledge. Learn more about the certificates available to earn this season.
G17: #VALUE!
XX1000: 125713

Sheet Case
B2: Microsoft Excel Collegiate Challenge
B4: Excelgram - Junior Varsity Edition | L4: Original Case Author
L5: Tsiory Razafitseheno
L7: Case Design Team
L8: David Brown
L9: Eric Kelley
L10: Nora Junaid
L11: Leo Fernandez
B14: Instructions
B15: You are studying how people influence each other and have decided to create a social network called Excelgram. This platform functions similarly to an existing social network that rhymes with its name.
B16: On Excelgram, you can follow people and people can also follow you. Here are some helpful definitions:
B18: A Follower: a person that follows you (not used in the Junior Varsity case)
B19: A Following: a person that you are following
B20: An influencer (Lv4+): a person that has many followers, hence the person can affect public opinion (not used in the Junior Varsity case)
B22: The platform had an humble launch of 850 subscribers. In the Users tab, you are given the ID of each user, their name, their date of birth, their principal interest and a list of their followings.
B23: The ID is composed by one letter, which determine the sex of the user ("M" for male and "F" for female), followed by 4 digits that is unique for every user.
B24: The "followings" list is an exhaustive list of every user's following and is separated by a slash "/"
B27: Bonus Questions
B29: To make the game more exciting, we have created 5 bonus questions for you. These questions can be answered at any time during the game.
B31: Game # | C31: Relates to Level # | D31: Points | E31: Answer | G31: Bonus Questions
B32: Bonus 1 | C32: N/A | D32: 40 | E32: =COUNTIF(tblUsers[Gender],"F") -> 424 | G32: How many users have an "F" at the start of their ID?
B33: Bonus 2 | C33: N/A | D33: 40 | E33: 785825 | G33: What is the sum of the numeric portion of all the IDs?
B34: Bonus 3 | C34: N/A | D34: 50 | E34: =COUNTIF(tblUsers[Date of birth weekday],5) -> 122 | G34: How many users were born on a Friday?
B35: Bonus 4 | C35: N/A | D35: 50 | E35: =_xlfn.XLOOKUP(MIN(tblUsers[Date of birth]),tblUsers[Date of birth],tblUsers[Name],,0,1) -> Atif Al-Zahrani | G35: Who is the oldest user?
B36: Bonus 5 | C36: N/A | D36: 70 | E36: 1996 | G36: What is the most common birth year among the users?
B38: Levels
B40: Level 1 | C40: Very Easy
B42: What is the name of the person in the given row on the User Data tab?
B43: Note that the row numbers always refer to the row of the cells, not the row of the data records.
B44: For example, row 1 of User Data is blank, row 2 contains headers, and row 3 is the first row with data.
B46: Example1: Row 13 in User Data has ID M-0510 which is associated with Brady Brock.
B48: Answer Hints:
B49: Game 1's answer starts with A or H.
B50: Game 2's answer starts with D or A.
B51: Game 3's answer starts with D or B.
B53: Game # | C53: Level | D53: Points | E53: Answer | G53: Row
B55: Example1 | C55: 1 | D55: 0 | E55: Brady Brock | G55: 13
B57: 1 | C57: 1 | D57: 2 | E57: {=INDEX('User Data'!C:C,Case!G57:G76)} -> Hai Ferguson | G57: 21
B58: 2 | C58: 1 | D58: 2 | E58: Arnulfo Lara | G58: 22
B59: 3 | C59: 1 | D59: 2 | E59: Bob Garza | G59: 23
...

Sheet User Data
B2: ID | C2: Name | D2: Date of birth | E2: Followings | F2: Main interest | G2: Gender | H2: Code | I2: Date of birth weekday | J2: Date of birth weekday 2
B3: F-0500 | C3: Anita Cardenas | D3: 35159 | E3: F-1198/F-0672/F-1169/F-1316/F-1204/F-0786/F-0592/M-0738/F-1045/M-0837/F-1126/F-1226/M-0678/M-1243/F-0545/M-0505/M-1025/M-0977/M-1036/M-0988/M-0961/F-1123/F-0950/M-1167/F-1016/F-1026/M-0833/M-0536/M-1223/M-0821/F-0957/M-1035/F-1143/F-0531/M-0540/M-1347/M-0960/M-0723/F-1151/F-1178/F-0748/M-1068/M-1292/M-0694/F-0839/M-1325/M-0548/M-0774/F-0763/F-0687/M-0567/M-1021/M-1262/M-0951/F-1081/M-0834/F-1196/M-0507/F-0953/F-1079/F-0757/F-0596/M-1170/M-1287/F-1202/F-0935/M-1078/F-0504/F-0954/F-1046/F-1333/M-0636/M-0610/F-1032/M-0949/M-0524/M-0895/M-0510/F-0512/M-1033/M-1031/M-0557/M-0868/F-1057/F-1086/F-0829/F-1263/M-0620/F-1210/F-0753/F-0688/F-0956/F-0638/F-0628/M-1345/F-1215/M-0993/M-0792/F-1278/M-1304/F-1213/M-1291/F-1324/F-1282/F-0714/M-1303/M-0995/F-0580/F-1138/M-1248/F-0537/F-1059/M-0878/M-0550/M-0970/F-0564/M-0802/F-1318/F-1061/F-0712/M-1194/M-1117/M-0920/F-1216/F-0657/M-1286/M-1111/F-1155/F-0544/F-1253/M-1005/M-1030/F-0663/F-1193/M-1201/F-0980/F-1028/F-0775/F-0651/M-0791/F-0739/M-0817/F-0764/F-0617/F-0517/F-0629/F-0934/F-0601/F-0842/F-0991/M-0919/F-1001/M-0740/F-1144/M-0649/M-0599/M-0758/M-0677/M-0528/F-0682/M-0646/M-0664/M-1158/F-1168/M-1276/M-0703/M-0607/M-1241/M-0560/M-1024/F-0668/M-1187/M-0680/M-0696/F-0538/M-0871/F-0719/F-1273/M-0997/M-0843/M-0755/M-0746/M-1139/F-0886/F-1315/M-1156/F-0846/M-1281/M-0967/F-0975/M-0928/F-1130/F-0561/M-1147/F-1066/F-0669/F-0830/M-1300/M-0860/M-0715/F-0889/F-0924/F-0578/M-0527/F-1336/F-0574/F-0705/F-1271/F-0804/M-0831/M-0816/F-1285/F-0955/M-1022/M-0777/M-0859/F-0720/M-0781/M-0926/F-0652/M-0611/M-0805/M-0716/F-1120/F-1274/F-0698/F-0726/F-0543/F-0864/M-0586/M-0818/M-0840/M-1184/M-0673/F-1106/F-0735/M-0778/M-0699/F-0952/M-0656/M-0602/F-0855/F-0799/F-0819/F-0884/M-0897/M-1339/F-1089/F-1063/M-0945/F-1227/F-1179/M-0582/F-1332/F-1023/F-1183/M-0826/F-1228/F-1250/M-1000/M-1056/F-0751/F-1313/F-1013/M-0862/F-0684/M-1182/M-0644/F-1119/F-1317/F-1010/M-0820/M-0744/F-0931/M-0947 | F3: Gaming | G3: =LEFT(tblUsers[[#This Row],[ID]]) -> F | H3: =RIGHT(tblUsers[[#This Row],[ID]],4) -> 0500 | I3: =WEEKDAY(tblUsers[[#This Row],[Date of birth]], 2) -> 4 | J3: =WEEKDAY(tblUsers[[#This Row],[Date of birth]]) -> 5 | K3: {=_xlfn.GROUPBY(YEAR(tblUsers[Date of birth]),tblUsers[Date of birth],_xleta.COUNTA,0,0,-2)} -> 1996 | L3: 65
B4: M-0501 | C4: Deanna Lucas | D4: 34185 | E4: F-0543/F-1123/M-1068/M-1293/F-0804/F-1198/M-1276/M-0843/F-0913/M-0567/M-0973/M-0536/F-1106/M-0837/F-1216/M-0961/M-1030 | F4: Writing | G4: =LEFT(tblUsers[[#This Row],[ID]]) -> M | H4: =RIGHT(tblUsers[[#This Row],[ID]],4) -> 0501 | I4: =WEEKDAY(tblUsers[[#This Row],[Date of birth]], 2) -> 3 | J4: =WEEKDAY(tblUsers[[#This Row],[Date of birth]]) -> 4 | K4: 1994 | L4: 60
B5: F-0502 | C5: Donny Forbes | D5: 33282 | E5: M-0505/F-0861/F-1119/F-0954/F-1123/F-1190/F-1212/M-0940/F-1071/M-0624/F-1002/M-0694/F-1046/F-0959/M-1347/F-1136/M-0824/M-0755/F-1215/M-0636/F-1120/F-0563/F-1324/F-1132/F-0672/M-1054/F-0953/F-0578/F-0804/F-0568/F-1336/F-1059/M-0877/M-0988/F-0596/F-1012/F-1257/F-1041/M-1287/F-0799/F-0775/M-1292/F-1079/F-1168/F-0592/F-0935/F-0545/M-0915/M-0910/F-0786/F-0812/F-0950/M-1243/F-1312/M-1319/F-0525/F-0687/M-0977/F-1297/M-0876/F-0838/F-0911/M-0986/F-0844/F-0574/F-1226/M-0806/F-1129/F-0531/M-0510/M-0925/M-0519/M-0996/F-0544/F-1169/F-1001/F-1188/M-1135/F-1273/M-1036/F-0882/M-0821/M-1005/M-0920/M-0566/F-0772/M-0899/F-0991/F-0583/M-0919/F-0504/M-0609/M-1184/F-1318/F-0538/M-0678/F-0846/F-1204/M-1102/F-0671/M-1223/F-0712/F-0685/M-0620/M-1302/M-0896/F-0726/F-1106/M-0646/M-0539/M-1091/F-1213/M-1030/M-0960/M-0841/M-1035/M-0859/F-0735/F-0957/F-0942/F-0836/F-0625/M-1111/F-0663/F-0629/M-0834/F-1143/F-0632/F-0543/M-1286/F-1305/M-0895/M-0716/M-1334/F-1026/M-0513/M-0792/F-1275/F-0580/F-0627/M-0992/F-0934/M-0851/M-1231/M-1084/M-0700/M-1139/M-1051/F-1032/F-1186/F-0651/F-1282/M-0779/F-1216/F-1013/M-0540/M-0979/M-1087/M-1307/F-1081/F-0797/M-1068/M-1187/F-1245/M-0560/M-1078/M-0771/M-0527/F-0698/F-1121/M-0630/F-0612/F-0714/M-1301/M-0818/M-0703/M-1241/F-1189/M-1109/F-1057/F-1146/F-1278/F-0939/M-0758/F-0512/M-0600/M-0550/F-0517/F-0864/F-1152/M-0843/F-1240/M-1025/M-1056/M-1031/M-0590/M-0809/F-1328/F-1155/F-1153/F-1075/F-0762/F-1317/M-1195/F-1049/F-1233/F-0551/F-0952/M-0586/M-1345/F-0884/F-0520/F-1263/F-0684/F-1285/F-0829/M-1082/F-0753/M-0868/M-0548/M-0768/M-1247/M-1291/M-1147/F-0828/F-0956/F-1234/M-0765/M-0964/M-1172/M-0691/F-0622/M-1268/M-0862/M-0606/F-1253/M-0745/M-0536/M-1329/F-1258/M-1262/F-0515/M-0507/M-0593/F-0984/M-0759/F-0748/M-1069/M-1181/F-1249/M-1339/M-1201/F-1126/F-0549/M-0831/M-0837/M-0871/M-0654/M-0594/F-0914/M-1311/M-0649/M-0523/M-1125/M-0944/M-1101/F-1028/M-0908/F-1061/F-0900/F-0717/F-1066/F-1225/M-0901/M-1021/F-1349/F-0832/M-0639/M-1033/M-0733/M-0802/M-0577/M-0926/F-0616/M-0961/F-0795/F-0845/F-1086/M-1276/M-1289/F-1045/F-1103/M-1182/M-1008/F-1178/M-0658/F-1272/F-1089/F-0810/F-0842/F-1138/M-0869/F-0676/F-1228/M-0599/M-1344/M-0607/F-0659/M-0650/M-1161/M-0892/M-0699/M-1325/F-1023/M-0509/M-0680/F-0974/F-0787/F-1210/M-0835/F-1171/F-0720/F-1259/F-0980/M-0752/F-1140/M-0582/M-1327/F-1333/M-0677 | F5: Hiking | G5: =LEFT(tblUsers[[#This Row],[ID]]) -> F | H5: =RIGHT(tblUsers[[#This Row],[ID]],4) -> 0502 | I5: =WEEKDAY(tblUsers[[#This Row],[Date of birth]], 2) -> 3 | J5: =WEEKDAY(tblUsers[[#This Row],[Date of birth]]) -> 4 | K5: 2006 | L5: 56
B6: F-0503 | C6: Sang Browning | D6: 37477 | E6: F-1168/F-1190/F-1045 | F6: Cooking | G6: =LEFT(tblUsers[[#This Row],[ID]]) -> F | H6: =RIGHT(tblUsers[[#This Row],[ID]],4) -> 0503 | I6: =WEEKDAY(tblUsers[[#This Row],[Date of birth]], 2) -> 5 | J6: =WEEKDAY(tblUsers[[#This Row],[Date of birth]]) -> 6 | K6: 1997 | L6: 55
B7: F-0504 | C7: Cortez Vang | D7: 38652 | E7: F-0672/M-1347/M-0837/F-1002/F-1198/F-1168/F-0688/F-1136/F-1151/F-0735/F-0627/F-1079/F-1098/M-0859/F-0531/M-1276/F-1190/M-0646/M-1014/M-0860/F-0512/M-0973/F-0563/F-0538/F-1171/F-0959/M-0678/F-0545/M-1201/F-1169/F-0583/M-0562/M-0982/M-1084/F-0957/M-1135/M-0694/M-0961/F-0763/M-0599/M-0593/F-1316/F-0846/F-0617/M-0831/F-1155/M-0833/M-0774/F-1041/M-0862/M-1248/M-0519/M-0609/F-0525/M-0877/M-1319/M-1031/F-1059/M-0733/M-0507/F-0954/M-0826/M-1187/F-0578/M-0986/M-0794/M-1303/M-0818/M-1087/F-0697/F-0911/M-1243/M-0949/F-1012/M-0824/M-0664/M-0594/F-0520/F-1060/F-1249/F-0668/F-1228/M-0906/F-1337/M-0899/M-0501/M-0600/M-1292/M-1287/F-1144/F-0898/F-1212/F-0953/F-0799/F-0685/F-1226/M-0758/F-0842/M-0576/M-0809/F-0622/F-1106/F-1324/F-0864/M-0658/M-1344/F-1280/M-0696/F-1055/M-1068/F-0861/M-0709/M-1241/M-1320/F-1257/F-1204/F-1119/F-0991/F-1196/M-1078/F-0588/F-1152/M-0892/F-0579/M-0703/M-0791/F-0714/F-1272/F-1215/F-1333/M-0995/F-1186/F-0931/F-0857/F-0632/F-0690/F-1028/M-0636/M-1095/F-0686/F-0950/M-0919/F-0808/F-0952/M-1307/F-0900/M-1051/F-0648/F-0893/M-0841/M-1077/F-1131/M-0550/M-1345/F-0975/M-0782/M-0527/F-1279/F-0937/M-0925/F-0748/F-0812/F-1165/M-0716/F-0934/M-0926/M-0553/M-0933/M-1182/M-0778/F-0537/M-0620/F-1222/M-0910/M-1269/F-1176/F-0819/M-0920/F-1112/F-1282/M-1072/M-0981/M-1205/F-0882/F-0619/M-0802/M-1102/F-0629/F-0980/M-0547/F-0828/F-0574/M-0724/F-0935/F-0955/F-1210/M-1235/F-1023/F-0984/F-1189/F-0561/F-1258/F-0751/F-1013/M-1255/F-0726/M-1304/F-0652/F-1178/F-1086/F-0530/F-0754/F-0625/M-0854/F-0836/F-0747/F-0760/F-1103/M-0792/M-0597/M-0590/F-1317/M-1231/M-0993/M-0988/M-0534/F-0904/M-0901/F-0558/F-0635/M-0557/F-1183/F-0787/M-1101/M-0556/M-0915/F-0974/M-0851/M-0699/F-0613/F-0990/M-0738/M-1054/M-0649/M-0834/M-0871/F-0638/F-0884/M-0560/F-1045/M-0677/M-0650/F-0628/M-1310/M-0843/M-1293/M-1037/F-1062/F-1146/F-0671/M-0602/M-0876/M-1164/F-1295/M-1194/M-0943/F-0948/M-1339/M-0821/F-0502/M-1030/F-1126/M-0805/F-1017/F-0942 | F7: Writing | G7: =LEFT(tblUsers[[#This Row],[ID]]) -> F | H7: =RIGHT(tblUsers[[#This Row],[ID]],4) -> 0504 | I7: =WEEKDAY(tblUsers[[#This Row],[Date of birth]], 2) -> 4 | J7: =WEEKDAY(tblUsers[[#This Row],[Date of birth]]) -> 5 | K7: 1999 | L7: 55
B8: M-0505 | C8: Bertha Swanson | D8: 36109 | E8: M-1276/F-0687/F-1151/F-0954/M-0694/M-0910/M-0636/M-0560/M-0961/M-1223/M-1167/F-0672/M-0507/M-1139/F-1079/M-0949/F-1132/F-0748/M-0821/F-0799/F-1152/F-0568/M-0919/F-0543/F-1324/M-0843/F-0836/F-1098/F-1171/F-0786/F-1138/F-0957/M-1084/M-1054/F-0622/M-0703/M-1111/M-1201/F-0861/M-0834/F-1210/F-0563/F-0772/M-0920/F-0934/F-1169/F-0937/F-0935/F-1129/M-0540/M-1248/F-1106/M-0806/F-1257/M-0896/F-1317/M-0658/F-1204/M-1181/F-1026/M-1195/M-0774/M-1068/M-0519/F-1273/F-0592/F-1155/M-1292/M-0967/F-0596/F-1318/F-1168/F-1012/M-0696/M-1072/F-1240/M-0940/F-0839/F-0659/M-1182/M-0513/M-0881/F-0632/M-0570/F-0714/M-0831/F-1066/M-1293/M-1339/F-0929/M-0778/M-1301/M-0837/F-1057/F-1042/M-1262/M-0993/M-0599/F-0764/F-1328/F-0627/F-0574/M-0851/F-1282/M-0630/F-0580/F-1045/M-0841/M-1107/M-0982/M-1038/F-0846/M-0536/M-0960/M-1344/F-0516/F-0638/M-0925/M-0995/F-1027/M-0802/F-1274/F-1143/F-0690/M-1031/M-1078/F-0517/F-0735/M-0758/M-0665/F-0520/F-1198/F-0829/M-0646/F-0807/F-1189/M-0878/M-0867/F-0545/M-0876/M-1077/M-0664/F-0974/F-0531/M-1243/F-1272/F-0648/M-1304/F-1136/F-1126/F-1179/M-0859/M-1184/F-0775/M-0888/F-0754/M-1036/F-0564/M-0973/M-0777/M-0871/F-0762/M-0809/F-0905/F-0956/M-1021/F-0760/M-0926/F-1316/M-1281/F-1183/M-0906/M-1024/F-0849/F-0913/M-0523/M-1303/M-1267/M-0593/F-1216/F-0598/F-0578/F-1297/M-0826/F-1196/M-0768/F-0697/M-0610/F-0882/M-0678/M-1235/M-0783/M-0877/F-1178/M-0715/F-1061/F-0797/M-0577/M-0608/M-0981/M-0723/F-1060/M-0600/M-0602/M-0755/M-0548/F-0975/F-1245/M-0986/F-1041/F-0712/M-0597/F-1086/M-1187/M-0559/F-0619/F-1226/M-0988/F-0660/F-0842/M-0779/F-0950/F-0684/F-0763/F-0898/M-1319/F-0952/M-0724/F-0537/F-1333/M-1231/M-1009/M-0781/M-0868/F-0825/M-1347/M-1208/M-0869/M-0556/F-0508/F-0990/M-0562/M-0649/F-0855/M-0928/M-0709/F-0685/M-0679/F-1123/F-0857/M-0970/F-0808/M-1135/F-1285/M-0850/F-0747/F-1121/F-1115/F-1016/F-1013/F-1212/F-0924/F-1070/M-1164/M-1218/M-1172/M-1005/M-0680/F-0726/M-0945/M-0524/M-0771/M-0699/M-0644/M-0656/F-0893/M-0587/F-0651/F-0773/M-0510/F-0515/F-1271/M-0738/F-1059/F-1071/F-0757/F-0544/F-1146/F-0689/F-1039/M-0824/M-0887/M-1291/M-1035/M-0527/M-0835/M-1069/F-0532/M-1287/M-0744/M-1264/F-0900/F-0939/M-0817/M-0815/F-1202/F-1313/M-0518/M-1014/M-1067/M-1323/M-0895/M-0941/M-0642/M-0557/F-1222/F-1002/M-1073/M-0992/F-1186/M-0776/F-0766/F-0569/F-1055/M-0814/F-1015/F-1144/M-1051/M-0933/F-1119/F-0617/F-0575/M-1022/M-1211/F-0686/F-0682/M-0624/F-1228/M-1185/M-0792/M-0865/F-0832/F-1165/M-1170/F-1018/M-0566/M-0603/M-0847/M-1064/M-0996/F-1065/M-0899/F-1215/M-1080/M-1148/F-1278/F-0530/F-0984/F-1232/F-1028/F-0980/M-1255/M-1205/F-0750/M-1166/F-0717/F-0955/F-0702/F-0629/M-0731/F-0579/F-1160/F-0875/F-0671/M-0594/F-1234/M-0994/M-0609/F-0633/F-0828/F-1120/F-0512/M-0640/M-0840/F-1214/F-0953/M-1307/M-0765/F-1046/M-0654/M-0944/F-0692/F-1337/F-0710/F-0737/M-0848/F-1336/M-0533/F-0883/M-1101/M-1099/M-0550/M-0677/F-0628/F-1092/M-0782/F-1340/M-1000/M-1269/F-1023/M-0909/F-0538/F-0914/M-0943/F-0844/M-0567/M-0901/M-0977/F-0635/F-1076/M-1268/F-1254/F-1263/F-0922/F-0525/F-0804/F-0819/M-1029/F-0753/F-1081/F-0812/M-0854/F-1108/F-1244/M-1207/F-1075/F-0698/M-1094/F-1294/F-1275/F-0948/M-0528/M-0866/F-0904/M-1163/F-1238/F-0787/M-1302/M-0860/M-1241/M-0833/M-1289/M-1286/F-1097/F-0625/F-1190/M-0526/F-0637/M-0607/F-0959/F-1346/F-1175/M-0573/F-0713/M-1219/M-0621/M-1320/F-1032/F-0535/M-1192/F-0647/F-1250/M-0620/F-0991/F-0810/F-0502/M-0675/M-0606/M-1147/M-0951/M-1096/F-1305/M-1109/M-1033/F-1048/M-0631/F-0688/M-0979/M-0915/F-0942/F-1312/F-0583/M-1025/F-0785/M-0582/F-0911/M-0706/F-1225/F-0549/F-1010/F-0666/F-1256/F-0801/M-1173/M-1161/F-0728/F-1052/F-0830/F-0751/M-0534/F-1188/F-0725/F-0614/F-1348/M-1224/F-0927/F-0917/F-1089/M-1044/M-1247/M-0590/M-0892/F-0864/M-0780/M-1095/F-0838/M-0862/F-1140/F-1253/F-0798 | F8: Reading | G8: =LEFT(tblUsers[[#This Row],[ID]]) -> M | H8: =RIGHT(tblUsers[[#This Row],[ID]],4) -> 0505 | I8: =WEEKDAY(tblUsers[[#This Row],[Date of birth]], 2) -> 2 | J8: =WEEKDAY(tblUsers[[#This Row],[Date of birth]]) -> 3 | K8: 2002 | L8: 55
B9: M-0506 | C9: Werner Fernandez | D9: 36953 | E9: F-0828/F-0954/M-0837/M-0505/F-0638/F-1120/F-0953/M-1111/F-0531/M-1078/M-0818/F-0747/M-1107/F-1226/F-1046/F-0632/M-0824/F-1032/M-1031/F-0735/F-1216/M-0841/M-0680/M-1135/F-0578/M-0519/M-1187/M-0977/F-0799/M-0925/F-1002/M-1231/F-1178/M-0967/M-0877/F-1106/M-1167/F-1004 | F9: Swimming | G9: =LEFT(tblUsers[[#This Row],[ID]]) -> M | H9: =RIGHT(tblUsers[[#This Row],[ID]],4) -> 0506 | I9: =WEEKDAY(tblUsers[[#This Row],[Date of birth]], 2) -> 6 | J9: =WEEKDAY(tblUsers[[#This Row],[Date of birth]]) -> 7 | K9: 2000 | L9: 54
B10: M-0507 | C10: Sherri Frost | D10: 37551 | E10: M-0821/M-0636/F-0622/F-0935/F-1212/M-1223/F-1169/F-0632/M-1293/F-0512/F-1285/F-0954/F-0775/F-0934/F-1324/M-0877/F-0735/F-1336/F-0828/M-1231/M-0609/M-1111/F-0957/M-1068/F-1213/M-0624/M-0524/M-0892/F-0537/F-0772/M-1201/M-0851/M-0940/F-0596/M-1051/M-0986/F-0900/M-0792/F-0739/F-1318/M-0694/F-0913/F-0846/M-0988/M-1084/F-1123/F-0515/M-1014/F-1190/F-0991/F-0937/M-0949/F-0799/F-0763/F-0579/F-0578/M-0979/M-1184/F-1119/F-0531/M-0553/F-1316/F-1120/M-1031/F-1138/M-1005/F-0502/F-1061/F-0672/M-1344/M-0646/M-0505/F-1010/M-1301/F-0685/F-1152/M-1218/F-0588/F-0712/M-1139/F-1312/M-1255/F-0629/M-1102/M-0831/F-0819/M-1107/M-1077/M-1304/F-1263/M-0834/F-0753/M-0961/F-0613/M-0901/M-0606/M-0557/F-1272/F-1004/M-0977/F-0688/M-0928/F-1129/F-0829/M-1307/M-1345/F-0838/F-0810/F-0561/M-0802/F-1106/M-0920/F-1155/M-0513/F-0893/F-0563/F-0682/M-0501/F-0530/M-0915/F-1274/M-0824/M-0862/M-0919/F-0580/F-0545/M-0888/F-0747/F-0671/F-1059/F-1215/M-1156/F-1297/M-0608/M-0859/F-1186/M-1035/F-1023/M-0996/M-1110/M-0951/F-0686/M-1247/F-1086/F-0804/M-0649/M-0567/F-1112/F-1143/F-0574/M-1326/M-1320/M-1281/M-0620/F-1279/M-1347/M-1145/M-1292/F-0635/M-0895/F-1348/F-1178/M-0897/M-0510/F-0514/M-1286/M-0582/M-0992/F-0520/M-0540/F-0728/M-1024/M-1195/M-0815/F-1103/M-0723/F-0952/M-0597/M-0536/F-1015/F-1136/M-0562/M-0590/F-1337/M-0771/F-0614/F-0727/M-0813/F-0956/M-1235/F-1222/M-0941/F-1313/M-1167/M-0740/F-1226/M-1095/M-0527/M-0903/M-0700/F-0583/M-0837/F-0592/M-0841/M-1038/F-0628/F-1132/M-0709/F-0764/M-0973/F-0601/F-0568/M-0926/F-0969/F-1026/F-0598/M-0560/F-1071/F-1046/F-1305/M-1069/M-0843/F-0767/M-1208/F-1126/F-0625/F-0955/M-0734/M-1268/M-1087/F-1342/M-1211/M-0995/M-0691/F-0974/M-0783/F-1282/F-1204/M-1303/M-0758/F-0849/F-1171/F-1041/M-1243/M-0943/M-0833/F-1188/F-0950/F-1001/F-0549/F-1066/M-0789/M-0556/M-0519/F-0839/M-0963/F-1002/F-1196/F-1168/F-1203/F-0975/M-0768/M-1276/F-0619/M-0933/F-0638/F-0917/M-0566/M-0678/M-1248/F-0687/F-0959/F-1240/F-1151/M-0765/M-1331/F-1315/M-1117/M-1164/F-0543/M-0528/M-0923/M-0899/F-1332/M-1262/M-1080/F-0953/F-1045/M-0602/M-1044/M-0534/M-0800/F-0508/F-1175/F-0773/F-1258/M-0518/M-0806/M-0675/M-1339/F-0942/M-0548/F-1202/F-0972/M-1170/M-0533/F-1013/F-0589/M-1266/M-0703/F-0898/F-1198/M-1181/F-1238/M-0699/F-0911/F-1314/M-0550/F-1261/F-0627/M-0642/M-1030/F-1154/F-0751/M-1000/F-1183/F-0786/F-0962/F-0544/M-0860/F-1216/M-0731/M-0778/F-0648/M-0809/F-0693/F-0617/F-1333/M-0878/F-1092/F-1349/M-1311/M-0850/M-0506/M-0581/F-0538/M-1043/F-0517/F-1322/M-1096/M-0572/F-1049/M-0529/M-1187/F-0503/M-0733/F-1055/F-0669/M-0818/M-0854/F-0864/F-0929/M-0704/M-0738/F-1256/M-0887/F-0858/F-0842/M-0868/F-0748/F-1098/F-0750/F-1016 | F10: Photography | G10: =LEFT(tblUsers[[#This Row],[ID]]) -> M | H10: =RIGHT(tblUsers[[#This Row],[ID]],4) -> 0507 | I10: =WEEKDAY(tblUsers[[#This Row],[Date of birth]], 2) -> 2 | J10: =WEEKDAY(tblUsers[[#This Row],[Date of birth]]) -> 3 | K10: 2001 | L10: 52
B11: F-0508 | C11: Marcy Hooper | D11: 35220 | E11: M-1223/F-0543/F-1171/M-0510/M-1025/M-1030/M-0926/M-0961/F-1257/M-0624/M-1307/F-0864/M-0925/F-0748/F-0687/F-1183/M-0851/F-1215/M-0806/F-0828/F-0682/F-0632/F-0953/F-1016/F-1196/M-0723/M-1276/M-0599/F-1004/M-1014/M-1339/F-1324/F-0580/M-1139/M-1184/F-0627/F-1143/F-1317/M-1036/M-0915/M-0694/F-0660/M-1248/F-0598/M-0910/M-1201/M-1145/M-1287/M-0744/M-1194/F-1212/M-0949/F-1026/F-0775/F-0538/F-0672/M-0606/F-0561/M-0519/M-1195/M-0779/F-0819/M-0869/M-0967/F-1138/M-0901/M-0843/F-0808/M-0524/F-0799/F-0739/F-0935/M-0831/M-0590/F-0512/M-0821/M-0996/F-0980/F-1059/F-1204/F-1285/F-0502/F-1165/F-0545/F-1178/M-1078/M-1033/F-0726/F-1063/F-0991/F-0663/F-1169/F-1168/M-1218/M-1301/F-0804/M-0860/F-0625/M-0636/M-0951/M-0526/M-0977/F-0517/F-0797/F-0514/M-0709/F-0959/M-0867/F-1013/F-0812/M-0670/F-1155/F-1146/M-0944/M-0593/M-0981/F-1226/M-0986/M-0979/F-1042/M-0513/M-0780/M-0620/M-1167/M-0841/F-1012/F-0531/F-1278/F-1316/M-1325/M-1326/F-0846/M-1084/M-0871/M-1281/M-1111/F-1032/M-0600/F-1136/M-0982/F-0697/F-1273/M-0646/M-0587/F-1179/F-0917/F-0905/M-1187/M-0553/M-0556/M-0560/F-0690/F-0855/F-0617/F-0588/F-0583/F-0719/F-0898/M-0607/M-0877/F-1210/F-0579/F-0574/M-0995/M-0608/M-1064/F-0712/M-1304/F-1023/M-0928/M-1005/M-0834/M-1135/F-1018/F-0757/F-0830/F-0798/M-0794/F-1328/F-1106/F-0717/M-0920/M-1054/F-0751/M-0970/M-1347/F-1188/M-0505/F-0668/F-0558/M-1293/F-1318/F-1305/M-0570/F-0532/M-0581/M-0539/F-0966/F-1041/F-0948/M-0507/M-1172/F-1057/F-0842/M-0988/M-0540/M-0941/M-0527/F-1070/M-0817/M-1091/M-1302/F-0516/M-1323/M-0833/F-0900/F-0720/F-0503/F-0563/M-0567/F-0913/F-0657/M-0501/M-0680/M-0826/M-0960/F-1133/F-0688/F-0692/F-1015/M-0626/M-0947/M-0805/F-1045/M-0815/M-1268/F-0893/F-0927/M-1038/M-0940/F-0651/M-1024/F-0728/F-0652/F-0616/M-1192/M-1069/M-1243/M-0562 | F11: Solving puzzles | G11: =LEFT(tblUsers[[#This Row],[ID]]) -> F | H11: =RIGHT(tblUsers[[#This Row],[ID]],4) -> 0508 | I11: =WEEKDAY(tblUsers[[#This Row],[Date of birth]], 2) -> 2 | J11: =WEEKDAY(tblUsers[[#This Row],[Date of birth]]) -> 3 | K11: 1992 | L11: 51
B12: M-0509 | C12: Margarito Hayden | D12: 35391 | E12: F-0953/F-0538/F-1151/M-0860/F-1126/F-1123/M-1031/F-0512/M-0534/F-1119/F-1210/M-0851/F-1045/F-0574/M-0744/F-0617/M-1135/F-1285/F-0638/M-1303/F-1012/F-0772/M-0967/M-1077/M-0996/F-1086/F-1136/M-0982/F-1060/F-1317/M-0818/F-0629/M-0919/M-0510/F-0525/M-0949/F-0751/M-0992/M-1339/M-1187/M-0960/F-1190/M-0755/F-1046/M-1068/M-1054/M-0570/M-1145/M-0783/M-0892/F-1169/M-1201/M-0694/F-0812/F-0531/F-0836/F-0959/F-0515/F-0712/M-0979/F-0520/M-1194/M-0606/F-0663/F-0757/M-0909/M-0576/M-0501/F-1106/M-1223/M-0779/F-1228/M-0794/M-1255/M-0536/M-0973/M-0906/M-0961/F-1280/M-0680/F-0625/F-1081/F-0913/F-0578/F-0623/M-0995/F-1198/F-0950/F-0894/M-0896/F-0984/M-1231/M-1291/M-1307/F-0545/F-1027/M-1302/M-0926/F-1316/F-0544/F-0563/M-0733/M-0802/M-0826/F-0991/M-0777/M-0529/F-1297/F-0842/F-1212/M-1044/F-1193/F-0735/M-0524/F-0508/M-0780/M-1267/M-0816/F-0829/F-1249/F-1071/F-0632/F-1070/M-0859/F-1263/F-1196/F-0798/F-1183/M-0567/F-0942/F-0668/M-0594/M-0519/F-1040/F-1337/F-1120/F-0787/F-0819/F-0957/M-1078/M-0560/F-0648/F-1010/F-1103/F-1226/M-0505/F-1130/F-0844/F-0564/F-1176/M-1117/F-0728/F-1098/M-0600/M-0597/M-0557/F-0532/M-0577/F-0690/F-0672/M-1266/M-0877/F-0886/F-1257/M-0528/F-1004/F-0647/F-0773/F-0786/F-1168/F-1336/F-0614/M-0824/F-1049/M-0587/F-1240/M-0630/M-0771/F-0753/M-1293/F-0980/F-0884/M-0513/F-1062/F-0810/M-1287/M-1167/M-0608/M-1033/F-1129/F-0804/F-0975/F-0687/M-0998/F-0872/M-0624/F-0827/M-1241/M-0507/M-1248/F-0657/F-1075/F-1216/F-1018/M-0782/F-1013/F-0855/F-0898/M-0920/F-1090/F-0939/F-1131/F-1032/M-1139/M-0539/M-0940/M-1007/F-0685/F-0767/F-0504/F-0530/M-1329/M-0556/F-0517/F-1321/M-1051/M-0599/F-1225/F-0924/M-0820/M-0831/M-0815/M-0665/M-1053/F-0701/F-1213/F-0955/M-1218/M-1269/F-0516/M-1286/M-0813/M-0540/F-1108/F-1001/M-0869/F-1079/F-1273/F-1222/M-0814/M-1195/F-1253/F-0568/M-0833/F-0828/M-0988/M-0636/M-1067/F-0613/F-1305/F-1112/F-0846/M-1247/F-0748/M-0738/F-1023/F-0669/M-1334/F-1251/F-0883/F-0929/F-0714/M-1147/F-1115/M-1243/M-1163/F-0619/M-0656/M-0774/F-0514/M-0806/M-1064/M-0910/F-1175/M-1347/M-0646/F-1152/M-1319/M-0759/M-0925/F-0551/F-0503/F-0987/M-1164/F-0661/M-1207/M-0888/F-0935/F-1171/M-1300/F-0839/M-0876/M-1118/M-1301/F-0968/M-0977/F-0705/F-0763/M-1072/F-1127/M-0550/M-1325/M-1344/F-0830/F-0948/M-0778/M-0752/F-0956/F-0861/M-0670/F-0954/M-1087 | F12: Playing board games | G12: =LEFT(tblUsers[[#This Row],[ID]]) -> M | H12: =RIGHT(tblUsers[[#This Row],[ID]],4) -> 0509 | I12: =WEEKDAY(tblUsers[[#This Row],[Date of birth]], 2) -> 5 | J12: =WEEKDAY(tblUsers[[#This Row],[Date of birth]]) -> 6 | K12: 1995 | L12: 51
B13: M-0510 | C13: Brady Brock | D13: 35487 | E13: F-1123/F-1013/F-1046/M-0837/M-1243/F-0935/F-1316/F-1317/F-0839/M-0778/M-0899/F-1129/M-1248/F-0819/F-1228/F-0625/F-0812/F-0804/F-1151/M-0986/M-1167/M-0609/M-0988/F-1012/F-0786/F-0900/F-0828/F-1002/M-1231/M-1035/M-0859/M-1301/F-1098/M-0664/F-1071/M-1036/F-1204/M-1051/F-0617/M-0599/M-1195/M-0694/M-0606/M-1201/M-0818/F-1126/M-1287/F-1132/F-0927/M-0768/M-1030/M-0566/M-0834/F-0545/M-0833/F-0512/M-1182/M-1145/M-0560/F-0578/F-1193/F-0668/M-0973/M-0777/F-0861/F-0882/F-0622/M-0967/M-0821/M-1054/M-0501/F-0829/M-0841/M-1255/M-1021/M-1135/M-0925/M-0843/F-0754/F-0638/M-0860/F-0747/M-0779/F-1210/F-0775/F-0697/M-0548/M-0940/F-1285/M-0979/M-0513/M-1319/F-1171/F-0686/F-0913/M-1102/F-0954/F-0531/M-1325/F-0959/M-1107/M-1024/M-0678/M-1218/F-1282/M-1087/F-0898/M-0536/M-0594/F-0714/M-0781/M-0555/F-0751/M-0755/M-0897/F-1169/M-1068/M-0733/F-1055/F-0763/F-1136/M-1156/F-0574/M-0895/M-0782/M-0744/F-0619/F-0563/M-0524/F-0727/M-0977/M-0862/M-1276/F-0975/M-1031/M-0981/M-1095/F-1179/F-0980/M-0878/F-1079/M-0901/F-1297/F-0717/F-0688/F-1215/M-1139/F-0525/M-0587/F-1202/M-0567/F-0623/M-0602/F-0628/F-1061/M-0944/M-1300/M-0876/F-0520/F-0748/M-0993/M-0700/F-1026/F-0596/M-1292/F-1346/M-0597/F-0852/F-0514/F-0810/M-0915/F-0953/F-0687/M-0960/M-1291/M-1307/M-0570/M-0961/F-1259/M-0634/M-1293/M-0577/F-1155/F-1272/M-1064/F-1165/F-0797/F-0503/M-1267/F-1040/F-1196/F-1183/F-0799/M-0742/M-0610/F-0579/F-1059/M-1038/M-0646/F-0669/F-1232/F-0787/M-1268/M-0963/M-0793/M-0919/M-0910/F-1016/M-0505/M-0868/M-0624/F-1032/M-0892/F-0598/F-0798/M-0826/F-0957/F-0671/M-1077/M-1347/F-0864/F-1144/M-1163/F-0629/F-1063/F-1178/F-1004/M-1084/M-1192/F-1130/F-1075/M-0964/F-1333/F-1312/F-0934/M-1184/F-0894/M-0774/M-1262/F-1198/M-0771/M-1009/M-0540/F-1089/F-0544/F-0772/M-1247/F-1314/M-1037/F-0592/M-0586/F-0685/M-0994/F-1233/M-0562/M-0644/M-0738/F-1318/F-1042/M-0696/M-0636/F-0739/M-0526/F-1138/F-1189/F-1060/M-0573/M-1286/F-0838/F-1256/F-1190/F-0583/M-0885/M-0877/M-0933/M-0752/M-1241/F-0795/F-0613/F-1106/F-0735/M-0923/F-0660/F-1226/M-1223/F-0551/F-0830/F-0972/F-1018/M-1339/F-0682/F-0757/F-1274/M-0654/F-1108/M-1005/M-0806/M-1110/M-1044/M-0770/F-1342/F-0937/M-1074/M-0998/F-1336/F-1119/F-0942/F-0924/F-0612/M-1208/F-1152/F-0591/M-0655/F-0911/M-0996/F-1305/F-1313/F-0726/F-0962/M-0550/F-0855/M-0920/M-1111/F-1086/M-1083/M-0670/F-0956/F-1134/F-0965/F-0532/M-0680/F-1160/F-1212/M-0928/F-0857/M-1033/M-0906/F-1045/M-0732/M-1206/F-0672/F-1168/M-0529/F-0580 | F13: Basketball | G13: =LEFT(tblUsers[[#This Row],[ID]]) -> M | H13: =RIGHT(tblUsers[[#This Row],[ID]],4) -> 0510 | I13: =WEEKDAY(tblUsers[[#This Row],[Date of birth]], 2) -> 3 | J13: =WEEKDAY(tblUsers[[#This Row],[Date of birth]]) -> 4 | K13: 2003 | L13: 50
B14: F-0511 | C14: Maryellen Gates | D14: 35902 | E14: F-0592/F-0804/M-0505/M-1201/F-1317/F-1285/M-1243/F-1046/F-1212/M-0860/F-1123/M-0967/F-0959/M-0636/M-1107/F-0672/F-1169/M-0680/M-0567/F-1204/M-0833/F-1171/M-0593/F-0537/M-0926/F-1086/M-1139/M-0899/F-0861/F-0735/F-0775/F-1136/M-0986/F-0799/M-0507/F-1213/M-1031/F-1216/M-0678/F-1196/F-1129/F-1138/M-0791/F-1032/F-0596/F-1151/M-0960/M-1033/F-0625/M-0510/F-0632/F-0911/F-1198/F-1132/M-1286/F-1324/M-1276/M-0996/M-0758/F-0563/F-0953/F-0954/M-0910/F-0688/F-0580/F-1193/F-1023/F-0929/M-1182/M-0817/F-1263/F-0660/M-0859/F-1183/M-0778/M-0783/M-1181/M-0768/M-0664/F-0686/F-0614/M-0809/F-1168/F-1106/M-1218/M-1303/F-0839/F-1305/F-1155/F-1188/M-1301/M-0658/F-0682/F-0671/F-1202/F-0812/F-1253/F-0638/F-1012/F-1002/F-0538/M-1247/M-1241/F-0545/F-1278/F-0525/F-0748/M-0590/F-0957/F-0517/M-0709/F-1079/M-0951/M-1038/M-0670/M-0869/F-0588/M-0782/F-1066/F-0772/F-1119/F-1228/F-0956/M-1068/M-0897/M-0995/F-0568/M-1014/M-0915/F-1062/M-1205/F-0753/F-0583/M-0909/M-1147/M-0792/F-0808/M-0519/M-0610/F-0687/F-0629/M-0597/M-1007/M-1005/F-1108/F-0579/M-0607/M-1110/M-1043/F-1059/M-1291/F-1318/M-1030/M-0665/M-1035/F-1190/M-0977/F-0872/F-0913/M-1281/M-0877/F-0705/F-1222/M-0557/M-0536/F-1040/F-1016/F-0659/M-0609/F-1297/M-1326/M-0781/F-1045/M-0556/F-1130/F-0807/M-1289/M-0925/M-0818/M-0738/M-0779/F-0980/M-0501/F-0669/M-0703/F-0763/F-0720/F-0924/F-1271 | F14: Pottery | G14: =LEFT(tblUsers[[#This Row],[ID]]) -> F | H14: =RIGHT(tblUsers[[#This Row],[ID]],4) -> 0511 | I14: =WEEKDAY(tblUsers[[#This Row],[Date of birth]], 2) -> 5 | J14: =WEEKDAY(tblUsers[[#This Row],[Date of birth]]) -> 6 | K14: 1991 | L14: 45
B15: F-0512 | C15: Mauro Goodwin | D15: 34497 | E15: M-0505/M-1223/M-0988/M-0843/M-0607/F-1136/F-1151/F-1013/F-1119/F-1285/M-1276/M-0636/M-1025/F-0592/F-1204/M-0778/F-0954/M-0949/F-1045/M-0609/F-0596/F-1171/M-0562/M-1139/F-1226/M-0703/M-0996/M-1248/M-0909/F-0980/M-1347/F-0754/M-0723/M-1031/F-1106/F-0927/M-1030/M-0960/F-1071/M-0806/M-0961/M-1187/F-0619/F-0772/M-0837/F-0583/M-0570/M-0851/F-0688/M-0536/M-1068/M-1107/F-1002/F-0726/M-0892/F-1060/M-0606/M-0646/M-0566/F-1169/F-0934/M-0738/F-0913/M-0694/F-0959/M-0899/F-0574/F-0751/M-1054/M-0896/M-1069/F-0812/F-1168/F-1202/F-0671/F-0504/M-0926/M-0782/F-1337/F-0929/F-0775/M-1182/F-0531/F-1010/M-0826/F-0544/M-1307/M-0620/F-1046/M-0593/M-1084/F-0714/M-0513/M-0820/F-1016/F-1061/F-0844/F-0935/F-0638/M-1339/F-0588/M-0540/M-0600/F-0957/M-1291/F-0617/F-0563/M-1319/F-0753/F-0549/F-1120/M-0925/M-1301/F-0515/M-1038/M-0920/F-1280/F-0747/M-0597/F-0942/F-1023/F-0911/F-1057/F-0632/F-1129/M-0758/F-1121/M-0901/F-0612/F-0622/M-0973/F-1213/F-1152/F-1305/M-0906/M-1303/F-0719/M-1147/F-0797/F-1282/M-0840/M-1005/M-0527/F-0502/F-0580/M-0862/M-1325/F-0628/M-0860/F-0525/M-1243/F-0849/M-0658/M-0742/F-1153/F-1313/F-1004/F-0956/F-1183/F-0687/M-1208/M-1091/F-0578/F-1126/M-1345/F-0685/M-1083/M-0501/F-1250/F-0517/F-1026/F-1349/F-1216/M-1035/M-0821/F-1190/F-1295/F-1075/M-1184/M-0724/M-0915/F-0787/F-1055/F-0974/M-0528/M-0834/F-0893/M-1142/M-1262/F-1138 | F15: Writing | G15: =LEFT(tblUsers[[#This Row],[ID]]) -> F | H15: =RIGHT(tblUsers[[#This Row],[ID]],4) -> 0512 | I15: =WEEKDAY(tblUsers[[#This Row],[Date of birth]], 2) -> 7 | J15: =WEEKDAY(tblUsers[[#This Row],[Date of birth]]) -> 1 | K15: 2004 | L15: 45
... B19: F-0516 | C19: Madeline Gonzales | D19: 39256 | E19: F-0786/M-0567/F-0592/M-1276/F-0935/F-0578/F-1336/F-1123/M-0841/M-0636/M-0678/F-1106/M-0899/F-0543/M-1111/F-0804/F-0953/M-0833/F-1120/M-1347/F-1178/F-1045/F-1004/M-0560/F-1215/F-0688/F-0913/F-0799/F-1165/F-1213/F-0763/M-0599/M-0755/M-0996/M-0680/F-0617/M-0988/M-1201/F-1002/M-0501/F-1324/M-0607/F-1086/M-1286/F-0622/F-1226/F-0726/F-1204/F-1155/F-0836/M-0738/F-1190/F-0682/F-1132/M-1181/M-0548/M-0540/F-1098/M-0792/F-0512/M-0977/F-0632/M-0536/M-1223/F-0838/F-1060/F-1312/F-1317/F-1212/M-0979/M-0507/M-0982/M-1319/M-1293/F-1119/F-1282/M-0550/M-1194/F-1066/F-1041/F-0747/F-0952/F-0775/M-0940/M-1036/F-1071/M-0928/M-1069/F-0757/M-0768/M-0715/M-1334/F-0545/F-0668/F-1126/M-0896/M-0709/M-0774/M-1068/M-0967/F-0959/F-0957/M-0570/F-0839/M-0691/F-1183/M-0818/F-0717/M-0590/F-0787/F-0672/F-0810/M-0877/M-0665/M-1267/M-1307/F-0764/F-1151/F-1168/M-0562/M-0981/M-1247/M-0658/F-1193/F-0819/M-1030/F-0525/F-1144/F-1059/F-1143/M-1231/F-0748/M-0694/M-1156/M-1298/M-0534/F-0588/M-0700/M-0523/M-1167/M-1033/F-0735/F-0754/M-1005/M-0758/F-0739/M-0881/M-1139/M-1302/M-0557/M-0673/F-0929/F-0864/F-0663/F-0950/F-1186/F-0623/M-1301/F-1316/F-1026/F-1245/F-0886/F-0531/M-1117/F-1305/F-0893/F-1342/M-0609/M-0885/F-1092/F-0911/M-0843/F-0798/M-0925/F-1046/F-1346/M-1142/F-0551/M-0646/M-1187/F-1318/F-0852/F-1238/F-1169/F-0698/M-1035/M-0634/M-0724/M-1170/M-0547/F-1171/F-1012/M-1325/M-0577/F-1032/F-0942/F-1057/F-0625/F-1328/F-0538/M-1083/F-1018/F-1249/M-0505/F-0574/M-0782/F-0808/F-0619/M-0926/M-0834 | F19: Drawing | G19: =LEFT(tblUsers[[#This Row],[ID]]) -> F | H19: =RIGHT(tblUsers[[#This Row],[ID]],4) -> 0516 | I19: =WEEKDAY(tblUsers[[#This Row],[Date of birth]], 2) -> 6 | J19: =WEEKDAY(tblUsers[[#This Row],[Date of birth]]) -> 7 | K19: 2007 | L19: 34
B20: F-0517 | C20: Mayra Townsend | D20: 36530 | E20: F-0622/F-0828/F-1204/M-0973/F-0775/M-0988/M-0755/M-0960/M-0859/M-0694/M-0536/F-0543/M-1223/F-1198/F-0935/M-1347/M-1031/M-1068/F-1152/M-0607/F-0959/M-0860/F-1213/F-0991/F-1126/M-0646/F-0799/M-0744/M-1014/M-0534/M-0834/F-0627/F-1079/M-1276/F-0629/M-0961/F-1013/M-1255/F-1001/M-0791/F-0671/M-0821/M-0926/F-0839/M-1287/F-0544/M-1187/M-0553/M-0774/M-1078/M-0606/M-1054/F-1032/M-1195/M-0550/F-1119/M-1087/M-0992/M-0636/F-0786/F-0846/F-1045/F-1273/F-1060/F-0957/F-1041/F-1106/M-0979/F-0660/F-1061/M-1051/M-0940/M-0843/M-0919/M-1243/F-0836/M-0680/F-0913/F-1010/M-1181/M-0593/M-1170/M-0895/M-0876/M-1111/F-0952/M-0896/M-0513/M-0783/F-1282/F-0844/M-0529/F-0592/F-1165/F-1129/M-1102/F-1086/M-1307/F-1136/F-0842/M-0818/F-1132/F-0735/M-0576/F-0719/F-0549/F-1263/F-0705/F-0545/M-0670/F-1002/M-0567/M-0526/F-1245/M-1262/M-0587/F-0583/F-0579/F-0804/F-1040/F-1210/M-0510/M-0777/F-0937/F-0504/M-0691/F-1016/F-1071/M-0768/M-0831/F-1046/M-1035/M-1043/F-1169/M-0501/F-1023/M-0602/M-0820/F-0613/M-1077/F-1278/F-0682/F-1168/M-0851/M-0970/F-1143/F-0578/M-1218/F-0807/M-0557/M-0548/F-1112/F-0659/F-0574/F-0754/F-0760/F-1316/F-0687/M-1286/M-1025/F-1130/M-0824/F-1337/F-1171/M-0837/F-1202/F-1123/F-1052/F-0984/F-0628/M-0862/M-0963/M-0885/F-1190/F-1233/M-1268/M-1005/M-0678/F-1215/F-0747/F-0893/F-1127/M-0899/M-0923/M-0779/F-0651/F-0720/F-1336/M-0881/F-0598/M-0814/M-0951/M-0986/M-0731/M-0505/F-0614/M-0539/F-1062/F-0502/F-1188/M-1109/F-1238/F-1346/F-0520/M-0878/M-0732 | F20: Yoga | G20: =LEFT(tblUsers[[#This Row],[ID]]) -> F | H20: =RIGHT(tblUsers[[#This Row],[ID]],4) -> 0517 | I20: =WEEKDAY(tblUsers[[#This Row],[Date of birth]], 2) -> 3 | J20: =WEEKDAY(tblUsers[[#This Row],[Date of birth]]) -> 4
B21: M-0518 | C21: Hai Ferguson | D21: 33451 | E21: F-0672/M-1014/M-1347/F-0537/M-1167/F-1123/F-0638/F-0688/M-0841/F-0804/F-1171/F-0913/F-1190/F-0775/F-0574/F-0934/F-1046/F-0748/F-1151/F-1119/F-0819/F-0592/F-1324/F-0627/F-0512/F-0957/F-1026/F-1120/M-0519/F-0980/F-1317/F-0900/F-1004/F-0538/F-1183/M-0678/F-0836/M-0540/M-0973/M-0562/F-0954/F-1216/M-1139/M-1303/F-1143/M-0534/M-1276/F-0671/F-1169/M-0505/M-1084/F-1016/F-0786/M-0824/F-1136/M-0609/M-1307/M-0755/M-1033/M-0986/M-0777/F-0502/M-1038/M-1101/M-0877/F-1212/M-1031/F-1146/M-0548/M-0896/F-1193/M-0961/M-0599/M-1145/F-0911/F-0950/M-1241/F-0668/M-0590/F-0622/F-0991/F-1155/M-0925/M-0610/F-0549/F-1079/F-0763/F-0687/F-0942/M-0919/M-1184/M-0940/M-0670/F-1312/M-1302/F-0564/M-0567/M-1111/F-0614/F-1063/M-0843/M-0779/M-1025/F-1013/F-1257/F-0935/M-0909/F-0660/F-1222/F-1297/F-1130/F-1202/M-0821/F-1032/M-0996/F-0544/M-1095/M-0620/F-0984/M-0995/M-0920/F-1144/F-0720/F-1001/F-0525/M-0869/F-0937/F-1271/M-1319/M-0834/M-1334/F-1041/F-0663/F-1131/F-1273/F-1002/M-0860/F-0531/M-0895/F-1318/F-0612/M-0694/F-0563/M-0818/F-0864/F-1126/M-1158/F-1210/F-0773/F-1108/M-0892/M-0507/F-0625/F-0905/M-0607/F-1305/M-0926/M-0553/F-1272/F-0515/F-1204/F-1178/F-1245/F-0855/F-0927/M-0992/F-1042/F-0799/F-1228/M-0559/F-1260/F-0616/F-1188/M-0550/F-1284/M-0501/M-0740/F-0844/F-0767/F-0686/M-0774/M-1054/M-0881/M-1172/F-1129/F-1280/M-0862/F-1315/F-0889/M-1022/M-0528/F-1226/M-1201/M-0732/F-0924/M-0982/F-0747/F-1132/M-0555/M-0679/M-1248/M-1135/F-0561/M-1195/M-0802/F-1168/M-1036/F-0893/M-0630/M-0746/M-1325/M-0977/M-1287/M-1300/M-1247/F-1274/M-0833/M-1289/F-0975/F-1152/M-0901/F-0737/M-0851/M-1083/F-1186/M-0837/M-0709/F-1333/M-0781/M-0641/M-0744/F-0861/M-1344/M-1164/F-0727/M-0560/M-0793/M-0947/M-0906/M-0556/F-0543/M-1021/F-1012/F-1138/F-1149/F-0712/M-0658/M-0680/F-0931/F-1121/M-1243/M-0967/F-0623/F-0504/F-1233/F-0797/M-1301/F-1134/F-0568/F-1023/M-0910/M-0650/F-1275/M-1298/M-1223/M-0608/F-1055/M-1262/M-0778/M-1304/M-0988/F-1059/F-1098/F-0772/F-1175/F-0956/F-0619/M-1110/F-1060/M-0998/F-0810/F-0698 | F21: Watching movies | G21: =LEFT(tblUsers[[#This Row],[ID]]) -> M | H21: =RIGHT(tblUsers[[#This Row],[ID]],4) -> 0518 | I21: =WEEKDAY(tblUsers[[#This Row],[Date of birth]], 2) -> 4 | J21: =WEEKDAY(tblUsers[[#This Row],[Date of birth]]) -> 5
B22: M-0519 | C22: Arnulfo Lara | D22: 39316 | E22: F-0828/F-0622/M-0567/F-1119/F-1285/M-0678/M-1201/M-1243/F-0812/F-0531/M-0960/M-1319/M-0851/M-0536/M-0636/M-0899/F-0671/M-1078/M-0723/F-1026/F-0786/F-1004/F-1120/M-1248/M-0949/M-1035/F-0579/M-1014/M-0919/F-0512/F-0882/M-0973/F-0935/M-1187/F-0775/F-0544/F-1155/F-0772/F-0799/F-0537/M-0892/M-0607/F-1171/M-1084/F-0525/F-0975/F-0934/M-0901/M-1231/M-0505/F-1169/F-1108/F-1138/F-0638/M-1025/F-1136/M-0988/F-0900/F-1204/F-0829/M-0782/M-0824/F-1066/M-0694/F-0937/F-1190/M-0744/M-1344/M-1247/F-1216/F-0953/M-1033/F-0838/F-0839/F-1212/F-0596/F-0754/M-0779/F-0959/F-1263/M-1301/F-0954/F-1196/M-0609/F-0578/F-0808/F-0864/M-1195/M-0570/F-1312/F-0913/F-1210/M-0982/F-0911/F-0760/F-0751/F-1168/M-1117/F-1001/M-0970/F-0516/M-0664/M-0526/M-0606/F-1271/M-0792/F-0632/M-1107/F-1106/F-0659/F-0580/F-0563/F-1027/F-1228/F-0712/F-0515/M-0778/M-0715/F-0927/F-0688/M-1223/F-1130/F-0517/F-0974/F-1071/F-0686/M-0670/F-1324/F-0719/F-0598/F-0955/M-0590/F-1143/F-0842/F-0617/F-1222/F-0980/M-1269/M-1241/M-1077/M-1347/M-1293/M-0877/F-0798/F-1336/M-0755/M-0620/M-1194/M-0573/M-0758/F-1284/M-0646/M-1147/M-1276/M-0738/M-1087/F-1070/M-0818/M-1283/F-0807/M-0771/M-0833/F-0568/M-0813/M-0594/M-0816/F-0543/F-1258/F-1215/F-0991/F-0735/F-1092/M-0837/F-1273/M-0940/F-0804/F-1198/M-1287/M-0649/F-0739/M-0553/M-0658/F-1346/F-1226/F-1126/F-1013/F-0687/F-1098/F-1175/M-0680/F-0619/M-0586/M-0854/F-0773/F-1127/M-1255/M-0941/F-1178/F-0651/F-1337/F-1260/M-1044/F-1149/M-1111/F-0747/F-0956/M-0909/M-1218/F-0698/M-1102/M-1325/F-1151/F-1079/M-0856/F-0648/M-0560/M-0656/F-1116/M-0802/F-0810/M-0979/M-0895/M-1208/M-1323/M-0998/F-0660/M-0860/M-0745/M-1101/F-0748/F-0763/M-1095/M-0626/M-1021/M-1167/F-1238/M-0945/M-0906/F-1057/M-0997/M-0765/F-0917/M-0599/F-1063/F-1041/F-1348/F-0931/F-1012/M-0582/M-0696/F-1259/F-0627/M-1291/F-0801/F-0685/M-0789/M-1329/F-1214/M-0507/F-0990/M-0995/F-0714/M-0566/M-0876/M-0630/F-0726/M-1331/M-1029/M-1031/F-0939/F-0522/M-0600/F-0948/F-1045/F-0929/M-0624/F-1075/M-0961/M-0887/M-0673/F-0502/F-0890/M-0977/F-0883/M-1003/F-0689/F-0530/M-0920/M-1304/M-0992/F-1280/F-1183/F-0592/M-0820/F-1152/M-1036/M-1211/F-1179/M-1161/M-0866/F-1015/M-0542/M-0528/M-0524/F-0857/M-0776/M-1286/M-0559/M-0540/M-1264/F-0861/F-0503/M-0964/F-1086/F-1233/M-0910/M-0859/F-1042/M-1300/M-1072/F-1229/M-0791/M-0604/M-1069/F-1202/F-0753/M-0821/M-1181/M-1009/F-0898/M-1145/F-1081/F-1165/M-1268/F-1318/F-0968/F-1089/M-0834/M-1334/M-0631/F-1176/F-1244/M-1054/F-0532/M-0761/F-0849/F-1297/F-0803/F-0672/F-0574/F-1040/M-1235/F-1123/F-0653/F-0538/F-1316/F-0625/M-0746/M-0862/F-1105/F-0520/F-0504/M-1056/M-1022/M-0926/M-0679/M-0903/F-1253/F-0628/M-0843/F-0551/F-1274/F-1032/F-0875/M-0996/F-1317/F-0564/F-0545/F-1061/F-0844/F-0684/M-0752/M-1139/M-0555 | F22: Photography | G22: =LEFT(tblUsers[[#This Row],[ID]]) -> M | H22: =RIGHT(tblUsers[[#This Row],[ID]],4) -> 0519 | I22: =WEEKDAY(tblUsers[[#This Row],[Date of birth]], 2) -> 3 | J22: =WEEKDAY(tblUsers[[#This Row],[Date of birth]]) -> 4
B23: F-0520 | C23: Bob Garza | D23: 33256 | E23: F-1198/F-1026/M-0960/M-1068/F-1285/F-1171/F-1324/F-1012/M-1243/M-0507/F-0763/M-0977/F-0538/F-0531/M-0599/M-0919/M-1347/M-0779/F-0563/F-1120/M-0778/F-0617/F-0688/F-1132/M-0949/M-1031/M-1248/M-0996/F-0537/M-0624/F-0747/F-1129/F-0935/F-0934/F-0839/M-1005/F-1071/M-0988/M-0791/F-0828/M-0680/F-1123/M-0536/F-1126/F-1318/M-1182/M-0610 | F23: Solving puzzles | G23: =LEFT(tblUsers[[#This Row],[ID]]) -> F | H23: =RIGHT(tblUsers[[#This Row],[ID]],4) -> 0520 | I23: =WEEKDAY(tblUsers[[#This Row],[Date of birth]], 2) -> 5 | J23: =WEEKDAY(tblUsers[[#This Row],[Date of birth]]) -> 6
B24: F-0521 | C24: Wilda Whitehead | D24: 37958 | E24: M-0821/F-1168/F-1336/F-1046/F-1013/F-0538/M-0973/F-0839/M-0678/F-1226/M-1111/M-0723/F-1152/F-0596/M-0505/F-0980/M-1033/F-1196/M-1107/F-0512/F-0927/F-1071/F-0900/F-0935/M-0834/F-0579/M-1035/F-0629/F-0864/M-0915/F-1190/M-0646/F-0739/M-0566/M-0548/F-0991/M-0824/M-1054/F-0574/F-0502/M-1347/M-0833/M-0680/M-0859/F-1079/M-0553/F-0568/F-1151/M-1077/F-0775/M-1036/M-0920/F-0846/F-1284/F-0592/F-0959/M-1339/M-0970/M-1319/F-1282/F-0861/F-0625/F-1004/M-1298/F-1012/F-0836/F-1210/F-0627/F-0622/F-0632/F-0786/M-0892/F-0929/F-0735/F-0668/F-0563/F-0717/F-1337/M-1087/M-0562/M-1167/M-0755/M-1117/F-0659/M-0620/F-0671/M-1101/F-1119/M-0636/F-1328/M-0694/F-1317/F-0754/F-0619/F-0598/F-0810/M-0715/M-0528/F-1324/M-1262/F-1086/M-0593/M-0982/M-0996/F-1213/M-0567/F-0893/F-1155/F-1215/F-0516/F-1285/M-1281/F-1032/M-1293/M-0944/M-0995/F-0828/F-0763/M-1334/F-1066/M-0576/F-0727/F-0894/M-1247/M-0877/M-0843/M-1084/M-1051/M-1301/F-1143/M-0696/M-0868/F-1023/M-1147/F-1057/M-0781/M-0709/F-1178/M-0926/F-0799/F-1271/F-0698/M-0557/F-0872/F-1183/F-1059/F-1278/M-1118/M-0932/M-1201/F-0720/F-1130/F-1272/M-0949/M-0740/M-0817/F-0617/M-0910/F-0807/F-0705/F-0545/M-0814/F-1018/F-0689/M-1109/M-1269/F-1186/M-1021/M-0909/M-0854/F-1045/F-0952/M-1241/M-0611/M-1218/F-0663/M-1068/F-1346/M-0513/M-1307/M-0501/M-0963/M-1043/F-0532/M-0771/M-1156/F-0772/M-1231/F-0686/F-0950/M-1030/F-1316/F-0842/M-0524/M-1292/M-0977/M-0988/F-0531/F-1010/F-0747/F-0564/M-1029/M-1325/M-0865/F-1132/F-0726/F-0719/F-0924/F-0838/F-0787/M-0582/M-0851/M-1286/M-1069/F-0748/F-1055/M-0778/F-1171/M-0871/M-1255/M-0947/F-1108/F-0613/M-0526/F-0762/M-1283/M-0993/M-0594/F-0583/F-1081/F-0797/F-1089/M-0791/M-0876/F-0601/F-1309/M-1205/F-0728/M-0691/M-0738/F-1169/F-1040/M-0928/M-0556/M-0650/M-0986/F-0882/M-0649/F-1312/M-0662/M-0606/F-0578/M-1194/F-1026/F-1204/M-0967/F-0812/M-0933/F-0543/M-1208/F-1333/F-0886/F-1229/F-1259/M-1145/F-1060/F-0875/M-0597/M-1078/F-1049/M-1044/F-0552/M-0536/F-1273/F-0955/F-1016/M-1038/M-0724/F-0588/F-1129/F-0954/M-0607/F-0669/M-0586/M-0899/F-1198/M-1320/M-0813/F-0751/M-1344/F-1189/M-0507/M-1195/M-1224/F-1209/F-1042/F-1098/F-0517/F-0549/M-1329/M-1182/F-1115/M-1304/M-0831/F-1103/M-0792/M-0895/F-1342/M-0853/F-0714/M-0862/M-1025/M-0994/F-0660/F-0974/M-1191/M-0540/F-0773/M-1163/M-0758/F-0707/M-0779/F-1274/F-0956/F-1313/M-0665/M-0699/F-1216/F-0914/M-0736/F-0795/F-0953/F-0653/F-0819/M-1223/M-1289/F-1318/M-1099/F-0804/M-0519/F-0537/M-1187/M-0584/F-1097/M-0655/M-0639/M-0878/F-0725/M-1302/F-1212/M-1276/F-0580/M-0744/F-0829/F-0672/F-1227/M-1311/F-1002/F-0966/M-1243/F-1165 | F24: Woodworking | G24: =LEFT(tblUsers[[#This Row],[ID]]) -> F | H24: =RIGHT(tblUsers[[#This Row],[ID]],4) -> 0521 | I24: =WEEKDAY(tblUsers[[#This Row],[Date of birth]], 2) -> 3 | J24: =WEEKDAY(tblUsers[[#This Row],[Date of birth]]) -> 4
B25: F-0522 | C25: Mervin Gaines | D25: 37369 | E25: F-0672/F-1119/F-0592/M-1243/F-0578/F-1098/F-1045/F-1190/M-0837/M-0967/F-0543/M-1276/M-0678/F-1071/M-1347/M-0833/F-1204/F-1013/F-0772/F-0786/M-1078/M-1107/M-1111/M-1033/F-0502/M-0926/F-0953/M-0624/F-1196/F-0927/F-0531/M-1303/F-0804/F-0900/M-0609/M-0610/F-0579/M-1339/F-0712/M-0524/M-0646/F-0864/M-1054/F-1212/M-1014/F-0739/F-0911/F-0660/F-0957/M-1241/F-1318/M-0859/M-1184/M-0567/M-0995/F-0846/M-0553/F-1226/F-1188/M-1025/M-0961/M-1195/F-1120/M-1031/F-0757/F-0929/M-1307/M-1247/F-0844/F-1285/F-1086/F-1213/M-0881/M-1248/F-1305/M-0534/F-1215/F-1152/M-0526/M-1135/F-1063/F-0714/M-0973/M-0755/F-0574/F-0775/F-1106/F-0525/M-0778/F-0614/F-1012/F-0627/F-0583/M-1147/M-0505/F-0538/F-1210/M-0774/F-0760/F-0717/M-0996/F-0686/F-0748/F-1253/M-1110/M-0599/M-0566/M-0636/F-0950/M-1181/M-0843/M-1044/F-0747/F-0917/F-1079/F-0515/F-0735/M-0960/F-1144/F-1169/F-0727/M-0536/F-0651/M-0818/F-0952/F-0913/M-0981/F-1233/M-1077/M-1036/M-1319/F-0697/F-0935/F-1198/F-1002/F-0830/F-0530/F-0764/F-1057/M-0868/M-1223/M-0963/F-0819/M-1022/M-0758/F-0596/M-0528/F-1062/M-0700/F-1168/F-0799/F-1129/F-0763/M-0915/M-0709/F-0619/F-1171/M-1208/F-1130/F-1228/M-0740/F-1297/F-0544/F-0828/M-0877/F-0580/F-1131/M-0892/M-0779/F-1183/M-0992/F-1193/M-0910/M-0897/M-1344/M-0608/F-1042/F-1123/M-1287/F-1108/M-1218/F-1328/M-1266/M-0951/F-0648/F-0719/M-0649/M-0834/F-1263/F-0632/M-1262/M-1167/M-0611/F-1046/F-0685/F-1336/F-0622/M-0949/F-0561/F-1316/F-0517/F-1066/M-0680/F-1337/F-1322/M-0738/F-1225/F-1324/M-1326/M-1095/M-1304/M-1269/M-1231/M-0979/M-1139/F-0692/M-1164/M-0867/M-0587/M-1293/F-1348/M-0815/F-0937/F-0931/M-0792/F-0882/M-0732/F-0563/M-1310/F-1333/F-0516/F-1146/F-0991/M-0919/M-0696/F-1138/M-0560/F-0956/F-1149/M-0901/M-0664/F-1141/F-0807/M-1021/M-0607/M-1302/M-1109/F-0625/F-0688/M-1038/F-1049/F-1315/M-0899/M-0555/F-1155/M-0724/M-0920/M-0940/M-0806/M-1030/F-1090/F-1151/M-1187/F-1115/M-0513/M-0970/F-1075/F-1017/F-1023/F-1176/M-1009/M-0860/F-0845/M-0691 | F25: Cooking | G25: =LEFT(tblUsers[[#This Row],[ID]]) -> F | H25: =RIGHT(tblUsers[[#This Row],[ID]],4) -> 0522 | I25: =WEEKDAY(tblUsers[[#This Row],[Date of birth]], 2) -> 2 | J25: =WEEKDAY(tblUsers[[#This Row],[Date of birth]]) -> 3
B26: M-0523 | C26: Edna Gomez | D26: 37617 | E26: F-0953/M-0960/F-1190/F-1212/F-1169/M-0505/M-0860/M-0910/F-0735/M-0824/M-1111/F-0579/F-1123/M-0694/M-0524/M-0567/M-0636/F-1129/F-0726/F-1002/F-1098/F-0543/M-0899/M-1347/F-1151/M-0566/F-0563/M-1033/M-0892/M-1051/F-0638/F-0627/F-1045/M-0909/M-1194/M-0609/M-0755/F-0975/F-1071/M-1107/M-0744/F-0622/F-1143/M-0967/M-0536/F-0804/F-1188/F-1004/F-0617/F-0954/M-0678/M-0831/F-0864/M-1195/F-0520/F-0598/F-1136/M-0906/M-1247/F-0828/F-1013/M-1054/F-1168/F-0959/F-0882/F-1108/F-0545/M-1068/M-1307/M-1345/F-1041/F-0549/F-1228/F-0836/F-1010/F-1086/M-0977/F-1079/M-0696/F-0508/M-1320/M-0562/M-0961/M-0510/F-1204/F-0685/M-1262/F-1240/M-0895/M-0587/M-1078/F-0911/F-0717/M-1117/M-0670/F-0583/F-1016/M-1218/M-1087/F-0900/M-0993/F-0846/F-0544/F-0596/F-0957/M-0553/M-0826/M-1298/F-0531/M-0837/F-1026/M-1339/F-1189/M-1293/F-0857/F-0934/M-0526/M-0821/M-0715/F-0697/F-0839/F-0682/M-0794/F-1171/M-1077/F-0512/M-0779/F-1092/F-1081/F-0689/M-0802/M-0709/M-0540/F-0517/M-1072/M-0738/F-1263/M-1241/F-1144/F-0991/F-0935/F-1337/F-0772/M-0851/F-0861/F-0737/M-0816/M-1286/F-1316/M-0925/M-0871/M-0593/F-0592/M-1084/F-0580/M-0843/M-0820/F-1028/F-0727/F-0651/F-0578/F-0698/F-0775/F-0629/F-0568/F-1066/M-1266/M-0878/F-1202/M-1223/M-0507/M-1158/F-1015/M-1283/F-0538/M-0602/M-0867/M-0646/F-0669/F-0625/M-1025/F-0893/F-0787/F-1233/F-0886/M-0679/M-0590/M-1167/M-0519/M-0809/F-1259/F-1046/F-1279/F-1249/M-0781/M-0732/M-0841/M-0665/M-0586/M-0997/M-0606/M-0865/M-1118/F-0574/F-0686/F-0515/F-1222/M-1248/M-0778/F-1165/M-0806/F-0739/F-0819/M-1276/M-0649/M-0876/F-0660/F-1312/M-0949/F-1273/M-0610/F-1317/M-1208/M-1163/F-1305/M-0656/F-0807/F-0663/M-0624/F-1257/F-0747/F-0838/F-0632/F-1070/M-0765/F-1146/F-1106/M-1344/F-0687/F-1112 | F26: Woodworking | G26: =LEFT(tblUsers[[#This Row],[ID]]) -> M | H26: =RIGHT(tblUsers[[#This Row],[ID]],4) -> 0523 | I26: =WEEKDAY(tblUsers[[#This Row],[Date of birth]], 2) -> 5 | J26: =WEEKDAY(tblUsers[[#This Row],[Date of birth]]) -> 6
B27: M-0524 | C27: Queen Silva | D27: 37786 | E27: F-0954/M-1347/M-0973/F-1151/F-1212/F-1317/F-0622/F-0786/F-0953/F-0537/M-0678/F-1285/F-0735/M-0821/M-1014/M-1167/M-1005/M-1293/M-0534/F-1228/F-0578/F-1213/F-0819/F-1168/M-0837/F-0804/M-1184/M-0988/M-0768/F-1002/M-0703/F-0959/F-1045/M-1292/M-0960/M-0899/M-1035/F-0935/F-1152/F-1026/M-0982/M-1182/M-0859/M-0841/F-0583/M-0778/M-1025/M-0507/F-1120/M-1248/F-1132/F-0580/F-0638/M-0738/F-1079/F-0798/M-1068/M-1344/F-1123/F-1042/M-0536/F-1215/F-0927/F-0682/M-1084/F-1001/F-0697/F-0882/F-1060/F-0619/F-0672/F-1226/F-0900/M-1051/M-0877/F-0538/F-0991/M-0664/F-1136/M-0783/M-0820/F-1146/F-0980/M-0560/F-1193/F-0844/M-0901/F-0629/M-0658/M-1231/M-0723/F-0857/M-0940/M-1111/M-1276/F-0512/F-1071/M-0646/F-1063/M-1107/M-1031/F-1119/F-1328/F-0563/F-1263/F-0549/M-0831/F-1165/M-1241/M-1345/F-1183/F-1023/F-0687/F-0898/M-0869/F-1272/M-1255/F-1143/F-0579/F-1278/M-0780/M-0851/F-1059/M-1319/M-1201/M-1195/F-0625/F-1240/F-0861/M-1087/F-1316/F-0864/M-1078/F-1284/F-0748/M-0539/M-1083/M-0636/M-0774/F-0842/F-0686/F-0924/M-1286/F-1179/F-1086/M-0566/F-0787/F-1121/F-0543/M-1243/M-1223/M-0606/F-1279/F-1336/M-0824/M-0526/M-1038/M-0813/M-0815/F-0545/F-1012/F-1013/F-1046/F-0657/F-0668/F-0516/F-0592/M-1021/M-0970/M-0590/F-1061/M-0979/M-1091/M-0910/F-1049/F-1106/F-0894/F-1129/M-0920/F-0659/M-0570/F-1273/F-1257/F-1188/F-0635/M-1072/F-1342/F-1348/F-0754/F-1144/M-1024/M-1102/M-0649/M-0977/F-1315/F-0719/M-1033/F-0839/M-0967/M-0555/F-1155/F-0942/F-1204/M-1339/F-1010/F-0574/M-0694/M-0673/F-1169/F-1092/F-1190/M-1303/M-1205/M-0745/F-0807/F-0552/F-0775/M-1300/F-0828/F-1232/M-0806/M-0602/M-0599/M-0996/F-1028/F-0502/M-1181/F-1259/F-0726/F-0522/F-1032/M-0600/M-0879/F-0929/F-0596/F-0517/F-0939/F-0952/M-1118/F-1256/F-0751/M-0933/F-0617/M-0680/F-0757/M-0513/M-0981/M-0789/F-0990/M-0782/M-1207/F-0937/F-1282/M-0833/M-0876/M-0670/M-0944/M-0826/F-1198/M-0553/F-0812/F-1015/M-0878/M-0586/F-0544/F-0917/F-0532/F-1333/M-1030/M-0892/M-0759/M-0501/F-1227/F-1234/M-0523/F-1171/F-1250/F-0855/M-0610/M-0630/M-0949/M-0626/F-1245/M-0941/F-1041/F-0810/M-0925/F-0858/M-0860/F-1116/M-0993/M-0817/F-0558/M-1142/F-0568/M-0505/F-0628/M-0528/F-0974/M-1287/M-0573/F-0962/M-0961/F-1249/M-1036/F-0520/M-0641/F-0931/M-0854/F-1157/F-1341/F-0886/F-0971/F-0845/M-1145/F-0614/F-0934/F-0727/M-1056/F-0698/M-1283/M-0597/F-0647/M-1269/M-0915/M-0733/F-0652/M-0744/F-1318/F-0983/F-0627/F-0504/F-1189/M-0776/F-1098/F-0632/M-0840/M-0509/F-1203/M-0847/M-0779/F-1138/M-0587/M-0761/F-0763/M-0548/M-1267/F-0795/F-0875/F-0846/F-1225/M-0862/M-1125/M-0540/F-1075/F-0693/M-0926/F-0707/M-1325/F-0760/M-0868/F-0836/M-0724/F-1127/M-0696 | F27: Football | G27: =LEFT(tblUsers[[#This Row],[ID]]) -> M | H27: =RIGHT(tblUsers[[#This Row],[ID]],4) -> 0524 | I27: =WEEKDAY(tblUsers[[#This Row],[Date of birth]], 2) -> 6 | J27: =WEEKDAY(tblUsers[[#This Row],[Date of birth]]) -> 7
B28: F-0525 | C28: Joan Graham | D28: 37531 | E28: F-1198/M-0821/M-0973/F-1013/F-1136/M-0567/M-0678/F-0687/M-0834/M-0926/F-0545/F-0861/M-1201/F-1190/M-0860/M-0755/M-0593/F-0574/M-0534/M-0624/M-0562/M-0524/F-1317/M-0779/M-0910/M-1036/M-1286/F-0688/M-0960/M-1303/F-1169/M-0778/M-0824/F-1215/M-0505/F-0927/M-1339/F-1316/M-1005/M-1187/M-0837/F-0786/M-1111/F-1032/F-0846/F-1204/F-0991/M-1035/F-0632/M-0670/M-0703/F-1086/M-1248/M-0646/F-1060/M-0892/F-0953/F-0672/M-0510/F-0763/F-0937/M-0507/M-0636/M-1031/F-0753/F-1202/F-1171/F-1071/F-1152/M-0826/F-1257/F-0508/M-0961/F-0913/F-0748/M-0831/F-1123/M-0862/F-0668/F-0660/M-0925/F-1165/F-0561/F-0772/F-0663/F-0520/M-1139/M-1087/F-0898/M-0949/M-0996/F-0954/F-1126/F-1336/M-1195/M-1054/M-0696/F-1312/F-0757/M-1095/M-1068/M-0540/F-0882/F-1119/M-1301/F-0775/F-0864/M-0609/M-0528/M-0876/M-1293/M-1014/F-1046/F-1001/M-0513/M-0970/M-1292/F-1179/M-0774/M-1024/M-0723/M-1269/M-0566/M-0782/M-0897/F-0537/F-0747/M-0992/M-0944/M-0700/M-0694/F-1226/F-0942/M-0995/F-1272/F-0543/F-0598/M-0981/F-1129/M-0620/M-1205/F-1062/M-1021/F-0719/M-0899/F-0712/F-0798/F-0623/M-0940/M-1083/F-1263/M-0715/F-0612/M-1262/F-1132/F-0808/F-0934/F-0502/F-1233/M-0815/F-1193/F-1245/F-0698/M-0744/F-0592/F-0787/F-1178/M-0573/M-0871/F-1016/M-1101/F-1253/F-1130/F-0836/F-1346/F-0705/F-0975/F-1186/F-1079/F-0616/F-1059/M-0988/M-1345/M-1320/F-0739/M-0865/M-0590/F-1061/F-1214/M-0709/M-0851/M-0977/F-0767/M-0986/M-0602/F-1023/M-1184/M-0895/M-0941/F-1154/F-0959/F-1070/F-0648/F-1212/M-0594/M-0576/M-0928/F-0917/F-1012/M-1167/F-1183/M-1107/M-0919/M-1323/F-0935/F-1063/F-0990/M-1162/M-0780/M-1118/F-1282/M-0626/M-0814/M-0559/M-0806/F-0669/M-0982/M-0967/F-0622/M-0867/F-1040/M-1211/F-1098/F-0522/M-0733/M-1145/M-0998/M-0599/F-1144/M-1223/M-0581/M-0641/M-1276/M-1044/F-1322/F-0596/M-1158/M-0758/F-1066/F-1045/M-0877/M-0850/F-1052/F-0579/M-0527/M-0820/M-1135/F-0563/F-0957/F-0504/M-0903/F-1324/F-0801/M-0529/M-1325/M-1156/F-0575/M-1268/F-1127/M-0933/F-0580/M-1142/M-1008/F-1055/M-1207/M-0557/F-0857/M-1084/F-0838/F-0613/F-0552/M-0665/M-1172/M-0818/F-0686/M-1326/F-1225/M-0658/F-1228/F-1242/F-1318/M-1289/F-1168/F-0804/F-1244/M-1264/M-0887/F-0671/F-1203/F-1120/M-0854/M-1102/F-1333/F-0627/F-0695/M-0716/F-0532/F-0750/F-0955/M-0879/M-0548/M-1331/F-1131/M-1025/F-0625/M-0771/M-1109/F-1140/M-0793/M-0555/M-1022/F-0617/M-0835/F-0635/M-1287/M-0533/M-1007/F-1112/F-0939/F-0538/M-0606/F-0980/M-0843/F-0962/F-1006/F-0588/F-1348/M-0553/M-0680/F-1151/M-0673/M-0560/M-1125/F-1213/M-0792/M-0539/F-1279/M-0679/M-1117/F-1106/F-0735/M-0738/M-0577/M-0649/F-0956/F-0710/F-0762/F-0638/F-1081/M-0783/M-1241/F-0827/M-0699/F-0601/M-1231/F-0883/F-0950/F-1261/M-1206/M-1329/F-1105/M-1078/F-0682/M-0920/F-0886/F-0952/F-1143/F-1295/F-0904/F-0872/M-0896/M-1327/M-1161/M-1347/M-0848/F-1305/M-1247/F-0578/F-1227/F-1285/F-1155/F-0819/M-0565/F-0828/M-0607/M-0650/F-1176/F-0842/F-1189/M-1307/F-0911/M-1051/M-1000/F-1188/F-0855/M-0885/F-0531/M-1173/M-0542/F-0725/F-0521/F-1216/M-1191/M-1073/M-0881/F-0766/F-0701/F-0583/M-0841/M-0704/F-0812/F-1337/F-0535/F-1238/M-0908/F-1075/F-0844 | F28: Solving puzzles | G28: =LEFT(tblUsers[[#This Row],[ID]]) -> F | H28: =RIGHT(tblUsers[[#This Row],[ID]],4) -> 0525 | I28: =WEEKDAY(tblUsers[[#This Row],[Date of birth]], 2) -> 3 | J28: =WEEKDAY(tblUsers[[#This Row],[Date of birth]]) -> 4
B29: M-0526 | C29: Hassan Curtis | D29: 36270 | E29: M-0926/F-1045/M-0778/M-1293/F-0804/F-0861/M-1223/F-1285/M-0738/F-1212/M-0977/F-1171/F-0537/F-0543/F-0954/F-1168/F-0748/F-0627/M-0821/M-0851/M-0910/F-0812/F-1169/M-1248/M-0806/F-1013/F-0622/M-0606/M-0593/F-1198/F-0512/F-1152/M-0843/F-0592/F-0953/M-0967/F-0842/F-0828/M-1054/F-1079/F-1026/F-1138/F-1204/M-0949/F-0515/F-0502/M-0610/M-0833/F-0864/F-0950/M-1167/F-1123/F-0712/F-1071/F-1196/F-0668/F-0568/F-0991/M-0961/F-0617/F-1190/F-1155/F-0614/F-1061/M-0986/F-0751/M-0862/M-0892/F-0538/M-0940/F-1086/M-0973/M-0624/M-0703/F-0927/F-0775/F-1146/F-0688/F-0671/M-0557/F-1215/M-0599/M-0620/M-1139/F-0839/M-0915/F-0525/M-0715/M-0587/F-0898/F-1271/M-1182/M-0696/M-0507/F-0549/M-0590/F-0574/M-1024/F-1337/M-0817/M-0777/F-0935/F-1349/M-0700/F-0629/M-0630/M-0670/F-1278/M-0548/M-1068/M-0982/F-0763/M-0944/F-0980/M-1300/F-1120/M-0567/M-0925/F-1284/M-0877/M-1170/F-0934/M-0723/F-1273/M-0540/M-1195/M-0510/M-0794/M-1051/M-0607/F-1324/M-0895/M-0774/F-1328/M-0755/M-0733/F-1151/F-0578/F-1070/F-0798/M-0608/M-0513/F-1226/M-1025/F-0753/F-1348/M-0881/F-0531/F-0787/M-1291/M-0524/F-0651/F-1002/F-1263/M-0680/M-1056/F-1023/M-0665/M-0878/F-0551/F-1297/M-0562/M-0920/F-0893/F-1119/M-1083/M-1320/F-0846/M-1111/M-0963/M-0824/M-1345/M-0694/F-0799/F-0561/M-1142/F-0757/M-1156/F-0672/M-1255/M-0576/M-0993/F-1042/M-0923/M-0553/M-1208/F-1317/F-0612/M-1301/M-1267/M-0611/M-1072/M-0570/F-1280/M-0941/M-0609/M-0816/F-0647/M-1344/M-1269/F-0819/F-0737/M-1162/M-0996/M-1184/F-0648/M-1319/F-1275/F-1321/F-1063/M-0501/M-0988/F-0917/M-1005/M-1087/M-0594/F-1004/F-0984/F-1234/M-1110/F-1316/M-0818/M-0646/F-1225/F-1055/F-0939/F-1213/F-1032/M-1067/F-1066/M-0740/M-0505/M-1135/F-1295/F-0852/M-0792 | F29: Woodworking | G29: =LEFT(tblUsers[[#This Row],[ID]]) -> M | H29: =RIGHT(tblUsers[[#This Row],[ID]],4) -> 0526 | I29: =WEEKDAY(tblUsers[[#This Row],[Date of birth]], 2) -> 2 | J29: =WEEKDAY(tblUsers[[#This Row],[Date of birth]]) -> 3
B30: M-0527 | C30: Leopoldo Harrell | D30: 38008 | E30: F-1169/F-0627/M-1347/F-0786/F-0935/F-0812/F-0574/M-0560/F-1002/F-1316/F-1136/M-0510/M-1031/F-1204/M-1014/M-0859/F-0545/F-0544/M-1139/M-0837/F-1016/M-0919/F-1120/F-1216/F-0638/F-0672/F-1023/F-0617/F-1228/F-0846/M-0977/F-0502/F-1152/F-0980/M-0636/F-0864/M-1287/F-1155/F-1013/F-1123/M-0646/F-0751/M-0973/F-0763/M-0843/M-0961/F-0839/M-1025/M-1231/M-1111/F-0798/F-0580/F-1317/F-0579/M-0915/M-1005/F-1138/F-0772/F-0828/M-0782/M-0925/F-1045/M-1201/F-0739/F-0735/F-1106/M-0607/F-0954/F-0578/F-0697/M-0824/F-1285/M-0831/M-0526/F-0619/F-1171/F-0804/F-0929/M-0534/M-0553/M-1345/M-0818/M-1194/F-1066/M-1267/F-0757/M-0768/F-1263/M-0624/F-0682/M-0723/M-0982/M-0744/F-1108/M-0877/M-1319/F-1010/M-1243/M-1241/M-0507/F-1273/M-0620/F-1012/F-0959/F-0819/F-0799/M-0986/F-0913/F-0625/F-1198/M-1223/M-0733/M-1218/M-0658/M-0587/M-1248/F-0747/M-0988/M-1307/M-0548/M-0777/M-0570/M-0960/M-1038/M-0529/F-0671/M-0910/F-0543/M-0851/M-1167/M-0606/F-0623/F-0592/M-1334/F-1280/F-0549/F-1214/F-1168/F-1176/F-1119/M-1044/M-1339/M-0826/M-0680/F-1061/F-1274/M-0755/M-1102/M-0981/F-1318/M-0992/M-1069/M-1304/F-1297/F-0632/M-1181/F-1049/F-1146/M-0840/F-1333/M-0802/F-0726/M-1293/M-1101/F-1215/M-0834/F-0894/M-1158/M-1344/F-1240/M-1068/M-0555/M-0696/F-1312/F-1026/M-0821/M-0860/M-0738/M-0833/M-0678/M-0594/M-0602/F-1178/F-0563/F-0647/M-0896/F-0504/M-1051/M-0920/F-1284/M-0794/F-1055/M-0901/F-1149/M-0593/F-1260/F-0516/M-0644/F-1282/F-0953/F-0564/M-0876/M-0862/M-1110/M-0895/F-0852/M-1184/M-1054/F-0934/F-1057/F-0687/M-0892/F-0886/F-1028/M-0993/F-0629/M-1329/F-0622/F-1175/M-0841/M-0694/F-0596/M-0792/F-0635/F-1042/F-0937/M-0909/M-0626/M-0995/F-1335/F-1004/F-1183/M-1078/F-1321/M-0550/F-0844/M-1276/M-1021/F-0668/F-1226/M-1262/F-0927/M-1291/F-0717/M-1053/M-1107/M-1255/F-1071/M-0677/F-0857/F-0520/F-1212/F-0561/F-0829/F-1141/F-1189/M-0513/F-0659/F-1046/F-0764/F-1086/F-0720/M-0716/M-0741/F-0931/F-0775/M-1067/M-1235/M-0562/F-1092/M-0539/M-1182/M-0670/F-0616/M-0752/F-1154/M-0774/M-0783/M-1091/M-0731/M-0817/F-1006/F-0748/F-0884/F-0525/F-0737/F-0532/M-1187/F-0628/F-0614/M-1030/M-0978/F-0705/F-1253/F-1250/M-0945/M-0524/M-0940/F-0861/M-0664/F-1337/F-0651/F-1244/F-1165/F-0514/F-1052/M-0662/F-0515/M-0691/M-0742/M-0536/F-0698/M-0806/M-0599/M-0736/F-0657/M-1247/M-0765/M-0759 | F30: Playing board games | G30: =LEFT(tblUsers[[#This Row],[ID]]) -> M | H30: =RIGHT(tblUsers[[#This Row],[ID]],4) -> 0527 | I30: =WEEKDAY(tblUsers[[#This Row],[Date of birth]], 2) -> 4 | J30: =WEEKDAY(tblUsers[[#This Row],[Date of birth]]) -> 5
B31: M-0528 | C31: Gay Cole | D31: 36097 | E31: F-1168/F-1169/M-0507/M-1293/F-1026/M-0926/F-0543/F-0592/M-1319/M-0837/F-1196 | F31: Photography | G31: =LEFT(tblUsers[[#This Row],[ID]]) -> M | H31: =RIGHT(tblUsers[[#This Row],[ID]],4) -> 0528 | I31: =WEEKDAY(tblUsers[[#This Row],[Date of birth]], 2) -> 4 | J31: =WEEKDAY(tblUsers[[#This Row],[Date of birth]]) -> 5
... B56: M-0553 | C56: Hao Ning | D56: 36780 | E56: F-0861/F-1123/M-0940/F-1212/M-0694/M-0678/M-0510/F-1106/F-0672/M-0877/F-1032/M-0973/M-0636/F-0579/M-1139/F-0531/M-0821/M-0774/M-0988/F-0580/F-0625/M-0824/M-1051/F-0537/F-1046/F-1215/M-1167/F-0934/F-0748/M-0920/M-0755/F-0629/F-1071/F-1312/F-1041/F-0763/M-1030/F-1126/F-1013/F-1059/F-1183/F-0772/F-0617/M-0624/M-1223/M-0670/F-0619/F-0726/F-1169/M-0986/F-1190/M-1187/F-1204/M-1276/M-1347/F-0568/M-0733/M-0550/F-0991/M-0860/M-0868/F-1086/M-0967/M-0607/M-0513/M-1194/M-0519/F-1324/M-0562/M-1135/F-1119/F-1066/F-1337/M-1319/M-1038/M-0949/M-0534/F-0984/F-0516/M-1293/F-0588/M-1182/M-1292/F-0686/M-1241/M-0781/M-1304/M-1035/M-0597/M-0834/F-0671/M-0536/F-1305/M-0826/M-0996/M-1344/F-0622/F-1016/M-1184/F-0975/M-1005/F-1245/M-0780/M-1303/F-1186/M-0816/M-1107/M-0567/M-0555/F-0937/F-1226/F-0812/F-0810/M-1014/F-0564/F-0574/M-0841/F-0842/M-0526/F-0688/F-1129/F-0894/F-0735/M-1084/M-0851/M-1036/M-0792/F-1213/F-1316/M-1147/F-1171/M-0559/F-1263/F-1214/M-0738/F-1130/F-0819/M-0933/F-1228/F-0705/M-0783/F-0929/F-0545 | F56: Solving puzzles | G56: =LEFT(tblUsers[[#This Row],[ID]]) -> M | H56: =RIGHT(tblUsers[[#This Row],[ID]],4) -> 0553 | I56: =WEEKDAY(tblUsers[[#This Row],[Date of birth]], 2) -> 1 | J56: =WEEKDAY(tblUsers[[#This Row],[Date of birth]]) -> 2
B57: M-0554 | C57: Roy Thomas | D57: 35730 | E57: {=INDEX(_xlfn._TRO_ALL('User Data'!C:C),Case!G57:G76)} -> Arnulfo Lara | F57: Cooking | G57: =LEFT(tblUsers[[#This Row],[ID]]) -> M | H57: =RIGHT(tblUsers[[#This Row],[ID]],4) -> 0554 | I57: =WEEKDAY(tblUsers[[#This Row],[Date of birth]], 2) -> 1 | J57: =WEEKDAY(tblUsers[[#This Row],[Date of birth]]) -> 2
