Workbook

Sheet Case
B2: Microsoft Excel Collegiate Challenge 2026
B4: This Spreadsheet is a Nightmare - MECC Junior Varsity Edition | T4: Case Author
T5: Harry Seiders
B14: Instructions
B15: You thought it would be a good idea to sit back and watch the Excel championship while eating pizza, ice cream, and ghost peppers.
B16: That crazy combination has lead you here into a waking nightmare, a spread sheet file with all kinds of frightful problems.
B19: Bonus Questions
B21: To make the game more exciting, we have created 5 bonus questions for you. These questions can be answered at any time during the game.
B23: Game # | C23: Relates to Level # | D23: Points | E23: Answer | G23: Question
B24: Bonus 1 | C24: 1 | D24: 30 | E24: {=MAX(LEN(E49:E68))} -> 8 | G24: In Level 1, excluding the example, how many characters is the longest answer?
B25: Bonus 2 | C25: 2 | D25: 40 | E25: =MAX(G88:AT107) + LARGE(G88:AT107, 2) -> 199601 | G25: In Level 2, excluding the example, among the 20x40 Sets of Numbers, what is the sum of the two largest individual numbers?
B26: Bonus 3 | C26: 4 | D26: 50 | E26: 96 | G26: In Level 4, excluding the example, how many times does the most frequently appearing emoji appear within the 20x40 set of emojis? Exclude the 20 Emojis of Interest from the count.
B27: Bonus 4 | C27: 1 | D27: 60 | E27: 12 | G27: In Level 1, excluding the example, how many times does the most frequently appearing letter appear in the answers?
B28: Bonus 5 | C28: 5 | D28: 70 | E28: =SUM(AV212:AV231) -> 152 | G28: In Level 5, excluding the example, how many times does an emoji appear directly after a semi-colon? E.g., ";👽". Important Note: Each emoji has a length of 2 characters.
B30: Questions
B32: Level 1 | C32: Easy
B34: Dreams and nightmares can have hidden messages.
B35: Remove the unwanted character to reveal the hidden word. Pay attention to which cell the word is located in.
B36: Hint: Consider using the SUBSTITUTE function.
B38: Example1: Removing the character ^ reveals the word COUNTIFS.
B40: Answer Hints:
B41: Game 1's answer starts with a T.
B42: Game 2's answer starts with an I.
B43: Game 3's answer starts with a C.
B45: Game # | C45: Level | D45: Points | E45: Answer | G45: Word | L45: Unwanted Character
B47: Example1 | C47: 1 | D47: 0 | E47: COUNTIFS | G47: ^C^^^O^^^U^^^N^^^T^^^I^^^F^^^S^ | L47: ^
B49: 1 | C49: 1 | D49: 4 | E49: =SUBSTITUTE(G49,L49, "") -> TEXTJOIN | G49: )T)))E)))X)))T)))J)))O)))I)))N) | L49: ) | P49: =_xlfn.CONCAT(E49:E68) -> TEXTJOININDEXCONCATINDEXCOUNTAIFSLENIFERRORMINIFSSUMIFSEOMONTHVLOOKUPMATCHINDIRECTAVERAGEMAXIFSTABLEXLOOKUPDATETEXT
B50: 2 | C50: 1 | D50: 4 | E50: =SUBSTITUTE(G50,L50, "") -> INDEX | G50: (I(((N(((D(((E(((X( | L50: (
B51: 3 | C51: 1 | D51: 4 | E51: =SUBSTITUTE(G51,L51, "") -> CONCAT | G51: *C***O***N***C***A***T* | L51: * | P51: {=MID(P49,_xlfn.SEQUENCE(1,LEN(P49)),1)} -> T | Q51: E | R51: X | S51: T | T51: J | U51: O | V51: I | W51: N | X51: I | Y51: N | Z51: D | AA51: E | AB51: X | AC51: C | AD51: O | AE51: N | AF51: C | AG51: A | AH51: T | AI51: I | AJ51: N | AK51: D | AL51: E | AM51: X | AN51: C | AO51: O | AP51: U | AQ51: N | AR51: T | AS51: A | AT51: I | AU51: F | AV51: S | AW51: L | AX51: E | AY51: N | AZ51: I | BA51: F | BB51: E | BC51: R | BD51: R | BE51: O | BF51: R | BG51: M | BH51: I | BI51: N | BJ51: I | BK51: F | BL51: S | BM51: S | BN51: U | BO51: M | BP51: I | BQ51: F | BR51: S | BS51: E | BT51: O | BU51: M | BV51: O | BW51: N | BX51: T | BY51: H | BZ51: V | CA51: L | CB51: O | CC51: O | CD51: K | CE51: U | CF51: P | CG51: M | CH51: A | CI51: T | CJ51: C | CK51: H | CL51: I | CM51: N | CN51: D | CO51: I | CP51: R | CQ51: E | CR51: C | CS51: T | CT51: A | CU51: V | CV51: E | CW51: R | CX51: A | CY51: G | CZ51: E | DA51: M | DB51: A | DC51: X | DD51: I | DE51: F | DF51: S | DG51: T | DH51: A | DI51: B | DJ51: L | DK51: E | DL51: X | DM51: L | DN51: O | DO51: O | DP51: K | DQ51: U | DR51: P | DS51: D | DT51: A | DU51: T | DV51: E | DW51: T | DX51: E | DY51: X | DZ51: T
B52: 4 | C52: 1 | D52: 4 | E52: =SUBSTITUTE(G52,L52, "") -> INDEX | G52: &I&&&N&&&D&&&E&&&X& | L52: &
B53: 5 | C53: 1 | D53: 4 | E53: =SUBSTITUTE(G53,L53, "") -> COUNTA | G53: ^C^^^O^^^U^^^N^^^T^^^A^ | L53: ^ | P53: {=_xlfn.UNIQUE(_xlfn.ANCHORARRAY(P51),1)} -> T | Q53: E | R53: X | S53: J | T53: O | U53: I | V53: N | W53: D | X53: C | Y53: A | Z53: U | AA53: F | AB53: S | AC53: L | AD53: R | AE53: M | AF53: H | AG53: V | AH53: K | AI53: P | AJ53: G | AK53: B
B54: 6 | C54: 1 | D54: 4 | E54: =SUBSTITUTE(G54,L54, "") -> IFS | G54: %I%%%F%%%S% | L54: % | P54: {=COUNTIF(_xlfn.ANCHORARRAY(P51),_xlfn.ANCHORARRAY(P53))} -> 11 | Q54: 12 | R54: 6 | S54: 1 | T54: 10 | U54: 11 | V54: 9 | W54: 4 | X54: 5 | Y54: 8 | Z54: 4 | AA54: 5 | AB54: 5 | AC54: 4 | AD54: 5 | AE54: 5 | AF54: 2 | AG54: 2 | AH54: 2 | AI54: 2 | AJ54: 1 | AK54: 1
B55: 7 | C55: 1 | D55: 4 | E55: =SUBSTITUTE(G55,L55, "") -> LEN | G55: $L$$$E$$$N$ | L55: $
B56: 8 | C56: 1 | D56: 4 | E56: =SUBSTITUTE(G56,L56, "") -> IFERROR | G56: #I###F###E###R###R###O###R# | L56: # | P56: =MAX(_xlfn.ANCHORARRAY(P54)) -> 12
B57: 9 | C57: 1 | D57: 4 | E57: =SUBSTITUTE(G57,L57, "") -> MINIFS | G57: @M@@@I@@@N@@@I@@@F@@@S@ | L57: @
B58: 10 | C58: 1 | D58: 4 | E58: =SUBSTITUTE(G58,L58, "") -> SUMIFS | G58: #S###U###M###I###F###S# | L58: #
B59: 11 | C59: 1 | D59: 4 | E59: =SUBSTITUTE(G59,L59, "") -> EOMONTH | G59: !E!!!O!!!M!!!O!!!N!!!T!!!H! | L59: !
B60: 12 | C60: 1 | D60: 4 | E60: =SUBSTITUTE(G60,L60, "") -> VLOOKUP | G60: >V>>>L>>>O>>>O>>>K>>>U>>>P> | L60: >
B61: 13 | C61: 1 | D61: 4 | E61: =SUBSTITUTE(G61,L61, "") -> MATCH | G61: ?M???A???T???C???H? | L61: ?
B62: 14 | C62: 1 | D62: 4 | E62: =SUBSTITUTE(G62,L62, "") -> INDIRECT | G62: ;I;;;N;;;D;;;I;;;R;;;E;;;C;;;T; | L62: ;
...

Sheet Graded Answers
B1: Your Answers
B2: Game # | C2: Answer | D2: Points
B3: Bonus 1 | C3: =IF(ISBLANK(Case!E24),"",Case!E24) -> 8 | D3: 30
B4: Bonus 2 | C4: =IF(ISBLANK(Case!E25),"",Case!E25) -> 199601 | D4: 40
B5: Bonus 3 | C5: =IF(ISBLANK(Case!E26),"",Case!E26) -> 96 | D5: 50 | O5: 1130
B6: Bonus 4 | C6: =IF(ISBLANK(Case!E27),"",Case!E27) -> 12 | D6: 60 | O6: =SUM(D3:D147) -> 1250 | P6: =O6-O5 -> 120
B7: Bonus 5 | C7: =IF(ISBLANK(Case!E28),"",Case!E28) -> 152 | D7: 70
B8: 1 | C8: =IF(ISBLANK(Case!E49),"",Case!E49) -> TEXTJOIN | D8: 4
B9: =B8+1 -> 2 | C9: =IF(ISBLANK(Case!E50),"",Case!E50) -> INDEX | D9: 4
B10: =B9+1 -> 3 | C10: =IF(ISBLANK(Case!E51),"",Case!E51) -> CONCAT | D10: 4
B11: =B10+1 -> 4 | C11: =IF(ISBLANK(Case!E52),"",Case!E52) -> INDEX | D11: 4
B12: =B11+1 -> 5 | C12: =IF(ISBLANK(Case!E53),"",Case!E53) -> COUNTA | D12: 4
B13: =B12+1 -> 6 | C13: =IF(ISBLANK(Case!E54),"",Case!E54) -> IFS | D13: 4
B14: =B13+1 -> 7 | C14: =IF(ISBLANK(Case!E55),"",Case!E55) -> LEN | D14: 4
B15: =B14+1 -> 8 | C15: =IF(ISBLANK(Case!E56),"",Case!E56) -> IFERROR | D15: 4
B16: =B15+1 -> 9 | C16: =IF(ISBLANK(Case!E57),"",Case!E57) -> MINIFS | D16: 4
B17: =B16+1 -> 10 | C17: =IF(ISBLANK(Case!E58),"",Case!E58) -> SUMIFS | D17: 4
B18: =B17+1 -> 11 | C18: =IF(ISBLANK(Case!E59),"",Case!E59) -> EOMONTH | D18: 4
B19: =B18+1 -> 12 | C19: =IF(ISBLANK(Case!E60),"",Case!E60) -> VLOOKUP | D19: 4
B20: =B19+1 -> 13 | C20: =IF(ISBLANK(Case!E61),"",Case!E61) -> MATCH | D20: 4
... B27: =B26+1 -> 20 | C27: =IF(ISBLANK(Case!E68),"",Case!E68) -> TEXT | D27: 4
B28: =B27+1 -> 21 | C28: =IF(ISBLANK(Case!E88),"",Case!E88) -> 33 | D28: 6
B29: =B28+1 -> 22 | C29: =IF(ISBLANK(Case!E89),"",Case!E89) -> 26 | D29: 6
B30: =B29+1 -> 23 | C30: =IF(ISBLANK(Case!E90),"",Case!E90) -> 23 | D30: 6
B31: =B30+1 -> 24 | C31: =IF(ISBLANK(Case!E91),"",Case!E91) -> 34 | D31: 6
B32: =B31+1 -> 25 | C32: =IF(ISBLANK(Case!E92),"",Case!E92) -> 28 | D32: 6
B33: =B32+1 -> 26 | C33: =IF(ISBLANK(Case!E93),"",Case!E93) -> 29 | D33: 6
B34: =B33+1 -> 27 | C34: =IF(ISBLANK(Case!E94),"",Case!E94) -> 29 | D34: 6
B35: =B34+1 -> 28 | C35: =IF(ISBLANK(Case!E95),"",Case!E95) -> 27 | D35: 6
B36: =B35+1 -> 29 | C36: =IF(ISBLANK(Case!E96),"",Case!E96) -> 28 | D36: 6
B37: =B36+1 -> 30 | C37: =IF(ISBLANK(Case!E97),"",Case!E97) -> 32 | D37: 6
B38: =B37+1 -> 31 | C38: =IF(ISBLANK(Case!E98),"",Case!E98) -> 31 | D38: 6
B39: =B38+1 -> 32 | C39: =IF(ISBLANK(Case!E99),"",Case!E99) -> 31 | D39: 6
... B47: =B46+1 -> 40 | C47: =IF(ISBLANK(Case!E107),"",Case!E107) -> 26 | D47: 6
B48: =B47+1 -> 41 | C48: =IF(ISBLANK(Case!E129),"",Case!E129) -> 1124160 | D48: 7
B49: =B48+1 -> 42 | C49: =IF(ISBLANK(Case!E130),"",Case!E130) -> 1166996 | D49: 7
B50: =B49+1 -> 43 | C50: =IF(ISBLANK(Case!E131),"",Case!E131) -> 765437 | D50: 7
B51: =B50+1 -> 44 | C51: =IF(ISBLANK(Case!E132),"",Case!E132) -> 576560 | D51: 7
B52: =B51+1 -> 45 | C52: =IF(ISBLANK(Case!E133),"",Case!E133) -> 764669 | D52: 7
B53: =B52+1 -> 46 | C53: =IF(ISBLANK(Case!E134),"",Case!E134) -> 642015 | D53: 7
...
